File: STRAIN_GAUGE/calibration test/2024-07-16/Steel_1.is_comp_RawData/Specimen_1_RawData_1.csv
Time,Extension,Load,Compressive strain (Extension),Compressive stress
(s),(mm),(N),(mm/mm),(MPa)
"0.00000","0.00000","0.03426","0.00000","0.00068"
"0.03000","0.00000","0.03280","0.00000","0.00065"
"0.06000","0.00001","0.02962","0.00000","0.00059"
"0.09000","0.00004","0.03176","0.00000","0.00063"
"0.12000","0.00010","0.03941","0.00001","0.00078"
"0.15000","0.00022","0.02799","0.00001","0.00056"
"0.18000","0.00041","0.02359","0.00003","0.00047"
"0.21000","0.00065","0.02106","0.00004","0.00042"
"0.24000","0.00095","0.03263","0.00006","0.00065"
"0.27000","0.00129","0.05253","0.00008","0.00105"
"0.30000","0.00164","0.05604","0.00010","0.00111"
"0.33000","0.00196","0.07389","0.00012","0.00147"
"0.36000","0.00228","0.07564","0.00014","0.00150"
"0.39000","0.00263","0.04981","0.00016","0.00099"
"0.42000","0.00296","0.06713","0.00019","0.00134"
"0.45000","0.00326","0.07442","0.00020","0.00148"
"0.48000","0.00354","0.02402","0.00022","0.00048"
"0.51000","0.00383","0.01121","0.00024","0.00022"
"0.54000","0.00411","0.00592","0.00026","0.00012"
"0.57000","0.00438","0.02298","0.00027","0.00046"
"0.60000","0.00465","0.03542","0.00029","0.00070"
"0.63000","0.00490","0.06812","0.00031","0.00136"
"0.66000","0.00518","0.09190","0.00032","0.00183"
"0.69000","0.00544","0.09538","0.00034","0.00190"
"0.72000","0.00573","0.04620","0.00036","0.00092"
"0.75000","0.00600","0.04139","0.00038","0.00082"
"0.78000","0.00626","0.01804","0.00039","0.00036"
"0.81000","0.00653","0.04707","0.00041","0.00094"
"0.84000","0.00679","0.06220","0.00042","0.00124"
"0.87000","0.00705","0.05983","0.00044","0.00119"
"0.90000","0.00731","0.04068","0.00046","0.00081"
"0.93000","0.00755","0.04076","0.00047","0.00081"
"0.96000","0.00780","0.01975","0.00049","0.00039"
"0.99000","0.00806","0.00666","0.00050","0.00013"
"1.02000","0.00832","0.01985","0.00052","0.00039"
"1.05000","0.00856","0.02239","0.00054","0.00045"
"1.08000","0.00881","0.02562","0.00055","0.00051"
"1.11000","0.00908","0.01197","0.00057","0.00024"
"1.14000","0.00934","0.01839","0.00058","0.00037"
"1.17000","0.00959","0.01397","0.00060","0.00028"
"1.20000","0.00984","0.04158","0.00062","0.00083"
"1.23000","0.01011","0.03646","0.00063","0.00073"
"1.26000","0.01038","0.03148","0.00065","0.00063"
"1.29000","0.01064","0.03946","0.00067","0.00078"
"1.32000","0.01089","0.06077","0.00068","0.00121"
"1.35000","0.01114","0.03783","0.00070","0.00075"
"1.38000","0.01142","0.04294","0.00071","0.00085"
"1.41000","0.01166","0.06157","0.00073","0.00122"
"1.44000","0.01189","0.11274","0.00074","0.00224"
"1.47000","0.01211","0.15497","0.00076","0.00308"
"1.50000","0.01236","0.20163","0.00077","0.00401"
"1.53000","0.01261","0.22420","0.00079","0.00446"
"1.56000","0.01286","0.25739","0.00080","0.00512"
"1.59000","0.01309","0.27839","0.00082","0.00554"
"1.62000","0.01333","0.29087","0.00083","0.00579"
"1.65000","0.01357","0.30146","0.00085","0.00600"
"1.68000","0.01381","0.31536","0.00086","0.00627"
"1.71000","0.01406","0.31742","0.00088","0.00631"
"1.74000","0.01431","0.31062","0.00089","0.00618"
"1.77000","0.01454","0.19022","0.00091","0.00378"
"1.80000","0.01479","0.14008","0.00092","0.00279"
"1.83000","0.01506","0.27896","0.00094","0.00555"
"1.86000","0.01531","0.46552","0.00096","0.00926"
"1.89000","0.01554","0.69179","0.00097","0.01376"
"1.92000","0.01578","0.95550","0.00099","0.01901"
"1.95000","0.01603","1.27567","0.00100","0.02538"
"1.98000","0.01628","1.63031","0.00102","0.03243"
"2.01000","0.01653","2.02456","0.00103","0.04028"
"2.04000","0.01678","2.45767","0.00105","0.04889"
"2.07000","0.01703","2.94866","0.00106","0.05866"
"2.10000","0.01728","3.43903","0.00108","0.06842"
"2.13000","0.01752","3.98119","0.00109","0.07920"
"2.16000","0.01778","4.61876","0.00111","0.09189"
"2.19000","0.01803","5.24061","0.00113","0.10426"
"2.22000","0.01827","5.81453","0.00114","0.11568"
"2.25000","0.01852","6.43552","0.00116","0.12803"
"2.28000","0.01878","7.10780","0.00117","0.14141"
"2.31000","0.01900","7.71246","0.00119","0.15343"
"2.34000","0.01926","8.41664","0.00120","0.16744"
"2.37000","0.01950","9.06199","0.00122","0.18028"
"2.40000","0.01974","9.75696","0.00123","0.19411"
"2.43000","0.02003","10.64503","0.00125","0.21178"
"2.46000","0.02028","11.38950","0.00127","0.22659"
"2.49000","0.02050","12.09146","0.00128","0.24055"
"2.52000","0.02076","12.95150","0.00130","0.25766"
"2.55000","0.02103","13.90553","0.00131","0.27664"
"2.58000","0.02129","14.81466","0.00133","0.29473"
"2.61000","0.02152","15.67509","0.00135","0.31185"
"2.64000","0.02176","16.55705","0.00136","0.32939"
"2.67000","0.02203","17.56185","0.00138","0.34938"
"2.70000","0.02228","18.47786","0.00139","0.36761"
"2.73000","0.02252","19.35037","0.00141","0.38496"
"2.76000","0.02277","20.25304","0.00142","0.40292"
"2.79000","0.02303","21.13746","0.00144","0.42052"
"2.82000","0.02327","21.99389","0.00145","0.43755"
"2.85000","0.02352","22.88920","0.00147","0.45537"
"2.88000","0.02376","23.75223","0.00148","0.47254"
"2.91000","0.02400","24.68368","0.00150","0.49107"
"2.94000","0.02426","25.64248","0.00152","0.51014"
"2.97000","0.02452","26.63177","0.00153","0.52982"
"3.00000","0.02479","27.67590","0.00155","0.55059"
"3.03000","0.02504","28.61484","0.00157","0.56927"
"3.06000","0.02529","29.58601","0.00158","0.58859"
"3.09000","0.02557","30.70466","0.00160","0.61085"
"3.12000","0.02581","31.69556","0.00161","0.63056"
"3.15000","0.02609","32.82087","0.00163","0.65295"
"3.18000","0.02637","33.89438","0.00165","0.67431"
"3.21000","0.02661","34.83389","0.00166","0.69300"
"3.24000","0.02687","35.84100","0.00168","0.71303"
"3.27000","0.02712","36.77168","0.00170","0.73155"
"3.30000","0.02738","37.71965","0.00171","0.75041"
"3.33000","0.02763","38.71208","0.00173","0.77015"
"3.36000","0.02786","39.61331","0.00174","0.78808"
"3.39000","0.02811","40.64772","0.00176","0.80866"
"3.42000","0.02836","41.64959","0.00177","0.82859"
"3.45000","0.02859","42.60344","0.00179","0.84757"
"3.48000","0.02880","43.51503","0.00180","0.86570"
"3.51000","0.02905","44.55507","0.00182","0.88639"
"3.54000","0.02930","45.63413","0.00183","0.90786"
"3.57000","0.02953","46.67753","0.00185","0.92862"
"3.60000","0.02977","47.80810","0.00186","0.95111"
"3.63000","0.03000","48.89729","0.00188","0.97278"
"3.66000","0.03025","50.04491","0.00189","0.99561"
"3.69000","0.03052","51.24208","0.00191","1.01943"
"3.72000","0.03077","52.37414","0.00192","1.04195"
"3.75000","0.03103","53.47525","0.00194","1.06386"
"3.78000","0.03126","54.48485","0.00195","1.08394"
"3.81000","0.03149","55.50660","0.00197","1.10427"
"3.84000","0.03173","56.59246","0.00198","1.12587"
"3.87000","0.03199","57.77644","0.00200","1.14943"
"3.90000","0.03224","58.90532","0.00202","1.17188"
"3.93000","0.03252","60.16551","0.00203","1.19695"
"3.96000","0.03278","61.40233","0.00205","1.22156"
"3.99000","0.03303","62.50915","0.00206","1.24358"
"4.02000","0.03324","63.47862","0.00208","1.26287"
"4.05000","0.03348","64.62538","0.00209","1.28568"
"4.08000","0.03375","66.03717","0.00211","1.31377"
"4.11000","0.03401","67.30379","0.00213","1.33897"
"4.14000","0.03425","68.47015","0.00214","1.36217"
"4.17000","0.03448","69.55907","0.00216","1.38383"
"4.20000","0.03478","70.93645","0.00217","1.41124"
"4.23000","0.03502","72.04357","0.00219","1.43326"
"4.26000","0.03525","73.04554","0.00220","1.45319"
"4.29000","0.03550","74.22177","0.00222","1.47660"
"4.32000","0.03575","75.41746","0.00223","1.50038"
"4.35000","0.03597","76.44969","0.00225","1.52092"
"4.38000","0.03622","77.64788","0.00226","1.54476"
"4.41000","0.03650","78.95679","0.00228","1.57080"
"4.44000","0.03677","80.23478","0.00230","1.59622"
"4.47000","0.03700","81.33182","0.00231","1.61805"
"4.50000","0.03724","82.51902","0.00233","1.64166"
"4.53000","0.03750","83.82424","0.00234","1.66763"
"4.56000","0.03774","85.06287","0.00236","1.69227"
"4.59000","0.03798","86.29362","0.00237","1.71676"
"4.62000","0.03826","87.70450","0.00239","1.74483"
"4.65000","0.03852","89.04530","0.00241","1.77150"
"4.68000","0.03878","90.36204","0.00242","1.79770"
"4.71000","0.03903","91.61496","0.00244","1.82262"
"4.74000","0.03930","92.89996","0.00246","1.84819"
"4.77000","0.03953","94.02329","0.00247","1.87053"
"4.80000","0.03980","95.43543","0.00249","1.89863"
"4.83000","0.04007","96.85783","0.00250","1.92693"
"4.86000","0.04032","98.14742","0.00252","1.95258"
"4.89000","0.04057","99.48372","0.00254","1.97917"
"4.92000","0.04083","100.81148","0.00255","2.00558"
"4.95000","0.04107","102.07238","0.00257","2.03067"
"4.98000","0.04132","103.49342","0.00258","2.05894"
"5.01000","0.04158","105.01244","0.00260","2.08916"
"5.04000","0.04184","106.56187","0.00261","2.11998"
"5.07000","0.04209","108.04875","0.00263","2.14956"
"5.09900","0.04236","109.61748","0.00265","2.18077"
"5.12900","0.04258","110.95421","0.00266","2.20736"
"5.15900","0.04281","112.34055","0.00268","2.23494"
"5.18900","0.04309","113.93572","0.00269","2.26668"
"5.21900","0.04333","115.36311","0.00271","2.29508"
"5.24900","0.04356","116.76614","0.00272","2.32299"
"5.27900","0.04378","118.13643","0.00274","2.35025"
"5.30900","0.04399","119.54451","0.00275","2.37826"
"5.33700","0.04423","121.15984","0.00276","2.41040"
"5.36600","0.04447","122.72433","0.00278","2.44152"
"5.39600","0.04468","124.18787","0.00279","2.47064"
"5.42400","0.04491","125.79924","0.00281","2.50270"
"5.45200","0.04515","127.39885","0.00282","2.53452"
"5.47900","0.04536","128.92134","0.00283","2.56481"
"5.50400","0.04556","130.50873","0.00285","2.59639"
"5.53000","0.04577","132.11829","0.00286","2.62841"
"5.55800","0.04599","133.70842","0.00287","2.66004"
"5.58300","0.04620","135.29231","0.00289","2.69156"
"5.61100","0.04643","136.92436","0.00290","2.72402"
"5.63900","0.04664","138.51340","0.00292","2.75564"
"5.66300","0.04685","140.03677","0.00293","2.78594"
"5.68700","0.04706","141.56310","0.00294","2.81631"
"5.71300","0.04728","143.20586","0.00296","2.84899"
"5.73200","0.04748","144.77090","0.00297","2.88013"
"5.75100","0.04767","146.40018","0.00298","2.91254"
"5.77400","0.04787","148.04999","0.00299","2.94536"
"5.79700","0.04806","149.67596","0.00300","2.97771"
"5.82100","0.04825","151.27550","0.00302","3.00953"
"5.85000","0.04844","152.91896","0.00303","3.04223"
"5.87400","0.04862","154.52289","0.00304","3.07414"
"5.89300","0.04880","156.16635","0.00305","3.10683"
"5.91200","0.04898","157.74559","0.00306","3.13825"
"5.93700","0.04917","159.34885","0.00307","3.17014"
"5.96100","0.04935","160.96245","0.00308","3.20225"
"5.97900","0.04952","162.61139","0.00310","3.23505"
"5.99800","0.04970","164.29156","0.00311","3.26848"
"6.02100","0.04987","165.94547","0.00312","3.30138"
"6.04200","0.05004","167.48840","0.00313","3.33208"
"6.06500","0.05021","169.11763","0.00314","3.36449"
"6.08800","0.05039","170.71550","0.00315","3.39628"
"6.10700","0.05056","172.30545","0.00316","3.42791"
"6.12600","0.05074","173.90768","0.00317","3.45978"
"6.14800","0.05092","175.49660","0.00318","3.49139"
"6.17200","0.05111","177.13121","0.00319","3.52391"
"6.19300","0.05128","178.67117","0.00321","3.55455"
"6.21400","0.05146","180.22803","0.00322","3.58552"
"6.23500","0.05164","181.83208","0.00323","3.61743"
"6.25600","0.05181","183.45049","0.00324","3.64963"
"6.27700","0.05199","185.08504","0.00325","3.68215"
"6.29800","0.05217","186.74716","0.00326","3.71522"
"6.32100","0.05235","188.38245","0.00327","3.74775"
"6.34300","0.05252","190.04385","0.00328","3.78080"
"6.36300","0.05270","191.69839","0.00329","3.81372"
"6.38400","0.05288","193.35663","0.00330","3.84671"
"6.40500","0.05305","194.98582","0.00332","3.87912"
"6.42600","0.05322","196.60034","0.00333","3.91124"
"6.44700","0.05340","198.30106","0.00334","3.94507"
"6.46600","0.05356","199.95351","0.00335","3.97795"
"6.48300","0.05373","201.61462","0.00336","4.01100"
"6.49800","0.05388","203.14511","0.00337","4.04144"
"6.51600","0.05405","204.81625","0.00338","4.07469"
"6.53400","0.05421","206.35422","0.00339","4.10529"
"6.55300","0.05437","207.94197","0.00340","4.13687"
"6.57400","0.05455","209.64134","0.00341","4.17068"
"6.59500","0.05472","211.25604","0.00342","4.20281"
"6.61600","0.05490","212.92332","0.00343","4.23598"
"6.63700","0.05509","214.65459","0.00344","4.27042"
"6.65900","0.05527","216.27757","0.00345","4.30271"
"6.68200","0.05545","217.92027","0.00347","4.33539"
"6.70200","0.05562","219.52525","0.00348","4.36732"
"6.72000","0.05578","221.11342","0.00349","4.39891"
"6.73900","0.05595","222.74460","0.00350","4.43136"
"6.76000","0.05612","224.36099","0.00351","4.46352"
"6.78100","0.05629","225.98849","0.00352","4.49590"
"6.79900","0.05645","227.56879","0.00353","4.52734"
"6.81900","0.05662","229.21466","0.00354","4.56008"
"6.84000","0.05680","230.93472","0.00355","4.59430"
"6.86100","0.05697","232.59006","0.00356","4.62723"
"6.88200","0.05714","234.20578","0.00357","4.65938"
"6.90200","0.05730","235.81717","0.00358","4.69143"
"6.92200","0.05746","237.46387","0.00359","4.72419"
"6.94300","0.05762","239.06679","0.00360","4.75608"
"6.96400","0.05778","240.74896","0.00361","4.78955"
"6.98500","0.05795","242.47728","0.00362","4.82393"
"7.00400","0.05810","244.06374","0.00363","4.85549"
"7.02500","0.05827","245.79201","0.00364","4.88988"
"7.04400","0.05843","247.39398","0.00365","4.92175"
"7.06500","0.05860","249.05162","0.00366","4.95472"
"7.08600","0.05876","250.59998","0.00367","4.98553"
"7.10700","0.05893","252.19318","0.00368","5.01722"
"7.12800","0.05910","253.74663","0.00369","5.04813"
"7.14900","0.05926","255.26785","0.00370","5.07839"
"7.17000","0.05943","256.93710","0.00371","5.11160"
"7.18800","0.05959","258.48849","0.00372","5.14247"
"7.20800","0.05976","260.13998","0.00373","5.17532"
"7.22900","0.05993","261.83069","0.00375","5.20896"
"7.25000","0.06010","263.44806","0.00376","5.24113"
"7.27100","0.06027","265.13812","0.00377","5.27476"
"7.29200","0.06044","266.86984","0.00378","5.30921"
"7.31000","0.06059","268.39951","0.00379","5.33964"
"7.32900","0.06075","270.00815","0.00380","5.37164"
"7.35000","0.06093","271.72653","0.00381","5.40583"
"7.37100","0.06110","273.46628","0.00382","5.44044"
"7.38900","0.06126","275.01627","0.00383","5.47127"
"7.40700","0.06142","276.72318","0.00384","5.50523"
"7.42500","0.06157","278.36752","0.00385","5.53795"
"7.44500","0.06173","280.02097","0.00386","5.57084"
"7.46300","0.06187","281.53284","0.00387","5.60092"
"7.48400","0.06204","283.26056","0.00388","5.63529"
"7.50300","0.06219","284.85989","0.00389","5.66711"
"7.52100","0.06235","286.43500","0.00390","5.69844"
"7.53900","0.06252","288.10248","0.00391","5.73162"
"7.55800","0.06268","289.71417","0.00392","5.76368"
"7.57900","0.06285","291.38968","0.00393","5.79701"
"7.59900","0.06302","293.03976","0.00394","5.82984"
"7.61700","0.06318","294.56140","0.00395","5.86011"
"7.63800","0.06336","296.25488","0.00396","5.89380"
"7.65700","0.06352","297.83499","0.00397","5.92524"
"7.67800","0.06368","299.46463","0.00398","5.95766"
"7.69900","0.06385","301.11865","0.00399","5.99057"
"7.72000","0.06401","302.78760","0.00400","6.02377"
"7.73900","0.06418","304.41608","0.00401","6.05617"
"7.75700","0.06434","306.05634","0.00402","6.08880"
"7.77500","0.06450","307.66229","0.00403","6.12075"
"7.79300","0.06465","309.21817","0.00404","6.15170"
"7.81100","0.06480","310.75964","0.00405","6.18237"
"7.83300","0.06496","312.35101","0.00406","6.21403"
"7.85500","0.06512","313.95917","0.00407","6.24602"
"7.87300","0.06528","315.54010","0.00408","6.27747"
"7.89100","0.06542","317.08228","0.00409","6.30815"
"7.91100","0.06558","318.74396","0.00410","6.34121"
"7.92900","0.06572","320.27072","0.00411","6.37158"
"7.94700","0.06588","321.95535","0.00412","6.40510"
"7.96500","0.06605","323.73535","0.00413","6.44051"
"7.98300","0.06621","325.44693","0.00414","6.47456"
"8.00100","0.06637","327.13770","0.00415","6.50820"
"8.01900","0.06653","328.72583","0.00416","6.53979"
"8.03700","0.06669","330.29648","0.00417","6.57104"
"8.05500","0.06685","331.89279","0.00418","6.60280"
"8.07300","0.06701","333.45303","0.00419","6.63384"
"8.09100","0.06717","334.99796","0.00420","6.66457"
"8.10900","0.06733","336.57901","0.00421","6.69603"
"8.12700","0.06749","338.16251","0.00422","6.72753"
"8.14600","0.06765","339.75699","0.00423","6.75925"
"8.16700","0.06782","341.40744","0.00424","6.79209"
"8.18700","0.06798","343.04095","0.00425","6.82458"
"8.20500","0.06813","344.59753","0.00426","6.85555"
"8.22300","0.06828","346.13568","0.00427","6.88615"
"8.24100","0.06844","347.70309","0.00428","6.91733"
"8.25900","0.06860","349.41779","0.00429","6.95145"
"8.27700","0.06877","351.10446","0.00430","6.98500"
"8.29700","0.06893","352.74365","0.00431","7.01761"
"8.31800","0.06909","354.37915","0.00432","7.05015"
"8.33900","0.06926","356.08447","0.00433","7.08408"
"8.35700","0.06941","357.63361","0.00434","7.11489"
"8.37500","0.06956","359.29053","0.00435","7.14786"
"8.39300","0.06971","360.99103","0.00436","7.18169"
"8.41100","0.06987","362.66568","0.00437","7.21500"
"8.42900","0.07002","364.34515","0.00438","7.24842"
"8.44700","0.07019","366.06305","0.00439","7.28259"
"8.46500","0.07034","367.65436","0.00440","7.31425"
"8.48600","0.07050","369.29065","0.00441","7.34680"
"8.50700","0.07066","370.86938","0.00442","7.37821"
"8.52800","0.07083","372.56885","0.00443","7.41202"
"8.54600","0.07098","374.08636","0.00444","7.44221"
"8.56500","0.07114","375.68073","0.00445","7.47393"
"8.58800","0.07131","377.28564","0.00446","7.50586"
"8.61000","0.07147","378.85574","0.00447","7.53710"
"8.63100","0.07163","380.50906","0.00448","7.56999"
"8.65200","0.07179","382.15262","0.00449","7.60268"
"8.67100","0.07195","383.73578","0.00450","7.63418"
"8.69000","0.07210","385.33136","0.00451","7.66592"
"8.71100","0.07227","387.02954","0.00452","7.69971"
"8.72900","0.07242","388.55405","0.00453","7.73004"
"8.74700","0.07256","390.10126","0.00454","7.76082"
"8.76600","0.07272","391.70267","0.00454","7.79268"
"8.78700","0.07288","393.39636","0.00456","7.82637"
"8.80700","0.07305","395.05530","0.00457","7.85938"
"8.82500","0.07320","396.62726","0.00457","7.89065"
"8.84300","0.07336","398.36652","0.00458","7.92525"
"8.86100","0.07352","400.09378","0.00459","7.95961"
"8.87900","0.07366","401.65787","0.00460","7.99073"
"8.89800","0.07381","403.27847","0.00461","8.02297"
"8.91600","0.07397","405.01520","0.00462","8.05752"
"8.93400","0.07413","406.77988","0.00463","8.09263"
"8.95200","0.07429","408.49484","0.00464","8.12675"
"8.97100","0.07445","410.13397","0.00465","8.15936"
"8.99200","0.07461","411.82248","0.00466","8.19295"
"9.01300","0.07478","413.45511","0.00467","8.22543"
"9.03200","0.07494","415.06812","0.00468","8.25752"
"9.05000","0.07511","416.76630","0.00469","8.29130"
"9.07000","0.07528","418.40967","0.00470","8.32400"
"9.09100","0.07544","420.07086","0.00472","8.35704"
"9.11200","0.07561","421.74594","0.00473","8.39037"
"9.13200","0.07577","423.41525","0.00474","8.42358"
"9.15000","0.07593","425.06226","0.00475","8.45635"
"9.16800","0.07608","426.68222","0.00476","8.48857"
"9.18600","0.07624","428.24362","0.00476","8.51964"
"9.20600","0.07639","429.89200","0.00477","8.55243"
"9.22800","0.07655","431.49924","0.00478","8.58440"
"9.25200","0.07671","433.16321","0.00479","8.61751"
"9.27200","0.07687","434.76871","0.00480","8.64945"
"9.29000","0.07702","436.42267","0.00481","8.68235"
"9.30800","0.07719","438.12466","0.00482","8.71621"
"9.32600","0.07735","439.87201","0.00483","8.75098"
"9.34400","0.07750","441.56302","0.00484","8.78462"
"9.36200","0.07765","443.21344","0.00485","8.81745"
"9.38000","0.07780","444.85089","0.00486","8.85003"
"9.39800","0.07795","446.54019","0.00487","8.88364"
"9.41600","0.07811","448.20459","0.00488","8.91675"
"9.43400","0.07826","449.84503","0.00489","8.94938"
"9.45200","0.07842","451.49402","0.00490","8.98219"
"9.47000","0.07856","453.04333","0.00491","9.01301"
"9.48900","0.07872","454.63931","0.00492","9.04476"
"9.50700","0.07887","456.20355","0.00493","9.07588"
"9.52600","0.07903","457.79034","0.00494","9.10745"
"9.54800","0.07920","459.42352","0.00495","9.13994"
"9.57000","0.07936","461.05197","0.00496","9.17234"
"9.58900","0.07952","462.63962","0.00497","9.20392"
"9.60700","0.07967","464.24948","0.00498","9.23595"
"9.62500","0.07984","465.94897","0.00499","9.26976"
"9.64200","0.08000","467.64261","0.00500","9.30345"
"9.65700","0.08014","469.17844","0.00501","9.33401"
"9.67300","0.08030","470.77786","0.00502","9.36583"
"9.69100","0.08045","472.40594","0.00503","9.39822"
"9.70900","0.08060","473.97098","0.00504","9.42935"
"9.72700","0.08075","475.52136","0.00505","9.46020"
"9.74500","0.08091","477.24911","0.00506","9.49457"
"9.76000","0.08106","478.80026","0.00507","9.52543"
"9.77600","0.08121","480.42355","0.00508","9.55772"
"9.79400","0.08137","482.04819","0.00509","9.59004"
"9.81500","0.08152","483.77322","0.00510","9.62436"
"9.83300","0.08167","485.42319","0.00510","9.65719"
"9.84800","0.08181","486.97394","0.00511","9.68804"
"9.86500","0.08196","488.64316","0.00512","9.72125"
"9.88400","0.08211","490.27118","0.00513","9.75364"
"9.90200","0.08226","491.82385","0.00514","9.78452"
"9.92000","0.08241","493.45374","0.00515","9.81695"
"9.93800","0.08256","495.05096","0.00516","9.84873"
"9.95600","0.08272","496.66345","0.00517","9.88081"
"9.97400","0.08287","498.26208","0.00518","9.91261"
"9.99200","0.08303","499.84406","0.00519","9.94408"
"10.01000","0.08319","501.40393","0.00520","9.97511"
"10.02800","0.08334","502.96301","0.00521","10.00613"
"10.04600","0.08349","504.49240","0.00522","10.03656"
"10.06700","0.08366","506.21933","0.00523","10.07091"
"10.08800","0.08382","507.87283","0.00524","10.10381"
"10.10900","0.08397","509.50540","0.00525","10.13629"
"10.13000","0.08414","511.21585","0.00526","10.17032"
"10.15100","0.08430","512.91937","0.00527","10.20421"
"10.17200","0.08446","514.62280","0.00528","10.23810"
"10.19100","0.08461","516.22394","0.00529","10.26995"
"10.21000","0.08476","517.81305","0.00530","10.30156"
"10.23100","0.08493","519.51410","0.00531","10.33541"
"10.25200","0.08509","521.22125","0.00532","10.36937"
"10.27000","0.08523","522.75830","0.00533","10.39995"
"10.28800","0.08538","524.38654","0.00534","10.43234"
"10.30600","0.08553","526.02100","0.00535","10.46486"
"10.32400","0.08567","527.55969","0.00535","10.49547"
"10.34200","0.08580","529.10187","0.00536","10.52615"
"10.36000","0.08594","530.66052","0.00537","10.55716"
"10.37800","0.08608","532.22943","0.00538","10.58837"
"10.39600","0.08623","533.82385","0.00539","10.62009"
"10.41400","0.08637","535.39087","0.00540","10.65126"
"10.43200","0.08652","536.94409","0.00541","10.68216"
"10.45000","0.08667","538.58002","0.00542","10.71471"
"10.46600","0.08683","540.17151","0.00543","10.74637"
"10.48300","0.08699","541.83600","0.00544","10.77948"
"10.50100","0.08714","543.39807","0.00545","10.81056"
"10.51900","0.08730","544.95032","0.00546","10.84144"
"10.53700","0.08745","546.55695","0.00547","10.87341"
"10.55500","0.08761","548.19531","0.00548","10.90600"
"10.57300","0.08777","549.92059","0.00549","10.94032"
"10.59100","0.08792","551.53046","0.00550","10.97235"
"10.60900","0.08807","553.10101","0.00550","11.00360"
"10.62900","0.08823","554.76312","0.00551","11.03666"
"10.65000","0.08839","556.41241","0.00552","11.06947"
"10.67000","0.08854","558.07245","0.00553","11.10250"
"10.68800","0.08870","559.75610","0.00554","11.13599"
"10.70600","0.08885","561.37317","0.00555","11.16817"
"10.72400","0.08900","562.94391","0.00556","11.19941"
"10.74200","0.08916","564.63904","0.00557","11.23314"
"10.76000","0.08932","566.36780","0.00558","11.26753"
"10.77800","0.08947","568.04901","0.00559","11.30098"
"10.79600","0.08961","569.69189","0.00560","11.33366"
"10.81400","0.08976","571.40735","0.00561","11.36779"
"10.83000","0.08990","573.00519","0.00562","11.39958"
"10.84800","0.09006","574.74487","0.00563","11.43419"
"10.86600","0.09022","576.40460","0.00564","11.46721"
"10.88400","0.09037","578.03064","0.00565","11.49955"
"10.90200","0.09052","579.63959","0.00566","11.53156"
"10.92000","0.09068","581.31995","0.00567","11.56499"
"10.93800","0.09084","582.98315","0.00568","11.59808"
"10.95700","0.09100","584.60852","0.00569","11.63042"
"10.97800","0.09116","586.27936","0.00570","11.66366"
"10.99800","0.09132","587.91101","0.00571","11.69612"
"11.01600","0.09148","589.55737","0.00572","11.72887"
"11.03400","0.09164","591.21655","0.00573","11.76188"
"11.05200","0.09179","592.75989","0.00574","11.79258"
"11.07300","0.09195","594.48682","0.00575","11.82694"
"11.09200","0.09210","596.08990","0.00576","11.85883"
"11.11000","0.09225","597.69214","0.00577","11.89071"
"11.12800","0.09240","599.26654","0.00578","11.92203"
"11.14600","0.09255","600.88397","0.00578","11.95421"
"11.16400","0.09271","602.55951","0.00579","11.98754"
"11.18200","0.09287","604.21783","0.00580","12.02053"
"11.20100","0.09302","605.84363","0.00581","12.05288"
"11.21900","0.09317","607.39154","0.00582","12.08367"
"11.23600","0.09332","609.05945","0.00583","12.11685"
"11.25100","0.09347","610.71997","0.00584","12.14989"
"11.26600","0.09361","612.40149","0.00585","12.18334"
"11.28100","0.09375","613.99316","0.00586","12.21501"
"11.29600","0.09389","615.55829","0.00587","12.24614"
"11.31300","0.09404","617.25049","0.00588","12.27981"
"11.33100","0.09420","618.96619","0.00589","12.31394"
"11.34900","0.09436","620.65021","0.00590","12.34744"
"11.36700","0.09451","622.24835","0.00591","12.37924"
"11.38500","0.09466","623.84912","0.00592","12.41108"
"11.40300","0.09481","625.41681","0.00593","12.44227"
"11.42100","0.09496","626.98724","0.00594","12.47352"
"11.44100","0.09512","628.63275","0.00595","12.50625"
"11.46200","0.09529","630.30658","0.00596","12.53955"
"11.48100","0.09544","631.90002","0.00597","12.57125"
"11.49900","0.09560","633.60004","0.00598","12.60507"
"11.51700","0.09576","635.26465","0.00598","12.63819"
"11.53500","0.09590","636.80786","0.00599","12.66889"
"11.55300","0.09605","638.31836","0.00600","12.69894"
"11.57100","0.09619","639.88574","0.00601","12.73012"
"11.58900","0.09634","641.48932","0.00602","12.76202"
"11.60700","0.09649","643.07715","0.00603","12.79361"
"11.62500","0.09664","644.69574","0.00604","12.82582"
"11.64300","0.09679","646.30945","0.00605","12.85792"
"11.66100","0.09694","647.87683","0.00606","12.88910"
"11.68100","0.09710","649.53186","0.00607","12.92203"
"11.70200","0.09726","651.24274","0.00608","12.95606"
"11.72000","0.09740","652.80023","0.00609","12.98705"
"11.73800","0.09754","654.44550","0.00610","13.01978"
"11.75600","0.09768","656.02374","0.00610","13.05118"
"11.77500","0.09782","657.60974","0.00611","13.08273"
"11.79500","0.09796","659.24847","0.00612","13.11533"
"11.81600","0.09812","660.96301","0.00613","13.14944"
"11.83400","0.09826","662.54279","0.00614","13.18087"
"11.85200","0.09842","664.22845","0.00615","13.21441"
"11.87000","0.09857","665.85626","0.00616","13.24679"
"11.88800","0.09872","667.41528","0.00617","13.27781"
"11.90600","0.09888","669.05963","0.00618","13.31052"
"11.92400","0.09904","670.74524","0.00619","13.34405"
"11.94300","0.09920","672.35168","0.00620","13.37601"
"11.96200","0.09935","673.95795","0.00621","13.40797"
"11.98000","0.09951","675.59216","0.00622","13.44048"
"11.99800","0.09966","677.24835","0.00623","13.47343"
"12.01800","0.09982","678.90588","0.00624","13.50640"
"12.03700","0.09997","680.53186","0.00625","13.53875"
"12.05500","0.10012","682.10657","0.00626","13.57008"
"12.07500","0.10028","683.79047","0.00627","13.60358"
"12.09300","0.10043","685.41449","0.00628","13.63589"
"12.11100","0.10058","687.11639","0.00629","13.66975"
"12.12900","0.10074","688.75098","0.00630","13.70227"
"12.14700","0.10088","690.30475","0.00631","13.73318"
"12.16500","0.10103","691.83716","0.00631","13.76366"
"12.18500","0.10118","693.49854","0.00632","13.79672"
"12.20300","0.10133","695.10071","0.00633","13.82859"
"12.22100","0.10148","696.82434","0.00634","13.86288"
"12.23900","0.10163","698.58997","0.00635","13.89801"
"12.25500","0.10177","700.19983","0.00636","13.93003"
"12.27000","0.10190","701.73828","0.00637","13.96064"
"12.28600","0.10204","703.34052","0.00638","13.99252"
"12.30400","0.10220","705.04120","0.00639","14.02635"
"12.32200","0.10235","706.73602","0.00640","14.06007"
"12.34000","0.10250","708.35608","0.00641","14.09230"
"12.35800","0.10265","709.89264","0.00642","14.12287"
"12.37600","0.10281","711.56934","0.00643","14.15622"
"12.39400","0.10297","713.20544","0.00644","14.18877"
"12.41400","0.10313","714.83136","0.00645","14.22112"
"12.43500","0.10329","716.50372","0.00646","14.25439"
"12.45300","0.10344","718.06293","0.00647","14.28541"
"12.47100","0.10360","719.70367","0.00647","14.31805"
"12.48900","0.10375","721.29034","0.00648","14.34962"
"12.50700","0.10389","722.87256","0.00649","14.38109"
"12.52500","0.10404","724.39563","0.00650","14.41139"
"12.54300","0.10418","725.94208","0.00651","14.44216"
"12.56100","0.10433","727.54510","0.00652","14.47405"
"12.57900","0.10448","729.17877","0.00653","14.50655"
"12.59700","0.10463","730.77826","0.00654","14.53837"
"12.61500","0.10477","732.31873","0.00655","14.56902"
"12.63300","0.10492","733.89307","0.00656","14.60034"
"12.65100","0.10507","735.52710","0.00657","14.63285"
"12.66900","0.10522","737.19489","0.00658","14.66603"
"12.68700","0.10537","738.87463","0.00659","14.69944"
"12.70500","0.10552","740.52008","0.00659","14.73218"
"12.72300","0.10567","742.23212","0.00660","14.76624"
"12.73800","0.10580","743.74658","0.00661","14.79637"
"12.75500","0.10595","745.43500","0.00662","14.82996"
"12.77300","0.10610","747.22253","0.00663","14.86552"
"12.78900","0.10625","748.82385","0.00664","14.89738"
"12.80700","0.10641","750.53387","0.00665","14.93140"
"12.82500","0.10656","752.19067","0.00666","14.96436"
"12.84300","0.10672","753.93982","0.00667","14.99916"
"12.85800","0.10687","755.46240","0.00668","15.02945"
"12.87600","0.10703","757.16168","0.00669","15.06325"
"12.89600","0.10719","758.81573","0.00670","15.09616"
"12.91600","0.10736","760.47784","0.00671","15.12923"
"12.93400","0.10751","762.04657","0.00672","15.16044"
"12.95200","0.10766","763.70221","0.00673","15.19337"
"12.97000","0.10782","765.36310","0.00674","15.22642"
"12.98800","0.10797","766.96826","0.00675","15.25835"
"13.00600","0.10811","768.50104","0.00676","15.28884"
"13.02400","0.10825","770.04950","0.00677","15.31965"
"13.04200","0.10840","771.67047","0.00678","15.35190"
"13.06000","0.10855","773.30139","0.00678","15.38434"
"13.07800","0.10870","774.92773","0.00679","15.41670"
"13.09600","0.10885","776.55023","0.00680","15.44898"
"13.11400","0.10900","778.12988","0.00681","15.48040"
"13.13200","0.10915","779.71759","0.00682","15.51199"
"13.15000","0.10929","781.25134","0.00683","15.54250"
"13.16800","0.10943","782.85742","0.00684","15.57445"
"13.18400","0.10957","784.46240","0.00685","15.60638"
"13.19900","0.10971","786.05231","0.00686","15.63801"
"13.21500","0.10985","787.65515","0.00687","15.66990"
"13.23300","0.11000","789.35187","0.00687","15.70366"
"13.25100","0.11015","791.05560","0.00688","15.73755"
"13.26900","0.11030","792.69916","0.00689","15.77025"
"13.28700","0.11045","794.32880","0.00690","15.80267"
"13.30500","0.11060","795.90491","0.00691","15.83403"
"13.32500","0.11075","797.55798","0.00692","15.86691"
"13.34600","0.11091","799.25000","0.00693","15.90057"
"13.36600","0.11108","800.91504","0.00694","15.93370"
"13.38700","0.11124","802.56677","0.00695","15.96656"
"13.40800","0.11140","804.24603","0.00696","15.99997"
"13.42900","0.11155","805.86725","0.00697","16.03222"
"13.45000","0.11171","807.53491","0.00698","16.06540"
"13.47000","0.11186","809.15417","0.00699","16.09761"
"13.48800","0.11201","810.74969","0.00700","16.12935"
"13.50600","0.11216","812.34882","0.00701","16.16117"
"13.52400","0.11231","813.95245","0.00702","16.19307"
"13.54200","0.11246","815.61041","0.00703","16.22606"
"13.56000","0.11261","817.26770","0.00704","16.25903"
"13.57800","0.11276","818.86725","0.00705","16.29085"
"13.59600","0.11291","820.45599","0.00706","16.32245"
"13.61400","0.11306","822.05981","0.00707","16.35436"
"13.63200","0.11321","823.78210","0.00708","16.38862"
"13.65000","0.11337","825.56116","0.00709","16.42402"
"13.66800","0.11352","827.19800","0.00709","16.45658"
"13.68600","0.11365","828.74615","0.00710","16.48738"
"13.70400","0.11379","830.39081","0.00711","16.52010"
"13.72200","0.11394","832.11945","0.00712","16.55449"
"13.74000","0.11409","833.81915","0.00713","16.58831"
"13.75800","0.11424","835.46167","0.00714","16.62098"
"13.77600","0.11440","837.13831","0.00715","16.65434"
"13.79400","0.11456","838.87512","0.00716","16.68889"
"13.81200","0.11472","840.64655","0.00717","16.72413"
"13.83000","0.11489","842.39771","0.00718","16.75897"
"13.84800","0.11504","844.01959","0.00719","16.79124"
"13.86600","0.11519","845.55292","0.00720","16.82174"
"13.88700","0.11536","847.26636","0.00721","16.85583"
"13.90800","0.11551","848.88184","0.00722","16.88797"
"13.92900","0.11567","850.58679","0.00723","16.92189"
"13.94800","0.11582","852.19598","0.00724","16.95390"
"13.96600","0.11598","853.88159","0.00725","16.98743"
"13.98200","0.11613","855.48798","0.00726","17.01939"
"13.99900","0.11628","857.16235","0.00727","17.05270"
"14.01700","0.11643","858.77667","0.00728","17.08482"
"14.03500","0.11657","860.32172","0.00729","17.11556"
"14.05300","0.11672","861.89825","0.00729","17.14692"
"14.07100","0.11686","863.46814","0.00730","17.17815"
"14.08900","0.11701","865.04004","0.00731","17.20942"
"14.10700","0.11716","866.66565","0.00732","17.24177"
"14.12500","0.11731","868.36835","0.00733","17.27564"
"14.14100","0.11745","869.97522","0.00734","17.30761"
"14.15600","0.11759","871.51575","0.00735","17.33825"
"14.17400","0.11774","873.26202","0.00736","17.37300"
"14.19200","0.11789","875.00970","0.00737","17.40777"
"14.20700","0.11803","876.54791","0.00738","17.43837"
"14.22200","0.11816","878.09271","0.00739","17.46910"
"14.24000","0.11832","879.81622","0.00740","17.50339"
"14.25800","0.11847","881.41034","0.00740","17.53510"
"14.27600","0.11863","883.14563","0.00741","17.56963"
"14.29100","0.11877","884.67285","0.00742","17.60001"
"14.30800","0.11893","886.35553","0.00743","17.63348"
"14.32600","0.11910","888.06940","0.00744","17.66758"
"14.34400","0.11925","889.65704","0.00745","17.69917"
"14.36400","0.11941","891.31500","0.00746","17.73215"
"14.38200","0.11956","892.87799","0.00747","17.76324"
"14.40000","0.11971","894.51733","0.00748","17.79586"
"14.41800","0.11986","896.12732","0.00749","17.82789"
"14.43600","0.12000","897.65863","0.00750","17.85835"
"14.45400","0.12015","899.22778","0.00751","17.88957"
"14.47200","0.12029","900.78662","0.00752","17.92058"
"14.49000","0.12044","902.34833","0.00753","17.95165"
"14.50800","0.12058","903.88257","0.00754","17.98217"
"14.52600","0.12073","905.51544","0.00755","18.01466"
"14.54400","0.12089","907.24475","0.00756","18.04906"
"14.56200","0.12105","908.92462","0.00757","18.08248"
"14.58000","0.12120","910.63440","0.00758","18.11650"
"14.59700","0.12135","912.30475","0.00758","18.14973"
"14.61200","0.12149","913.88580","0.00759","18.18118"
"14.62700","0.12163","915.50525","0.00760","18.21340"
"14.64200","0.12176","917.10303","0.00761","18.24519"
"14.65800","0.12190","918.71460","0.00762","18.27725"
"14.67600","0.12205","920.35004","0.00763","18.30978"
"14.69400","0.12219","921.91931","0.00764","18.34100"
"14.71200","0.12234","923.54700","0.00765","18.37338"
"14.73000","0.12250","925.22729","0.00766","18.40681"
"14.74800","0.12265","926.92407","0.00767","18.44057"
"14.76600","0.12281","928.63196","0.00768","18.47455"
"14.78400","0.12298","930.38489","0.00769","18.50942"
"14.80200","0.12315","932.08124","0.00770","18.54317"
"14.82200","0.12330","933.66284","0.00771","18.57463"
"14.84300","0.12346","935.24493","0.00772","18.60611"
"14.86300","0.12361","936.89764","0.00773","18.63899"
"14.88100","0.12376","938.53888","0.00774","18.67164"
"14.89900","0.12392","940.22607","0.00774","18.70520"
"14.91700","0.12407","941.85059","0.00775","18.73752"
"14.93500","0.12421","943.41394","0.00776","18.76863"
"14.95300","0.12436","944.95697","0.00777","18.79932"
"14.97300","0.12451","946.61829","0.00778","18.83237"
"14.99100","0.12465","948.14990","0.00779","18.86284"
"15.00900","0.12479","949.72119","0.00780","18.89410"
"15.02900","0.12495","951.38208","0.00781","18.92715"
"15.04900","0.12510","953.01959","0.00782","18.95972"
"15.06700","0.12524","954.58862","0.00783","18.99094"
"15.08500","0.12538","956.15308","0.00784","19.02206"
"15.10500","0.12553","957.81384","0.00785","19.05510"
"15.12500","0.12567","959.47559","0.00785","19.08816"
"15.14300","0.12581","961.08063","0.00786","19.12009"
"15.16100","0.12595","962.72449","0.00787","19.15280"
"15.17900","0.12610","964.42285","0.00788","19.18658"
"15.19700","0.12626","966.19543","0.00789","19.22185"
"15.21500","0.12642","967.98798","0.00790","19.25751"
"15.23300","0.12658","969.73486","0.00791","19.29226"
"15.25100","0.12673","971.37427","0.00792","19.32488"
"15.26900","0.12688","972.97565","0.00793","19.35674"
"15.28700","0.12703","974.53149","0.00794","19.38769"
"15.30500","0.12719","976.07727","0.00795","19.41844"
"15.32300","0.12733","977.62720","0.00796","19.44928"
"15.34100","0.12749","979.24658","0.00797","19.48149"
"15.35900","0.12764","980.91541","0.00798","19.51469"
"15.37700","0.12779","982.51422","0.00799","19.54650"
"15.39500","0.12793","984.06897","0.00800","19.57743"
"15.41300","0.12808","985.66583","0.00801","19.60920"
"15.43100","0.12823","987.29248","0.00801","19.64156"
"15.44900","0.12838","988.93103","0.00802","19.67416"
"15.46700","0.12853","990.56177","0.00803","19.70660"
"15.48500","0.12867","992.11841","0.00804","19.73757"
"15.50300","0.12882","993.70331","0.00805","19.76910"
"15.52100","0.12897","995.37067","0.00806","19.80227"
"15.53900","0.12913","997.09003","0.00807","19.83648"
"15.55700","0.12929","998.81464","0.00808","19.87079"
"15.57000","0.12939","1000.02063","0.00809","19.89478"