File: STRAIN_GAUGE/calibration test/2024-07-16/Steel_1.is_comp_RawData/Specimen_1_RawData_2.csv
Time,Extension,Load,Compressive strain (Extension),Compressive stress
(s),(mm),(N),(mm/mm),(MPa)
"0.00000","0.00000","-0.01605","0.00000","-0.00032"
"0.04000","0.00000","-0.01288","0.00000","-0.00026"
"0.08000","0.00002","-0.01872","0.00000","-0.00037"
"0.12000","0.00006","-0.01589","0.00000","-0.00032"
"0.16000","0.00018","-0.02382","0.00001","-0.00047"
"0.20000","0.00044","-0.01019","0.00003","-0.00020"
"0.24000","0.00082","-0.02000","0.00005","-0.00040"
"0.28000","0.00128","-0.01725","0.00008","-0.00034"
"0.32000","0.00179","-0.01720","0.00011","-0.00034"
"0.36000","0.00225","-0.01952","0.00014","-0.00039"
"0.40000","0.00271","-0.01538","0.00017","-0.00031"
"0.44000","0.00313","-0.01533","0.00020","-0.00031"
"0.48000","0.00355","-0.00942","0.00022","-0.00019"
"0.52000","0.00394","-0.01217","0.00025","-0.00024"
"0.56000","0.00433","-0.02154","0.00027","-0.00043"
"0.60000","0.00471","-0.00233","0.00029","-0.00005"
"0.64000","0.00507","-0.02154","0.00032","-0.00043"
"0.68000","0.00542","-0.00526","0.00034","-0.00010"
"0.72000","0.00578","-0.01268","0.00036","-0.00025"
"0.76000","0.00612","-0.01062","0.00038","-0.00021"
"0.80000","0.00645","-0.00682","0.00040","-0.00014"
"0.84000","0.00678","-0.01562","0.00042","-0.00031"
"0.88000","0.00710","-0.00560","0.00044","-0.00011"
"0.92000","0.00744","-0.01374","0.00046","-0.00027"
"0.96000","0.00778","-0.00970","0.00049","-0.00019"
"1.00000","0.00808","-0.01106","0.00051","-0.00022"
"1.04000","0.00843","-0.00633","0.00053","-0.00013"
"1.08000","0.00878","-0.01414","0.00055","-0.00028"
"1.12000","0.00911","-0.02521","0.00057","-0.00050"
"1.16000","0.00943","-0.01709","0.00059","-0.00034"
"1.20000","0.00978","-0.02420","0.00061","-0.00048"
"1.24000","0.01013","-0.01382","0.00063","-0.00027"
"1.28000","0.01044","-0.02062","0.00065","-0.00041"
"1.32000","0.01078","-0.00907","0.00067","-0.00018"
"1.36000","0.01112","-0.01696","0.00070","-0.00034"
"1.40000","0.01144","-0.01066","0.00072","-0.00021"
"1.44000","0.01180","-0.01227","0.00074","-0.00024"
"1.48000","0.01213","-0.02210","0.00076","-0.00044"
"1.52000","0.01245","-0.01496","0.00078","-0.00030"
"1.56000","0.01280","-0.02301","0.00080","-0.00046"
"1.60000","0.01313","-0.01000","0.00082","-0.00020"
"1.64000","0.01346","-0.01314","0.00084","-0.00026"
"1.68000","0.01383","-0.01027","0.00086","-0.00020"
"1.72000","0.01417","0.00086","0.00089","0.00002"
"1.76000","0.01451","-0.00304","0.00091","-0.00006"
"1.80000","0.01485","0.02500","0.00093","0.00050"
"1.84000","0.01519","0.01267","0.00095","0.00025"
"1.88000","0.01553","0.02295","0.00097","0.00046"
"1.92000","0.01588","0.03858","0.00099","0.00077"
"1.96000","0.01621","0.00978","0.00101","0.00019"
"2.00000","0.01652","0.07147","0.00103","0.00142"
"2.04000","0.01689","0.02959","0.00106","0.00059"
"2.08000","0.01723","0.06870","0.00108","0.00137"
"2.12000","0.01755","0.20827","0.00110","0.00414"
"2.16000","0.01783","0.35621","0.00111","0.00709"
"2.20000","0.01818","0.52017","0.00114","0.01035"
"2.24000","0.01852","0.69590","0.00116","0.01384"
"2.28000","0.01881","0.86666","0.00118","0.01724"
"2.32000","0.01910","0.97623","0.00119","0.01942"
"2.36000","0.01943","1.15415","0.00121","0.02296"
"2.40000","0.01981","1.42946","0.00124","0.02844"
"2.44000","0.02018","1.68696","0.00126","0.03356"
"2.48000","0.02048","1.87477","0.00128","0.03730"
"2.52000","0.02079","2.09514","0.00130","0.04168"
"2.56000","0.02111","2.32873","0.00132","0.04633"
"2.60000","0.02145","2.37908","0.00134","0.04733"
"2.64000","0.02176","2.38840","0.00136","0.04752"
"2.68000","0.02210","2.68236","0.00138","0.05336"
"2.72000","0.02242","2.98291","0.00140","0.05934"
"2.76000","0.02277","3.31540","0.00142","0.06596"
"2.80000","0.02311","3.66357","0.00144","0.07288"
"2.84000","0.02345","4.05897","0.00147","0.08075"
"2.88000","0.02379","4.46506","0.00149","0.08883"
"2.92000","0.02412","4.89946","0.00151","0.09747"
"2.96000","0.02446","5.37317","0.00153","0.10690"
"3.00000","0.02478","5.80857","0.00155","0.11556"
"3.04000","0.02512","6.28471","0.00157","0.12503"
"3.08000","0.02546","6.77996","0.00159","0.13488"
"3.12000","0.02582","7.32271","0.00161","0.14568"
"3.16000","0.02613","7.75907","0.00163","0.15436"
"3.20000","0.02644","8.23635","0.00165","0.16386"
"3.24000","0.02676","8.66962","0.00167","0.17248"
"3.28000","0.02709","9.14093","0.00169","0.18185"
"3.32000","0.02744","9.63127","0.00172","0.19161"
"3.36000","0.02776","10.08970","0.00174","0.20073"
"3.40000","0.02810","10.61399","0.00176","0.21116"
"3.44000","0.02843","11.12198","0.00178","0.22126"
"3.48000","0.02878","11.67090","0.00180","0.23219"
"3.52000","0.02910","12.15218","0.00182","0.24176"
"3.56000","0.02943","12.68102","0.00184","0.25228"
"3.60000","0.02977","13.26539","0.00186","0.26391"
"3.64000","0.03014","13.86737","0.00188","0.27588"
"3.68000","0.03048","14.43299","0.00191","0.28714"
"3.72000","0.03086","14.99339","0.00193","0.29828"
"3.76000","0.03121","15.51011","0.00195","0.30856"
"3.80000","0.03155","16.02464","0.00197","0.31880"
"3.84000","0.03188","16.55770","0.00199","0.32940"
"3.88000","0.03219","17.08098","0.00201","0.33982"
"3.92000","0.03254","17.64607","0.00203","0.35106"
"3.96000","0.03288","18.21038","0.00206","0.36228"
"4.00000","0.03322","18.73505","0.00208","0.37272"
"4.04000","0.03354","19.31439","0.00210","0.38425"
"4.08000","0.03389","19.91495","0.00212","0.39620"
"4.12000","0.03420","20.44363","0.00214","0.40671"
"4.16000","0.03453","20.98431","0.00216","0.41747"
"4.20000","0.03486","21.49253","0.00218","0.42758"
"4.24000","0.03514","21.93966","0.00220","0.43648"
"4.28000","0.03545","22.45024","0.00222","0.44663"
"4.32000","0.03579","23.04530","0.00224","0.45847"
"4.36000","0.03612","23.59132","0.00226","0.46933"
"4.40000","0.03643","24.13685","0.00228","0.48019"
"4.44000","0.03680","24.74314","0.00230","0.49225"
"4.48000","0.03711","25.29325","0.00232","0.50319"
"4.52000","0.03741","25.85988","0.00234","0.51447"
"4.56000","0.03775","26.49575","0.00236","0.52712"
"4.60000","0.03808","27.11874","0.00238","0.53951"
"4.64000","0.03842","27.70946","0.00240","0.55126"
"4.68000","0.03878","28.35979","0.00242","0.56420"
"4.72000","0.03911","28.90887","0.00244","0.57512"
"4.76000","0.03944","29.51098","0.00247","0.58710"
"4.80000","0.03979","30.13638","0.00249","0.59954"
"4.84000","0.04012","30.73323","0.00251","0.61142"
"4.88000","0.04047","31.38077","0.00253","0.62430"
"4.92000","0.04082","32.01206","0.00255","0.63686"
"4.96000","0.04112","32.60389","0.00257","0.64863"
"5.00000","0.04146","33.27782","0.00259","0.66204"
"5.04000","0.04179","33.94104","0.00261","0.67524"
"5.08000","0.04212","34.62334","0.00263","0.68881"
"5.12000","0.04247","35.30016","0.00265","0.70227"
"5.16000","0.04279","35.93010","0.00267","0.71481"
"5.20000","0.04312","36.54375","0.00270","0.72701"
"5.24000","0.04342","37.14865","0.00271","0.73905"
"5.28000","0.04376","37.81118","0.00274","0.75223"
"5.32000","0.04413","38.55226","0.00276","0.76697"
"5.36000","0.04446","39.21809","0.00278","0.78022"
"5.40000","0.04479","39.87046","0.00280","0.79320"
"5.44000","0.04513","40.58892","0.00282","0.80749"
"5.48000","0.04547","41.33779","0.00284","0.82239"
"5.52000","0.04583","42.15437","0.00286","0.83863"
"5.56000","0.04618","42.88881","0.00289","0.85325"
"5.60000","0.04653","43.62840","0.00291","0.86796"
"5.64000","0.04686","44.30468","0.00293","0.88141"
"5.68000","0.04720","44.99335","0.00295","0.89511"
"5.72000","0.04752","45.65295","0.00297","0.90824"
"5.76000","0.04785","46.29029","0.00299","0.92092"
"5.80000","0.04821","47.05996","0.00301","0.93623"
"5.84000","0.04855","47.77995","0.00303","0.95055"
"5.88000","0.04890","48.52792","0.00306","0.96543"
"5.92000","0.04922","49.24352","0.00308","0.97967"
"5.96000","0.04955","49.97071","0.00310","0.99414"
"6.00000","0.04989","50.73297","0.00312","1.00930"
"6.04000","0.05019","51.41779","0.00314","1.02292"
"6.08000","0.05050","52.13630","0.00316","1.03722"
"6.12000","0.05082","52.81102","0.00318","1.05064"
"6.16000","0.05114","53.49143","0.00320","1.06418"
"6.20000","0.05145","54.20781","0.00322","1.07843"
"6.24000","0.05178","55.04298","0.00324","1.09505"
"6.28000","0.05211","56.00225","0.00326","1.11413"
"6.32000","0.05243","57.02741","0.00328","1.13452"
"6.36000","0.05276","58.16033","0.00330","1.15706"
"6.40000","0.05309","59.30842","0.00332","1.17990"
"6.44000","0.05341","60.61520","0.00334","1.20590"
"6.48000","0.05375","62.05898","0.00336","1.23462"
"6.52000","0.05408","63.46413","0.00338","1.26258"
"6.56000","0.05441","64.92625","0.00340","1.29167"
"6.60000","0.05474","66.36169","0.00342","1.32022"
"6.64000","0.05507","67.88296","0.00344","1.35049"
"6.68000","0.05541","69.48947","0.00346","1.38245"
"6.72000","0.05574","71.14693","0.00348","1.41542"
"6.76000","0.05607","72.78460","0.00350","1.44800"
"6.80000","0.05639","74.44162","0.00352","1.48097"
"6.84000","0.05672","76.15780","0.00354","1.51511"
"6.88000","0.05707","78.01501","0.00357","1.55206"
"6.92000","0.05741","79.84285","0.00359","1.58842"
"6.96000","0.05772","81.64008","0.00361","1.62418"
"7.00000","0.05806","83.57668","0.00363","1.66271"
"7.04000","0.05838","85.36197","0.00365","1.69822"
"7.08000","0.05873","87.27836","0.00367","1.73635"
"7.12000","0.05906","89.12791","0.00369","1.77314"
"7.16000","0.05940","91.00452","0.00371","1.81048"
"7.20000","0.05974","92.97227","0.00373","1.84962"
"7.24000","0.06008","95.00665","0.00376","1.89010"
"7.28000","0.06039","96.87885","0.00377","1.92734"
"7.32000","0.06068","98.68233","0.00379","1.96322"
"7.35800","0.06102","100.77926","0.00381","2.00494"
"7.39300","0.06135","102.93427","0.00383","2.04781"
"7.42600","0.06166","105.01857","0.00385","2.08928"
"7.46500","0.06198","107.18294","0.00387","2.13234"
"7.50200","0.06230","109.34255","0.00389","2.17530"
"7.53800","0.06261","111.45009","0.00391","2.21723"
"7.57400","0.06295","113.61282","0.00393","2.26026"
"7.61400","0.06326","115.63615","0.00395","2.30051"
"7.65200","0.06357","117.70773","0.00397","2.34172"
"7.68800","0.06387","119.76945","0.00399","2.38274"
"7.72400","0.06416","121.83582","0.00401","2.42385"
"7.76000","0.06446","123.97543","0.00403","2.46641"
"7.79600","0.06477","126.11355","0.00405","2.50895"
"7.83200","0.06507","128.20062","0.00407","2.55047"
"7.87000","0.06536","130.32437","0.00408","2.59272"
"7.90400","0.06563","132.44022","0.00410","2.63481"
"7.93900","0.06591","134.51376","0.00412","2.67607"
"7.97500","0.06619","136.60147","0.00414","2.71760"
"8.01300","0.06649","138.71321","0.00416","2.75961"
"8.05000","0.06679","140.83122","0.00417","2.80175"
"8.08800","0.06709","142.95088","0.00419","2.84392"
"8.12300","0.06740","145.09720","0.00421","2.88662"
"8.15900","0.06769","147.23891","0.00423","2.92923"
"8.19100","0.06797","149.28162","0.00425","2.96986"
"8.22800","0.06826","151.38297","0.00427","3.01167"
"8.26300","0.06855","153.52263","0.00428","3.05424"
"8.30200","0.06884","155.63231","0.00430","3.09621"
"8.33600","0.06913","157.78952","0.00432","3.13912"
"8.36800","0.06942","160.00044","0.00434","3.18311"
"8.40200","0.06969","162.12886","0.00436","3.22545"
"8.43600","0.06997","164.28458","0.00437","3.26834"
"8.46800","0.07026","166.45561","0.00439","3.31153"
"8.50000","0.07054","168.54318","0.00441","3.35306"
"8.53200","0.07082","170.58643","0.00443","3.39371"
"8.56800","0.07112","172.68970","0.00444","3.43555"
"8.60300","0.07141","174.76680","0.00446","3.47688"
"8.63700","0.07169","176.89278","0.00448","3.51917"
"8.67300","0.07199","179.05745","0.00450","3.56223"
"8.70900","0.07226","181.13815","0.00452","3.60363"
"8.74400","0.07255","183.28590","0.00453","3.64636"
"8.77600","0.07284","185.46477","0.00455","3.68970"
"8.81000","0.07312","187.58727","0.00457","3.73193"
"8.84200","0.07338","189.64603","0.00459","3.77289"
"8.87400","0.07366","191.83492","0.00460","3.81643"
"8.90600","0.07393","193.96681","0.00462","3.85885"
"8.93800","0.07421","196.13751","0.00464","3.90203"
"8.97100","0.07449","198.26093","0.00466","3.94428"
"9.00700","0.07479","200.45537","0.00467","3.98793"
"9.04100","0.07509","202.61975","0.00469","4.03099"
"9.07500","0.07538","204.73988","0.00471","4.07317"
"9.10700","0.07567","206.88710","0.00473","4.11589"
"9.13900","0.07595","208.98364","0.00475","4.15760"
"9.17100","0.07622","211.07635","0.00476","4.19923"
"9.20300","0.07650","213.20023","0.00478","4.24148"
"9.23800","0.07679","215.36984","0.00480","4.28465"
"9.27000","0.07706","217.44841","0.00482","4.32600"
"9.30200","0.07733","219.56071","0.00483","4.36802"
"9.33400","0.07760","221.78215","0.00485","4.41222"
"9.36600","0.07786","223.82317","0.00487","4.45282"
"9.40200","0.07813","225.99252","0.00488","4.49598"
"9.43400","0.07840","228.07733","0.00490","4.53745"
"9.46600","0.07868","230.17047","0.00492","4.57910"
"9.50100","0.07897","232.26373","0.00494","4.62074"
"9.53700","0.07925","234.33844","0.00495","4.66202"
"9.57300","0.07953","236.43987","0.00497","4.70382"
"9.60600","0.07981","238.52914","0.00499","4.74539"
"9.63800","0.08008","240.59991","0.00500","4.78658"
"9.67300","0.08036","242.73854","0.00502","4.82913"
"9.70800","0.08063","244.89326","0.00504","4.87200"
"9.74300","0.08091","247.01295","0.00506","4.91417"
"9.77700","0.08118","249.10439","0.00507","4.95577"
"9.80900","0.08145","251.31476","0.00509","4.99975"
"9.84100","0.08172","253.53056","0.00511","5.04383"
"9.87300","0.08198","255.64603","0.00512","5.08592"
"9.90500","0.08225","257.76456","0.00514","5.12806"
"9.93800","0.08253","259.89651","0.00516","5.17048"
"9.97400","0.08282","262.09576","0.00518","5.21423"
"10.01000","0.08311","264.22183","0.00519","5.25653"
"10.04500","0.08339","266.32538","0.00521","5.29838"
"10.07700","0.08368","268.52454","0.00523","5.34213"
"10.11100","0.08396","270.66675","0.00525","5.38474"
"10.14600","0.08424","272.83795","0.00526","5.42794"
"10.17800","0.08451","274.94940","0.00528","5.46994"
"10.20800","0.08478","277.06000","0.00530","5.51193"
"10.24000","0.08505","279.12265","0.00532","5.55297"
"10.27200","0.08530","281.17459","0.00533","5.59379"
"10.30400","0.08556","283.32639","0.00535","5.63660"
"10.33600","0.08581","285.38986","0.00536","5.67765"
"10.36800","0.08607","287.44748","0.00538","5.71859"
"10.40000","0.08635","289.66269","0.00540","5.76266"
"10.43300","0.08663","291.78622","0.00541","5.80490"
"10.46500","0.08691","293.93158","0.00543","5.84758"
"10.49900","0.08720","296.09070","0.00545","5.89054"
"10.53100","0.08748","298.22958","0.00547","5.93309"
"10.56400","0.08776","300.34198","0.00548","5.97511"
"10.59700","0.08803","302.44904","0.00550","6.01703"
"10.63000","0.08830","304.53854","0.00552","6.05860"
"10.66300","0.08856","306.60553","0.00553","6.09972"
"10.69500","0.08884","308.81650","0.00555","6.14371"
"10.72700","0.08913","311.07547","0.00557","6.18865"
"10.75900","0.08939","313.23978","0.00559","6.23171"
"10.78900","0.08965","315.41483","0.00560","6.27498"
"10.81700","0.08991","317.52841","0.00562","6.31703"
"10.84900","0.09018","319.68616","0.00564","6.35995"
"10.88100","0.09046","321.87173","0.00565","6.40344"
"10.91500","0.09074","323.98798","0.00567","6.44554"
"10.95100","0.09103","326.16653","0.00569","6.48888"
"10.98500","0.09131","328.27695","0.00571","6.53086"
"11.01700","0.09158","330.37427","0.00572","6.57259"
"11.04900","0.09184","332.40402","0.00574","6.61297"
"11.08100","0.09211","334.50885","0.00576","6.65484"
"11.11300","0.09237","336.57883","0.00577","6.69602"
"11.14500","0.09264","338.71280","0.00579","6.73848"
"11.17700","0.09292","340.87054","0.00581","6.78140"
"11.20900","0.09319","342.99887","0.00582","6.82375"
"11.24200","0.09345","345.13348","0.00584","6.86621"
"11.27400","0.09370","347.23474","0.00586","6.90802"
"11.30600","0.09396","349.35419","0.00587","6.95018"
"11.34000","0.09423","351.49527","0.00589","6.99278"
"11.37500","0.09451","353.67386","0.00591","7.03612"
"11.41100","0.09478","355.77826","0.00592","7.07798"
"11.44500","0.09507","357.88675","0.00594","7.11993"
"11.47800","0.09535","359.95224","0.00596","7.16102"
"11.51400","0.09562","362.09143","0.00598","7.20358"
"11.54800","0.09590","364.22394","0.00599","7.24601"
"11.58000","0.09617","366.34793","0.00601","7.28826"
"11.61300","0.09643","368.40726","0.00603","7.32923"
"11.64500","0.09670","370.49490","0.00604","7.37076"
"11.67700","0.09696","372.51697","0.00606","7.41099"
"11.71000","0.09723","374.62436","0.00608","7.45292"
"11.73900","0.09748","376.69806","0.00609","7.49417"
"11.77100","0.09774","378.89441","0.00611","7.53787"
"11.80300","0.09802","381.10452","0.00613","7.58183"
"11.83500","0.09830","383.33322","0.00614","7.62617"
"11.86700","0.09857","385.46576","0.00616","7.66860"
"11.90200","0.09886","387.61417","0.00618","7.71134"
"11.93600","0.09914","389.73120","0.00620","7.75346"
"11.96800","0.09942","391.81427","0.00621","7.79490"
"12.00000","0.09968","393.85999","0.00623","7.83560"
"12.03200","0.09996","396.00424","0.00625","7.87825"
"12.06500","0.10022","398.08649","0.00626","7.91968"
"12.09700","0.10049","400.18103","0.00628","7.96135"
"12.12900","0.10076","402.29910","0.00630","8.00349"
"12.16100","0.10104","404.40985","0.00631","8.04548"
"12.19400","0.10129","406.48340","0.00633","8.08673"
"12.22600","0.10155","408.65836","0.00635","8.13000"
"12.25600","0.10181","410.74957","0.00636","8.17160"
"12.28800","0.10207","412.83011","0.00638","8.21299"
"12.31900","0.10234","414.98627","0.00640","8.25589"
"12.34700","0.10260","417.00366","0.00641","8.29602"
"12.38000","0.10288","419.15576","0.00643","8.33884"
"12.41300","0.10317","421.25851","0.00645","8.38067"
"12.44500","0.10345","423.38373","0.00647","8.42295"
"12.47800","0.10372","425.51587","0.00648","8.46537"
"12.50900","0.10400","427.64255","0.00650","8.50768"
"12.54000","0.10427","429.79944","0.00652","8.55059"
"12.57500","0.10454","431.89905","0.00653","8.59236"
"12.60900","0.10482","434.07642","0.00655","8.63568"
"12.63800","0.10508","436.15039","0.00657","8.67694"
"12.67000","0.10535","438.27341","0.00658","8.71917"
"12.70200","0.10561","440.47244","0.00660","8.76292"
"12.73200","0.10587","442.62836","0.00662","8.80581"
"12.76000","0.10613","444.67499","0.00663","8.84653"
"12.78900","0.10639","446.77261","0.00665","8.88826"
"12.82100","0.10667","448.92041","0.00667","8.93099"
"12.85700","0.10696","451.08615","0.00669","8.97407"
"12.89300","0.10724","453.16089","0.00670","9.01535"
"12.92800","0.10752","455.26913","0.00672","9.05729"
"12.96000","0.10779","457.35800","0.00674","9.09885"
"12.99600","0.10806","459.54010","0.00675","9.14226"
"13.03200","0.10834","461.71783","0.00677","9.18559"
"13.06500","0.10862","463.88779","0.00679","9.22875"
"13.09800","0.10889","465.98746","0.00681","9.27053"
"13.13300","0.10917","468.17072","0.00682","9.31396"
"13.16500","0.10942","470.24692","0.00684","9.35527"
"13.19700","0.10967","472.37082","0.00685","9.39752"
"13.22900","0.10993","474.52841","0.00687","9.44044"
"13.26100","0.11020","476.62344","0.00689","9.48212"
"13.29300","0.11046","478.66907","0.00690","9.52282"
"13.32500","0.11073","480.73849","0.00692","9.56399"
"13.35800","0.11100","482.80392","0.00694","9.60508"
"13.39400","0.11128","484.89255","0.00696","9.64663"
"13.42700","0.11156","487.04129","0.00697","9.68938"
"13.45900","0.11184","489.19055","0.00699","9.73214"
"13.49100","0.11210","491.28571","0.00701","9.77382"
"13.52300","0.11238","493.46304","0.00702","9.81714"
"13.55500","0.11266","495.63217","0.00704","9.86029"
"13.58900","0.11293","497.73669","0.00706","9.90216"
"13.62100","0.11319","499.84143","0.00707","9.94403"
"13.65300","0.11345","501.99390","0.00709","9.98685"
"13.68500","0.11371","504.14014","0.00711","10.02955"
"13.71700","0.11398","506.35828","0.00712","10.07368"
"13.74900","0.11426","508.57986","0.00714","10.11788"
"13.77800","0.11453","510.67020","0.00716","10.15946"
"13.81000","0.11481","512.79749","0.00718","10.20178"
"13.84300","0.11509","514.88702","0.00719","10.24335"
"13.87900","0.11538","517.05969","0.00721","10.28658"
"13.91400","0.11566","519.20667","0.00723","10.32929"
"13.94600","0.11593","521.35095","0.00725","10.37195"
"13.97800","0.11622","523.56848","0.00726","10.41606"
"14.01000","0.11649","525.74158","0.00728","10.45930"
"14.04300","0.11676","527.83008","0.00730","10.50085"
"14.07500","0.11704","529.97064","0.00731","10.54343"
"14.10700","0.11730","532.12146","0.00733","10.58622"
"14.13700","0.11756","534.27490","0.00735","10.62906"
"14.16700","0.11782","536.40576","0.00736","10.67145"
"14.19900","0.11809","538.59131","0.00738","10.71493"
"14.22700","0.11835","540.66260","0.00740","10.75614"
"14.25800","0.11862","542.76984","0.00741","10.79806"
"14.29500","0.11891","544.89258","0.00743","10.84029"
"14.32900","0.11919","547.00037","0.00745","10.88223"
"14.36100","0.11948","549.15717","0.00747","10.92514"
"14.39400","0.11975","551.26758","0.00748","10.96712"
"14.42700","0.12002","553.39459","0.00750","11.00944"
"14.46000","0.12030","555.51282","0.00752","11.05158"
"14.49400","0.12056","557.58917","0.00754","11.09289"
"14.52600","0.12083","559.67151","0.00755","11.13431"
"14.56100","0.12111","561.84418","0.00757","11.17754"
"14.59100","0.12137","563.95270","0.00759","11.21948"
"14.62300","0.12162","566.09857","0.00760","11.26217"
"14.65900","0.12189","568.23694","0.00762","11.30472"
"14.69300","0.12216","570.38104","0.00763","11.34737"
"14.72500","0.12243","572.56702","0.00765","11.39086"
"14.75900","0.12270","574.62964","0.00767","11.43189"
"14.79400","0.12298","576.69604","0.00769","11.47300"
"14.82600","0.12326","578.76013","0.00770","11.51407"
"14.86100","0.12354","580.94031","0.00772","11.55744"
"14.89300","0.12381","583.01996","0.00774","11.59881"
"14.92500","0.12407","585.09509","0.00775","11.64010"
"14.95700","0.12433","587.11633","0.00777","11.68031"
"14.99100","0.12460","589.23419","0.00779","11.72244"
"15.02300","0.12486","591.26208","0.00780","11.76279"
"15.05500","0.12513","593.32709","0.00782","11.80387"
"15.08600","0.12538","595.40332","0.00784","11.84517"
"15.11400","0.12563","597.46527","0.00785","11.88619"
"15.14600","0.12589","599.60211","0.00787","11.92871"
"15.18000","0.12616","601.74219","0.00788","11.97128"
"15.21400","0.12644","603.91016","0.00790","12.01441"
"15.24600","0.12672","606.03754","0.00792","12.05673"
"15.27900","0.12700","608.17987","0.00794","12.09935"
"15.31500","0.12730","610.35736","0.00796","12.14267"
"15.34700","0.12757","612.48859","0.00797","12.18507"
"15.37900","0.12784","614.56641","0.00799","12.22641"
"15.41100","0.12812","616.67358","0.00801","12.26833"
"15.44300","0.12838","618.75079","0.00802","12.30966"
"15.47600","0.12866","620.86847","0.00804","12.35179"
"15.51100","0.12893","623.02527","0.00806","12.39469"
"15.54300","0.12921","625.16040","0.00808","12.43717"
"15.57500","0.12946","627.27826","0.00809","12.47931"
"15.60400","0.12971","629.35657","0.00811","12.52065"
"15.63500","0.12998","631.54932","0.00812","12.56427"
"15.66600","0.13026","633.74829","0.00814","12.60802"
"15.69600","0.13053","635.88867","0.00816","12.65060"
"15.72800","0.13081","637.96942","0.00818","12.69200"
"15.76000","0.13110","640.11432","0.00819","12.73467"
"15.79200","0.13139","642.34863","0.00821","12.77912"
"15.82400","0.13167","644.45221","0.00823","12.82097"
"15.85600","0.13193","646.48096","0.00825","12.86133"
"15.88800","0.13220","648.53107","0.00826","12.90212"
"15.92400","0.13248","650.68579","0.00828","12.94498"
"15.96000","0.13274","652.75708","0.00830","12.98619"
"15.99200","0.13302","654.86475","0.00831","13.02812"
"16.02400","0.13329","657.05322","0.00833","13.07166"
"16.05600","0.13355","659.20844","0.00835","13.11454"
"16.08400","0.13380","661.28259","0.00836","13.15580"
"16.11500","0.13406","663.40948","0.00838","13.19811"
"16.14700","0.13432","665.44769","0.00840","13.23866"
"16.17900","0.13460","667.53290","0.00841","13.28015"
"16.21100","0.13488","669.65802","0.00843","13.32242"
"16.24600","0.13517","671.78973","0.00845","13.36483"
"16.28000","0.13545","673.91571","0.00847","13.40713"
"16.31200","0.13573","676.06451","0.00848","13.44988"
"16.34700","0.13601","678.22211","0.00850","13.49280"
"16.38200","0.13629","680.37830","0.00852","13.53570"
"16.41800","0.13657","682.53833","0.00854","13.57867"
"16.45100","0.13684","684.60175","0.00855","13.61972"
"16.48600","0.13712","686.75195","0.00857","13.66250"
"16.51800","0.13738","688.89465","0.00859","13.70512"
"16.55000","0.13763","690.97998","0.00860","13.74661"
"16.58300","0.13789","693.05804","0.00862","13.78795"
"16.62100","0.13816","695.16473","0.00863","13.82986"
"16.65400","0.13842","697.22510","0.00865","13.87085"
"16.68600","0.13870","699.33197","0.00867","13.91277"
"16.71800","0.13899","701.45148","0.00869","13.95493"
"16.75000","0.13926","703.50836","0.00870","13.99585"
"16.78200","0.13954","705.60254","0.00872","14.03752"
"16.81400","0.13981","707.70691","0.00874","14.07938"
"16.84800","0.14009","709.83350","0.00876","14.12169"
"16.88300","0.14036","711.95184","0.00877","14.16383"
"16.91500","0.14064","714.11920","0.00879","14.20695"
"16.94700","0.14093","716.32904","0.00881","14.25091"
"16.97900","0.14119","718.42261","0.00882","14.29256"
"17.01400","0.14146","720.57416","0.00884","14.33537"
"17.04600","0.14173","722.77362","0.00886","14.37912"
"17.07800","0.14199","724.90308","0.00887","14.42149"
"17.11000","0.14227","727.06427","0.00889","14.46449"
"17.14200","0.14255","729.28107","0.00891","14.50859"
"17.17400","0.14283","731.35150","0.00893","14.54978"
"17.20800","0.14312","733.45819","0.00895","14.59169"
"17.24400","0.14340","735.55664","0.00896","14.63344"
"17.27600","0.14369","737.74536","0.00898","14.67698"
"17.30800","0.14397","739.92462","0.00900","14.72033"
"17.34100","0.14425","742.02954","0.00902","14.76221"
"17.37300","0.14453","744.19977","0.00903","14.80538"
"17.40800","0.14481","746.38007","0.00905","14.84876"
"17.44100","0.14509","748.56573","0.00907","14.89224"
"17.47100","0.14536","750.70398","0.00908","14.93478"
"17.50300","0.14563","752.91229","0.00910","14.97871"
"17.53300","0.14589","755.05066","0.00912","15.02126"
"17.56500","0.14617","757.24396","0.00914","15.06489"
"17.59700","0.14645","759.41382","0.00915","15.10806"
"17.62700","0.14672","761.47314","0.00917","15.14903"
"17.66300","0.14701","763.57062","0.00919","15.19076"
"17.69900","0.14730","765.69305","0.00921","15.23298"
"17.73400","0.14759","767.85046","0.00922","15.27590"
"17.77000","0.14788","770.05542","0.00924","15.31977"
"17.80200","0.14816","772.21326","0.00926","15.36270"
"17.83600","0.14843","774.32727","0.00928","15.40475"
"17.87100","0.14872","776.47644","0.00929","15.44751"
"17.90300","0.14900","778.69299","0.00931","15.49161"
"17.93500","0.14926","780.73016","0.00933","15.53213"
"17.96700","0.14952","782.88135","0.00935","15.57493"
"17.99600","0.14978","784.97577","0.00936","15.61660"
"18.02800","0.15004","787.04425","0.00938","15.65775"
"18.06200","0.15032","789.14966","0.00939","15.69963"
"18.09800","0.15059","791.23651","0.00941","15.74115"
"18.13400","0.15087","793.26068","0.00943","15.78142"
"18.17200","0.15116","795.37756","0.00945","15.82353"
"18.20700","0.15145","797.51318","0.00947","15.86602"
"18.24100","0.15173","799.65533","0.00948","15.90864"
"18.27400","0.15201","801.77490","0.00950","15.95081"
"18.30600","0.15229","803.91388","0.00952","15.99336"
"18.33800","0.15256","806.04077","0.00954","16.03567"
"18.37300","0.15285","808.20050","0.00955","16.07864"
"18.40600","0.15312","810.32874","0.00957","16.12098"
"18.43800","0.15338","812.42310","0.00959","16.16265"
"18.47200","0.15364","814.54108","0.00960","16.20478"
"18.50700","0.15392","816.72015","0.00962","16.24813"
"18.53900","0.15419","818.88629","0.00964","16.29123"
"18.57100","0.15447","821.02850","0.00965","16.33384"
"18.60300","0.15475","823.15118","0.00967","16.37607"
"18.64100","0.15505","825.29321","0.00969","16.41869"
"18.67700","0.15534","827.42822","0.00971","16.46116"
"18.71000","0.15562","829.51959","0.00973","16.50277"
"18.74200","0.15590","831.70758","0.00974","16.54630"
"18.77400","0.15618","833.87469","0.00976","16.58941"
"18.80600","0.15645","835.92609","0.00978","16.63022"
"18.83800","0.15672","837.97729","0.00979","16.67103"
"18.87100","0.15699","840.06073","0.00981","16.71248"
"18.90300","0.15726","842.20203","0.00983","16.75508"
"18.93500","0.15752","844.30377","0.00985","16.79689"
"18.96500","0.15778","846.43103","0.00986","16.83921"
"18.99700","0.15806","848.62323","0.00988","16.88282"
"19.02900","0.15835","850.84949","0.00990","16.92711"
"19.06100","0.15863","852.96783","0.00991","16.96926"
"19.09300","0.15891","855.02930","0.00993","17.01027"
"19.12600","0.15920","857.13434","0.00995","17.05215"
"19.16400","0.15948","859.22552","0.00997","17.09375"
"19.19900","0.15976","861.34778","0.00999","17.13597"
"19.23100","0.16005","863.52826","0.01000","17.17935"
"19.26300","0.16033","865.73059","0.01002","17.22316"
"19.29500","0.16060","867.78320","0.01004","17.26400"
"19.32800","0.16088","869.91754","0.01005","17.30646"
"19.36400","0.16116","872.06262","0.01007","17.34914"
"19.39800","0.16142","874.21930","0.01009","17.39204"
"19.43000","0.16169","876.43463","0.01011","17.43611"
"19.46200","0.16197","878.66394","0.01012","17.48046"
"19.49400","0.16224","880.77209","0.01014","17.52241"
"19.52600","0.16251","882.85602","0.01016","17.56386"
"19.55900","0.16279","884.99213","0.01017","17.60636"
"19.59400","0.16308","887.09509","0.01019","17.64820"
"19.62900","0.16337","889.24054","0.01021","17.69088"
"19.66400","0.16365","891.38617","0.01023","17.73356"
"19.69600","0.16392","893.45886","0.01025","17.77480"
"19.73200","0.16420","895.56409","0.01026","17.81668"
"19.76600","0.16447","897.67023","0.01028","17.85858"
"19.80100","0.16476","899.84363","0.01030","17.90182"
"19.83300","0.16503","901.94647","0.01031","17.94366"
"19.86900","0.16530","904.12183","0.01033","17.98693"
"19.90300","0.16556","906.21021","0.01035","18.02848"
"19.93500","0.16581","908.26440","0.01036","18.06935"
"19.96700","0.16606","910.29529","0.01038","18.10975"
"20.00300","0.16634","912.42133","0.01040","18.15205"
"20.03500","0.16660","914.50659","0.01041","18.19353"
"20.06700","0.16688","916.56989","0.01043","18.23458"
"20.10000","0.16717","918.68109","0.01045","18.27658"
"20.13400","0.16745","920.81177","0.01047","18.31897"
"20.16600","0.16773","922.98199","0.01048","18.36214"
"20.19900","0.16800","925.07825","0.01050","18.40385"
"20.23100","0.16828","927.20404","0.01052","18.44614"
"20.26300","0.16854","929.27863","0.01053","18.48741"
"20.29700","0.16882","931.36938","0.01055","18.52901"
"20.33200","0.16909","933.50641","0.01057","18.57152"
"20.36400","0.16936","935.65552","0.01058","18.61428"
"20.39600","0.16962","937.82672","0.01060","18.65747"
"20.42800","0.16988","939.91913","0.01062","18.69910"
"20.46000","0.17015","942.10693","0.01063","18.74262"
"20.49200","0.17042","944.20923","0.01065","18.78445"
"20.52400","0.17070","946.39148","0.01067","18.82786"
"20.55600","0.17099","948.52216","0.01069","18.87025"
"20.58800","0.17127","950.65735","0.01070","18.91273"
"20.61900","0.17156","952.83636","0.01072","18.95608"
"20.65100","0.17184","955.03326","0.01074","18.99978"
"20.68400","0.17212","957.18201","0.01076","19.04253"
"20.72000","0.17241","959.40332","0.01078","19.08672"
"20.75200","0.17267","961.47620","0.01079","19.12796"
"20.78300","0.17295","963.65009","0.01081","19.17121"
"20.81500","0.17323","965.89014","0.01083","19.21577"
"20.84500","0.17349","968.04816","0.01084","19.25871"
"20.87300","0.17374","970.09113","0.01086","19.29935"
"20.90300","0.17399","972.18805","0.01087","19.34107"
"20.93500","0.17426","974.25757","0.01089","19.38224"
"20.96900","0.17453","976.40039","0.01091","19.42487"
"21.00500","0.17482","978.54102","0.01093","19.46746"
"21.04100","0.17511","980.66199","0.01094","19.50965"
"21.07500","0.17539","982.76080","0.01096","19.55140"
"21.10700","0.17566","984.88116","0.01098","19.59359"
"21.13900","0.17594","987.05548","0.01100","19.63685"
"21.17100","0.17622","989.23682","0.01101","19.68024"
"21.20300","0.17649","991.35059","0.01103","19.72229"
"21.23500","0.17675","993.38977","0.01105","19.76286"
"21.26800","0.17702","995.50208","0.01106","19.80489"
"21.30200","0.17729","997.67218","0.01108","19.84806"
"21.33200","0.17755","999.79657","0.01110","19.89032"
"21.36000","0.17779","1001.82831","0.01111","19.93074"
"21.39000","0.17805","1003.91986","0.01113","19.97235"
"21.42500","0.17832","1006.01819","0.01115","20.01410"
"21.45800","0.17859","1008.13947","0.01116","20.05630"
"21.49200","0.17888","1010.25250","0.01118","20.09834"
"21.52800","0.17916","1012.31934","0.01120","20.13945"
"21.56400","0.17943","1014.38641","0.01121","20.18058"
"21.59700","0.17970","1016.49011","0.01123","20.22243"
"21.63100","0.17998","1018.59308","0.01125","20.26427"
"21.66700","0.18026","1020.80975","0.01127","20.30836"
"21.70300","0.18054","1022.98712","0.01128","20.35168"
"21.73500","0.18082","1025.17383","0.01130","20.39519"
"21.76700","0.18109","1027.31152","0.01132","20.43771"
"21.79900","0.18136","1029.54175","0.01134","20.48208"
"21.83100","0.18162","1031.68762","0.01135","20.52477"
"21.86300","0.18189","1033.91467","0.01137","20.56908"
"21.89500","0.18216","1036.06152","0.01138","20.61179"
"21.92900","0.18243","1038.19641","0.01140","20.65426"
"21.96100","0.18270","1040.28735","0.01142","20.69586"
"21.99700","0.18300","1042.43005","0.01144","20.73849"
"22.03200","0.18328","1044.57495","0.01146","20.78116"
"22.06400","0.18355","1046.65796","0.01147","20.82260"
"22.09600","0.18383","1048.80334","0.01149","20.86528"
"22.12800","0.18411","1050.95789","0.01151","20.90814"
"22.16000","0.18439","1053.15051","0.01152","20.95177"
"22.19300","0.18465","1055.23901","0.01154","20.99331"
"22.22800","0.18493","1057.35754","0.01156","21.03546"
"22.26000","0.18520","1059.50537","0.01158","21.07819"
"22.29100","0.18547","1061.70886","0.01159","21.12203"
"22.31900","0.18571","1063.73669","0.01161","21.16237"
"22.35100","0.18599","1066.00806","0.01162","21.20756"
"22.38300","0.18627","1068.24695","0.01164","21.25210"
"22.41500","0.18655","1070.41699","0.01166","21.29527"
"22.44800","0.18684","1072.57751","0.01168","21.33825"
"22.48300","0.18713","1074.74048","0.01170","21.38128"
"22.51800","0.18742","1076.92468","0.01171","21.42474"
"22.55000","0.18769","1079.03491","0.01173","21.46672"
"22.58500","0.18798","1081.20459","0.01175","21.50988"
"22.61800","0.18825","1083.35657","0.01177","21.55269"
"22.65000","0.18853","1085.56995","0.01178","21.59673"
"22.68200","0.18880","1087.67407","0.01180","21.63859"
"22.71600","0.18908","1089.83264","0.01182","21.68153"
"22.74800","0.18935","1092.02417","0.01183","21.72513"
"22.78000","0.18962","1094.23059","0.01185","21.76903"
"22.81200","0.18989","1096.45032","0.01187","21.81319"
"22.84400","0.19016","1098.63867","0.01189","21.85672"
"22.87700","0.19043","1100.71057","0.01190","21.89794"
"22.90900","0.19071","1102.81042","0.01192","21.93972"
"22.94500","0.19100","1104.92578","0.01194","21.98180"
"22.98000","0.19128","1107.01306","0.01195","22.02333"
"23.01500","0.19156","1109.16064","0.01197","22.06605"
"23.04800","0.19183","1111.26575","0.01199","22.10793"
"23.08000","0.19212","1113.46533","0.01201","22.15169"
"23.11200","0.19239","1115.58899","0.01202","22.19394"
"23.14400","0.19267","1117.81897","0.01204","22.23830"
"23.17700","0.19295","1119.94250","0.01206","22.28055"
"23.21300","0.19323","1122.13757","0.01208","22.32422"
"23.24500","0.19348","1124.20581","0.01209","22.36537"
"23.27800","0.19374","1126.31653","0.01211","22.40736"
"23.31100","0.19401","1128.49609","0.01213","22.45072"
"23.34400","0.19427","1130.59290","0.01214","22.49243"
"23.38000","0.19456","1132.77795","0.01216","22.53590"
"23.41600","0.19485","1134.95886","0.01218","22.57929"
"23.45200","0.19513","1137.01636","0.01220","22.62022"
"23.48800","0.19541","1139.14221","0.01221","22.66252"
"23.52400","0.19569","1141.24524","0.01223","22.70435"
"23.55600","0.19597","1143.41492","0.01225","22.74752"
"23.58800","0.19624","1145.59119","0.01227","22.79081"
"23.62100","0.19652","1147.73535","0.01228","22.83347"
"23.65600","0.19679","1149.87915","0.01230","22.87612"
"23.68800","0.19706","1151.92285","0.01232","22.91678"
"23.72300","0.19732","1154.04382","0.01233","22.95897"
"23.75600","0.19757","1156.12134","0.01235","23.00031"
"23.78800","0.19783","1158.29871","0.01236","23.04362"
"23.82000","0.19811","1160.52795","0.01238","23.08797"
"23.85300","0.19838","1162.63623","0.01240","23.12991"
"23.88200","0.19864","1164.72058","0.01242","23.17138"
"23.91400","0.19893","1166.92151","0.01243","23.21517"
"23.94600","0.19922","1169.04590","0.01245","23.25743"
"23.97800","0.19949","1171.16626","0.01247","23.29961"
"24.00900","0.19977","1173.33801","0.01249","23.34282"
"24.04100","0.20005","1175.50781","0.01250","23.38599"
"24.07300","0.20031","1177.55127","0.01252","23.42664"
"24.10200","0.20058","1179.65308","0.01254","23.46845"
"24.13300","0.20086","1181.83289","0.01255","23.51182"
"24.16500","0.20113","1183.94336","0.01257","23.55381"
"24.20000","0.20140","1186.12207","0.01259","23.59715"
"24.23200","0.20166","1188.31482","0.01260","23.64077"
"24.26400","0.20192","1190.49158","0.01262","23.68408"
"24.29600","0.20220","1192.66370","0.01264","23.72729"
"24.32800","0.20247","1194.81946","0.01265","23.77018"
"24.36100","0.20275","1196.90967","0.01267","23.81176"
"24.39700","0.20304","1199.12842","0.01269","23.85590"
"24.43000","0.20332","1201.21387","0.01271","23.89739"
"24.46200","0.20359","1203.34436","0.01272","23.93978"
"24.49400","0.20387","1205.50439","0.01274","23.98275"
"24.52600","0.20415","1207.73328","0.01276","24.02709"
"24.55900","0.20442","1209.82935","0.01278","24.06879"
"24.59100","0.20469","1211.96863","0.01279","24.11135"
"24.62500","0.20497","1214.11890","0.01281","24.15413"
"24.65800","0.20524","1216.21838","0.01283","24.19590"
"24.69000","0.20550","1218.33459","0.01284","24.23800"
"24.72200","0.20576","1220.49902","0.01286","24.28106"
"24.75400","0.20603","1222.65710","0.01288","24.32399"
"24.78600","0.20629","1224.70923","0.01289","24.36482"
"24.81800","0.20655","1226.77026","0.01291","24.40582"
"24.85000","0.20682","1228.83301","0.01293","24.44686"
"24.88500","0.20711","1230.94788","0.01294","24.48893"
"24.92000","0.20739","1233.06079","0.01296","24.53097"
"24.95200","0.20766","1235.18677","0.01298","24.57326"
"24.98400","0.20793","1237.30396","0.01300","24.61538"
"25.01700","0.20820","1239.43396","0.01301","24.65776"
"25.04900","0.20847","1241.57715","0.01303","24.70039"
"25.08100","0.20874","1243.65930","0.01305","24.74182"
"25.11700","0.20902","1245.82910","0.01306","24.78498"
"25.15300","0.20928","1247.91333","0.01308","24.82645"
"25.18600","0.20954","1250.08923","0.01310","24.86974"
"25.21600","0.20979","1252.21875","0.01311","24.91210"
"25.24500","0.21005","1254.33069","0.01313","24.95412"
"25.27500","0.21032","1256.46948","0.01314","24.99667"
"25.30700","0.21060","1258.68213","0.01316","25.04069"
"25.34300","0.21089","1260.80725","0.01318","25.08296"
"25.38100","0.21118","1262.93567","0.01320","25.12531"
"25.41500","0.21145","1265.01587","0.01322","25.16669"
"25.44700","0.21172","1267.18091","0.01323","25.20976"
"25.47800","0.21200","1269.36987","0.01325","25.25331"
"25.51200","0.21227","1271.50281","0.01327","25.29575"
"25.54400","0.21254","1273.61926","0.01328","25.33785"
"25.57300","0.21280","1275.69214","0.01330","25.37909"
"25.60500","0.21308","1277.86597","0.01332","25.42234"
"25.63700","0.21333","1279.93176","0.01333","25.46343"
"25.66600","0.21358","1282.10645","0.01335","25.50670"
"25.69600","0.21384","1284.27588","0.01337","25.54986"
"25.72800","0.21411","1286.45886","0.01338","25.59329"
"25.76000","0.21437","1288.50488","0.01340","25.63399"
"25.78800","0.21464","1290.67981","0.01342","25.67726"
"25.81900","0.21492","1292.82581","0.01343","25.71995"
"25.85500","0.21522","1295.01477","0.01345","25.76350"
"25.89000","0.21550","1297.14563","0.01347","25.80589"
"25.92200","0.21577","1299.30786","0.01349","25.84891"
"25.95100","0.21603","1301.40991","0.01350","25.89073"
"25.98600","0.21631","1303.56958","0.01352","25.93369"
"26.01800","0.21657","1305.65503","0.01354","25.97518"
"26.05000","0.21683","1307.71570","0.01355","26.01618"
"26.08300","0.21711","1309.88464","0.01357","26.05933"
"26.11200","0.21736","1311.98059","0.01358","26.10103"
"26.14300","0.21761","1314.14880","0.01360","26.14416"
"26.17100","0.21786","1316.21082","0.01362","26.18518"
"26.20300","0.21812","1318.35608","0.01363","26.22786"
"26.23300","0.21838","1320.45483","0.01365","26.26962"
"26.26400","0.21865","1322.57458","0.01367","26.31179"
"26.30000","0.21894","1324.75842","0.01368","26.35523"
"26.33300","0.21922","1326.88501","0.01370","26.39754"
"26.36500","0.21950","1329.05066","0.01372","26.44062"
"26.39700","0.21977","1331.22314","0.01374","26.48384"
"26.42900","0.22004","1333.34058","0.01375","26.52597"
"26.46100","0.22032","1335.56226","0.01377","26.57017"
"26.49400","0.22059","1337.74438","0.01379","26.61358"
"26.53000","0.22087","1339.91614","0.01380","26.65679"
"26.56200","0.22112","1341.97693","0.01382","26.69778"
"26.59100","0.22137","1344.11279","0.01384","26.74028"
"26.62100","0.22163","1346.28271","0.01385","26.78345"
"26.65200","0.22188","1348.44092","0.01387","26.82638"
"26.68300","0.22214","1350.53247","0.01388","26.86799"
"26.71600","0.22240","1352.62427","0.01390","26.90961"
"26.75100","0.22268","1354.79236","0.01392","26.95274"
"26.78400","0.22297","1356.99390","0.01394","26.99654"
"26.82000","0.22325","1359.16821","0.01395","27.03979"
"26.85600","0.22354","1361.39038","0.01397","27.08400"
"26.89100","0.22381","1363.58020","0.01399","27.12757"
"26.92300","0.22408","1365.69336","0.01400","27.16961"
"26.95800","0.22435","1367.82812","0.01402","27.21208"
"26.99000","0.22460","1369.89185","0.01404","27.25313"
"27.02200","0.22487","1372.02869","0.01405","27.29564"
"27.05400","0.22513","1374.07263","0.01407","27.33631"
"27.08600","0.22539","1376.25916","0.01409","27.37981"
"27.11700","0.22564","1378.43115","0.01410","27.42302"
"27.14500","0.22588","1380.48206","0.01412","27.46382"
"27.17600","0.22613","1382.56360","0.01413","27.50523"
"27.20500","0.22639","1384.67981","0.01415","27.54733"
"27.23500","0.22665","1386.79370","0.01417","27.58939"
"27.26700","0.22692","1388.84424","0.01418","27.63018"
"27.29900","0.22719","1390.91162","0.01420","27.67131"
"27.32900","0.22746","1393.00586","0.01422","27.71297"
"27.35700","0.22772","1395.09314","0.01423","27.75450"
"27.39100","0.22799","1397.29211","0.01425","27.79824"
"27.42300","0.22826","1399.40601","0.01427","27.84030"
"27.45500","0.22852","1401.55676","0.01428","27.88309"
"27.48700","0.22879","1403.72412","0.01430","27.92620"
"27.52300","0.22906","1405.83301","0.01432","27.96816"
"27.55300","0.22931","1407.92200","0.01433","28.00972"
"27.58100","0.22956","1410.14050","0.01435","28.05386"
"27.60500","0.22981","1412.33936","0.01436","28.09760"
"27.63000","0.23006","1414.47290","0.01438","28.14005"
"27.65800","0.23032","1416.55725","0.01439","28.18151"
"27.68800","0.23059","1418.70435","0.01441","28.22423"
"27.71800","0.23086","1420.83716","0.01443","28.26666"
"27.75200","0.23114","1422.91577","0.01445","28.30801"
"27.79100","0.23142","1425.01721","0.01446","28.34982"
"27.82800","0.23169","1427.19714","0.01448","28.39319"
"27.86100","0.23196","1429.29419","0.01450","28.43491"
"27.89600","0.23222","1431.42578","0.01451","28.47731"
"27.92600","0.23249","1433.56970","0.01453","28.51996"
"27.95600","0.23275","1435.68811","0.01455","28.56211"
"27.99100","0.23302","1437.84912","0.01456","28.60510"
"28.02000","0.23327","1439.91443","0.01458","28.64619"
"28.05000","0.23351","1442.03003","0.01459","28.68828"
"28.08200","0.23377","1444.21680","0.01461","28.73178"
"28.11300","0.23403","1446.41492","0.01463","28.77551"
"28.14500","0.23429","1448.55518","0.01464","28.81809"
"28.17900","0.23456","1450.67334","0.01466","28.86023"
"28.21100","0.23482","1452.69800","0.01468","28.90051"
"28.24400","0.23509","1454.77832","0.01469","28.94190"
"28.28000","0.23537","1456.88904","0.01471","28.98389"
"28.31200","0.23563","1458.99036","0.01473","29.02569"
"28.34400","0.23590","1461.18359","0.01474","29.06932"
"28.37200","0.23615","1463.20435","0.01476","29.10953"
"28.40400","0.23642","1465.45947","0.01478","29.15439"
"28.43600","0.23669","1467.59949","0.01479","29.19697"
"28.47000","0.23696","1469.73230","0.01481","29.23940"
"28.50200","0.23722","1471.85950","0.01483","29.28172"
"28.53400","0.23747","1474.03284","0.01484","29.32495"
"28.56600","0.23772","1476.19629","0.01486","29.36799"
"28.59500","0.23797","1478.28516","0.01487","29.40955"
"28.62600","0.23823","1480.48865","0.01489","29.45339"
"28.65500","0.23849","1482.56152","0.01491","29.49463"
"28.68700","0.23876","1484.73669","0.01492","29.53790"
"28.72100","0.23904","1486.91870","0.01494","29.58131"
"28.75700","0.23933","1489.09167","0.01496","29.62454"
"28.78900","0.23959","1491.18469","0.01497","29.66618"
"28.82200","0.23985","1493.26294","0.01499","29.70752"
"28.85400","0.24011","1495.39539","0.01501","29.74995"
"28.88900","0.24038","1497.52747","0.01502","29.79236"
"28.92000","0.24064","1499.66028","0.01504","29.83479"
"28.92500","0.24068","1500.02820","0.01504","29.84211"