File: STRAIN_GAUGE/calibration test/2024-07-16/Steel_2.is_comp_RawData/Specimen_2_RawData_2.csv
Time,Extension,Load,Compressive strain (Extension),Compressive stress
(s),(mm),(N),(mm/mm),(MPa)
"0.00000","-0.00002","0.22022","0.00000","0.00438"
"0.04000","-0.00002","0.23228","0.00000","0.00462"
"0.08000","-0.00001","0.30207","0.00000","0.00601"
"0.12000","0.00003","0.37555","0.00000","0.00747"
"0.16000","0.00012","0.57905","0.00001","0.01152"
"0.20000","0.00033","1.24466","0.00002","0.02476"
"0.24000","0.00072","2.68437","0.00005","0.05340"
"0.28000","0.00120","4.71422","0.00007","0.09379"
"0.31800","0.00165","6.84087","0.00010","0.13609"
"0.35200","0.00204","8.95657","0.00013","0.17819"
"0.38600","0.00243","11.06939","0.00015","0.22022"
"0.42200","0.00281","13.23396","0.00018","0.26328"
"0.45700","0.00316","15.35545","0.00020","0.30549"
"0.48900","0.00349","17.47541","0.00022","0.34766"
"0.52300","0.00384","19.59485","0.00024","0.38983"
"0.56200","0.00419","21.73106","0.00026","0.43233"
"0.59900","0.00454","23.81260","0.00028","0.47374"
"0.63900","0.00492","25.89631","0.00031","0.51519"
"0.67800","0.00528","28.00323","0.00033","0.55711"
"0.71400","0.00561","30.07877","0.00035","0.59840"
"0.75300","0.00593","32.14630","0.00037","0.63953"
"0.79100","0.00624","34.23103","0.00039","0.68100"
"0.82700","0.00656","36.34335","0.00041","0.72303"
"0.86300","0.00687","38.47929","0.00043","0.76552"
"0.89900","0.00717","40.64087","0.00045","0.80852"
"0.93400","0.00746","42.79029","0.00047","0.85129"
"0.97000","0.00775","44.90997","0.00048","0.89346"
"1.00500","0.00805","47.02279","0.00050","0.93549"
"1.04100","0.00836","49.12451","0.00052","0.97730"
"1.07700","0.00869","51.29691","0.00054","1.02052"
"1.11600","0.00900","53.32826","0.00056","1.06093"
"1.15500","0.00932","55.42615","0.00058","1.10267"
"1.19100","0.00962","57.56377","0.00060","1.14519"
"1.22600","0.00992","59.70421","0.00062","1.18778"
"1.25900","0.01021","61.79637","0.00064","1.22940"
"1.29400","0.01049","63.93276","0.00066","1.27190"
"1.32900","0.01077","65.98457","0.00067","1.31272"
"1.36100","0.01105","68.08225","0.00069","1.35445"
"1.39300","0.01132","70.18855","0.00071","1.39636"
"1.42600","0.01160","72.27964","0.00073","1.43796"
"1.46200","0.01191","74.43071","0.00074","1.48075"
"1.49700","0.01221","76.50010","0.00076","1.52192"
"1.53100","0.01251","78.60122","0.00078","1.56372"
"1.56600","0.01283","80.72003","0.00080","1.60587"
"1.60300","0.01314","82.84610","0.00082","1.64817"
"1.63900","0.01344","84.97158","0.00084","1.69046"
"1.67100","0.01372","87.10699","0.00086","1.73294"
"1.70400","0.01400","89.21423","0.00087","1.77486"
"1.73900","0.01429","91.32396","0.00089","1.81683"
"1.77100","0.01457","93.35103","0.00091","1.85716"
"1.80700","0.01485","95.44355","0.00093","1.89879"
"1.84300","0.01512","97.54736","0.00095","1.94064"
"1.87300","0.01538","99.65002","0.00096","1.98247"
"1.90200","0.01564","101.75034","0.00098","2.02426"
"1.93400","0.01589","103.85927","0.00099","2.06621"
"1.96600","0.01617","106.06219","0.00101","2.11004"
"2.00200","0.01645","108.17313","0.00103","2.15204"
"2.04200","0.01677","110.31105","0.00105","2.19457"
"2.08100","0.01709","112.37184","0.00107","2.23557"
"2.11700","0.01738","114.48471","0.00109","2.27760"
"2.15300","0.01766","116.63241","0.00110","2.32033"
"2.18700","0.01793","118.74113","0.00112","2.36228"
"2.21900","0.01820","120.91049","0.00114","2.40544"
"2.25300","0.01848","123.07944","0.00115","2.44859"
"2.28600","0.01875","125.17105","0.00117","2.49020"
"2.31800","0.01902","127.22142","0.00119","2.53099"
"2.35000","0.01930","129.37054","0.00121","2.57375"
"2.38500","0.01956","131.55453","0.00122","2.61719"
"2.41700","0.01983","133.76898","0.00124","2.66125"
"2.44900","0.02010","135.92245","0.00126","2.70409"
"2.48300","0.02038","138.02788","0.00127","2.74598"
"2.51900","0.02069","140.19633","0.00129","2.78912"
"2.55500","0.02099","142.37103","0.00131","2.83238"
"2.58700","0.02126","144.48601","0.00133","2.87446"
"2.61900","0.02153","146.65732","0.00135","2.91765"
"2.64900","0.02181","148.80695","0.00136","2.96042"
"2.68300","0.02207","150.98035","0.00138","3.00366"
"2.71500","0.02234","153.16547","0.00140","3.04713"
"2.74800","0.02261","155.32161","0.00141","3.09003"
"2.78200","0.02286","157.43277","0.00143","3.13203"
"2.81200","0.02310","159.50513","0.00144","3.17325"
"2.84100","0.02336","161.63014","0.00146","3.21553"
"2.87300","0.02363","163.78708","0.00148","3.25844"
"2.90500","0.02390","165.96600","0.00149","3.30179"
"2.93700","0.02419","168.11891","0.00151","3.34462"
"2.97200","0.02448","170.27060","0.00153","3.38743"
"3.00400","0.02475","172.35793","0.00155","3.42895"
"3.03800","0.02502","174.45567","0.00156","3.47069"
"3.07000","0.02528","176.58447","0.00158","3.51304"
"3.10100","0.02555","178.77271","0.00160","3.55657"
"3.13300","0.02582","180.91075","0.00161","3.59911"
"3.16200","0.02608","183.00024","0.00163","3.64067"
"3.19000","0.02633","185.04376","0.00165","3.68133"
"3.21800","0.02659","187.22008","0.00166","3.72463"
"3.25000","0.02685","189.34035","0.00168","3.76681"
"3.28300","0.02712","191.47517","0.00169","3.80928"
"3.31100","0.02735","193.50624","0.00171","3.84968"
"3.33900","0.02759","195.54883","0.00172","3.89032"
"3.36900","0.02785","197.69896","0.00174","3.93310"
"3.40100","0.02813","199.88794","0.00176","3.97664"
"3.42900","0.02840","201.96259","0.00177","4.01792"
"3.45700","0.02866","204.05635","0.00179","4.05957"
"3.48900","0.02892","206.16878","0.00181","4.10160"
"3.52100","0.02918","208.29932","0.00182","4.14398"
"3.55000","0.02944","210.43242","0.00184","4.18642"
"3.58200","0.02969","212.55101","0.00186","4.22857"
"3.61400","0.02995","214.60591","0.00187","4.26945"
"3.64800","0.03021","216.68980","0.00189","4.31091"
"3.68200","0.03048","218.78717","0.00191","4.35263"
"3.71800","0.03076","220.95277","0.00192","4.39572"
"3.75400","0.03101","223.05984","0.00194","4.43763"
"3.78700","0.03126","225.26212","0.00195","4.48145"
"3.81500","0.03151","227.35730","0.00197","4.52313"
"3.84500","0.03176","229.51283","0.00198","4.56601"
"3.87900","0.03202","231.66228","0.00200","4.60877"
"3.90900","0.03229","233.79272","0.00202","4.65116"
"3.94100","0.03257","235.89276","0.00204","4.69294"
"3.97600","0.03282","237.96027","0.00205","4.73407"
"4.00700","0.03306","240.11835","0.00207","4.77700"
"4.03600","0.03330","242.21376","0.00208","4.81869"
"4.06400","0.03356","244.43314","0.00210","4.86284"
"4.09300","0.03382","246.54152","0.00211","4.90479"
"4.12800","0.03410","248.69881","0.00213","4.94771"
"4.15700","0.03436","250.76654","0.00215","4.98884"
"4.18900","0.03461","252.86234","0.00216","5.03054"
"4.21900","0.03486","255.04678","0.00218","5.07399"
"4.24300","0.03507","257.07266","0.00219","5.11430"
"4.27100","0.03530","259.28473","0.00221","5.15831"
"4.30200","0.03555","261.48929","0.00222","5.20216"
"4.33300","0.03581","263.67154","0.00224","5.24558"
"4.36100","0.03605","265.75388","0.00225","5.28701"
"4.39100","0.03630","267.83783","0.00227","5.32846"
"4.42700","0.03659","269.99332","0.00229","5.37135"
"4.46000","0.03688","272.11633","0.00230","5.41358"
"4.49200","0.03715","274.29388","0.00232","5.45690"
"4.52300","0.03741","276.38336","0.00234","5.49847"
"4.55500","0.03767","278.57214","0.00235","5.54202"
"4.58600","0.03792","280.65350","0.00237","5.58342"
"4.61500","0.03817","282.74777","0.00239","5.62509"
"4.64700","0.03844","284.95032","0.00240","5.66891"
"4.67900","0.03871","287.18439","0.00242","5.71335"
"4.71100","0.03897","289.35785","0.00244","5.75659"
"4.73900","0.03919","291.43530","0.00245","5.79792"
"4.76400","0.03942","293.56952","0.00246","5.84038"
"4.79100","0.03965","295.70367","0.00248","5.88284"
"4.82400","0.03990","297.85403","0.00249","5.92562"
"4.85300","0.04016","300.00809","0.00251","5.96847"
"4.88100","0.04042","302.18665","0.00253","6.01181"
"4.91100","0.04068","304.26663","0.00254","6.05319"
"4.94400","0.04095","306.41660","0.00256","6.09596"
"4.97500","0.04123","308.57578","0.00258","6.13892"
"5.00500","0.04150","310.66779","0.00259","6.18054"
"5.03900","0.04175","312.79355","0.00261","6.22283"
"5.07100","0.04202","315.00439","0.00263","6.26681"
"5.10000","0.04227","317.08694","0.00264","6.30824"
"5.13200","0.04252","319.31369","0.00266","6.35254"
"5.16000","0.04278","321.50488","0.00267","6.39614"
"5.18800","0.04303","323.68787","0.00269","6.43957"
"5.21800","0.04327","325.81927","0.00270","6.48197"
"5.25000","0.04353","328.07538","0.00272","6.52685"
"5.27800","0.04378","330.14819","0.00274","6.56809"
"5.31000","0.04402","332.27783","0.00275","6.61046"
"5.34300","0.04426","334.35895","0.00277","6.65186"
"5.37800","0.04453","336.51785","0.00278","6.69481"
"5.41400","0.04480","338.69223","0.00280","6.73807"
"5.44500","0.04507","340.79947","0.00282","6.77999"
"5.47300","0.04531","342.85538","0.00283","6.82089"
"5.50500","0.04556","344.97501","0.00285","6.86306"
"5.53700","0.04583","347.11612","0.00286","6.90566"
"5.56900","0.04609","349.28253","0.00288","6.94876"
"5.60400","0.04636","351.39529","0.00290","6.99079"
"5.63300","0.04661","353.47650","0.00291","7.03219"
"5.66300","0.04686","355.59305","0.00293","7.07430"
"5.69300","0.04711","357.82703","0.00294","7.11874"
"5.71900","0.04734","359.99802","0.00296","7.16193"
"5.74700","0.04758","362.28287","0.00297","7.20739"
"5.77500","0.04781","364.53918","0.00299","7.25228"
"5.80300","0.04804","366.75116","0.00300","7.29628"
"5.83100","0.04828","368.89230","0.00302","7.33888"
"5.85900","0.04852","371.00363","0.00303","7.38088"
"5.88900","0.04878","373.08807","0.00305","7.42235"
"5.92100","0.04904","375.20145","0.00307","7.46440"
"5.95000","0.04928","377.32843","0.00308","7.50671"
"5.97800","0.04953","379.48218","0.00310","7.54956"
"6.00900","0.04978","381.59985","0.00311","7.59169"
"6.04200","0.05004","383.75235","0.00313","7.63451"
"6.07100","0.05028","385.83243","0.00314","7.67589"
"6.10100","0.05054","387.97089","0.00316","7.71844"
"6.13100","0.05079","390.07193","0.00317","7.76023"
"6.16300","0.05103","392.13226","0.00319","7.80122"
"6.19400","0.05127","394.27255","0.00320","7.84380"
"6.22200","0.05151","396.37106","0.00322","7.88555"
"6.25000","0.05176","398.47711","0.00324","7.92745"
"6.28200","0.05204","400.66983","0.00325","7.97107"
"6.31400","0.05231","402.78348","0.00327","8.01312"
"6.34300","0.05256","404.89792","0.00329","8.05519"
"6.37200","0.05282","407.00769","0.00330","8.09716"
"6.40600","0.05309","409.16550","0.00332","8.14009"
"6.44000","0.05337","411.26596","0.00334","8.18188"
"6.47000","0.05363","413.40936","0.00335","8.22452"
"6.49900","0.05388","415.51733","0.00337","8.26645"
"6.52700","0.05412","417.68835","0.00338","8.30965"
"6.55600","0.05436","419.85770","0.00340","8.35280"
"6.58800","0.05460","422.05515","0.00341","8.39652"
"6.61600","0.05485","424.21933","0.00343","8.43958"
"6.64100","0.05508","426.33014","0.00344","8.48157"
"6.66900","0.05534","428.55527","0.00346","8.52584"
"6.69700","0.05559","430.71173","0.00347","8.56874"
"6.72500","0.05583","432.75595","0.00349","8.60941"
"6.75300","0.05607","434.78903","0.00350","8.64985"
"6.78100","0.05632","436.82004","0.00352","8.69026"
"6.81100","0.05658","438.90619","0.00354","8.73176"
"6.84900","0.05685","440.98376","0.00355","8.77309"
"6.88100","0.05710","443.14490","0.00357","8.81609"
"6.91100","0.05735","445.28778","0.00358","8.85872"
"6.94300","0.05760","447.47009","0.00360","8.90213"
"6.97200","0.05784","449.61954","0.00362","8.94490"
"7.00200","0.05811","451.79050","0.00363","8.98809"
"7.03700","0.05837","453.93613","0.00365","9.03077"
"7.06900","0.05861","456.02634","0.00366","9.07236"
"7.10100","0.05886","458.15848","0.00368","9.11477"
"7.12900","0.05909","460.21609","0.00369","9.15571"
"7.15700","0.05933","462.27112","0.00371","9.19659"
"7.18500","0.05957","464.41849","0.00372","9.23931"
"7.21300","0.05983","466.63455","0.00374","9.28340"
"7.24400","0.06007","468.78818","0.00375","9.32625"
"7.27600","0.06033","470.96973","0.00377","9.36965"
"7.30800","0.06059","473.12445","0.00379","9.41251"
"7.34000","0.06085","475.29865","0.00380","9.45577"
"7.37200","0.06112","477.48688","0.00382","9.49930"
"7.40300","0.06138","479.60260","0.00384","9.54139"
"7.43200","0.06163","481.70587","0.00385","9.58323"
"7.46000","0.06187","483.82324","0.00387","9.62536"
"7.48800","0.06212","485.99637","0.00388","9.66859"
"7.51600","0.06237","488.17804","0.00390","9.71199"
"7.54500","0.06261","490.30618","0.00391","9.75433"
"7.57400","0.06284","492.42816","0.00393","9.79655"
"7.60200","0.06307","494.47375","0.00394","9.83724"
"7.63000","0.06330","496.58594","0.00396","9.87926"
"7.65700","0.06354","498.79596","0.00397","9.92323"
"7.68500","0.06377","500.88751","0.00399","9.96484"
"7.71300","0.06401","502.99435","0.00400","10.00675"
"7.74300","0.06426","505.14603","0.00402","10.04956"
"7.77200","0.06450","507.25406","0.00403","10.09150"
"7.80000","0.06475","509.27365","0.00405","10.13168"
"7.83400","0.06503","511.42932","0.00406","10.17456"
"7.86800","0.06530","513.55701","0.00408","10.21689"
"7.89700","0.06554","515.70599","0.00410","10.25965"
"7.92400","0.06578","517.94885","0.00411","10.30427"
"7.95200","0.06602","520.20898","0.00413","10.34923"
"7.98100","0.06626","522.31769","0.00414","10.39118"
"8.01300","0.06653","524.42615","0.00416","10.43313"
"8.04500","0.06678","526.48212","0.00417","10.47403"
"8.07300","0.06701","528.57965","0.00419","10.51576"
"8.10100","0.06725","530.76923","0.00420","10.55932"
"8.13000","0.06748","532.86078","0.00422","10.60093"
"8.15800","0.06772","534.96033","0.00423","10.64270"
"8.18600","0.06795","537.06598","0.00425","10.68459"
"8.21500","0.06820","539.22528","0.00426","10.72755"
"8.24900","0.06845","541.35809","0.00428","10.76998"
"8.27900","0.06871","543.52252","0.00429","10.81304"
"8.30700","0.06897","545.65039","0.00431","10.85537"
"8.33600","0.06922","547.74548","0.00433","10.89705"
"8.36300","0.06947","549.96948","0.00434","10.94130"
"8.39300","0.06972","552.16394","0.00436","10.98495"
"8.42100","0.06996","554.36035","0.00437","11.02865"
"8.44600","0.07020","556.49078","0.00439","11.07103"
"8.47500","0.07045","558.61786","0.00440","11.11335"
"8.50700","0.07070","560.80377","0.00442","11.15684"
"8.53500","0.07094","562.87994","0.00443","11.19814"
"8.56700","0.07116","564.94385","0.00445","11.23920"
"8.59700","0.07138","567.07220","0.00446","11.28154"
"8.62500","0.07160","569.18634","0.00448","11.32360"
"8.65600","0.07185","571.34045","0.00449","11.36646"
"8.68800","0.07211","573.57098","0.00451","11.41083"
"8.72000","0.07237","575.81317","0.00452","11.45544"
"8.74800","0.07261","577.88275","0.00454","11.49661"
"8.78000","0.07286","580.03625","0.00455","11.53946"
"8.81200","0.07312","582.17438","0.00457","11.58199"
"8.84100","0.07337","584.30786","0.00459","11.62444"
"8.87200","0.07362","586.50043","0.00460","11.66806"
"8.90400","0.07388","588.73291","0.00462","11.71247"
"8.93500","0.07411","590.92944","0.00463","11.75617"
"8.96700","0.07436","593.14972","0.00465","11.80034"
"8.99500","0.07461","595.24463","0.00466","11.84202"
"9.02300","0.07486","597.43768","0.00468","11.88565"
"9.05100","0.07509","599.63721","0.00469","11.92940"
"9.07900","0.07532","601.89838","0.00471","11.97439"
"9.10600","0.07556","604.09662","0.00472","12.01812"
"9.13500","0.07581","606.24200","0.00474","12.06080"
"9.16700","0.07607","608.47321","0.00475","12.10519"
"9.19600","0.07631","610.64319","0.00477","12.14836"
"9.22400","0.07656","612.77795","0.00478","12.19083"
"9.25300","0.07681","614.88605","0.00480","12.23277"
"9.28500","0.07707","617.12988","0.00482","12.27741"
"9.31300","0.07730","619.21033","0.00483","12.31880"
"9.34200","0.07754","621.31488","0.00485","12.36067"
"9.37400","0.07779","623.57904","0.00486","12.40571"
"9.40600","0.07805","625.85126","0.00488","12.45092"
"9.43400","0.07829","628.00336","0.00489","12.49373"
"9.46200","0.07852","630.12738","0.00491","12.53599"
"9.49000","0.07878","632.34076","0.00492","12.58002"
"9.51800","0.07902","634.47626","0.00494","12.62250"
"9.54600","0.07926","636.70935","0.00495","12.66693"
"9.57400","0.07949","638.87653","0.00497","12.71004"
"9.60200","0.07973","640.97217","0.00498","12.75174"
"9.63000","0.07997","643.12360","0.00500","12.79454"
"9.65800","0.08022","645.34442","0.00501","12.83872"
"9.68900","0.08047","647.46997","0.00503","12.88101"
"9.72100","0.08072","649.52161","0.00505","12.92182"
"9.75200","0.08097","651.68256","0.00506","12.96481"
"9.78100","0.08121","653.78027","0.00508","13.00655"
"9.81300","0.08145","655.83801","0.00509","13.04748"
"9.84200","0.08170","657.95844","0.00511","13.08967"
"9.87000","0.08196","660.19739","0.00512","13.13421"
"9.89500","0.08219","662.31030","0.00514","13.17625"
"9.92300","0.08245","664.47186","0.00515","13.21925"
"9.95100","0.08269","666.48718","0.00517","13.25934"
"9.97900","0.08292","668.57092","0.00518","13.30080"
"10.00700","0.08316","670.73175","0.00520","13.34379"
"10.03500","0.08340","672.93878","0.00521","13.38769"
"10.06300","0.08364","675.18524","0.00523","13.43238"
"10.09200","0.08388","677.31836","0.00524","13.47482"
"10.12000","0.08412","679.39362","0.00526","13.51611"
"10.15100","0.08438","681.56763","0.00527","13.55936"
"10.18300","0.08464","683.72192","0.00529","13.60222"
"10.21500","0.08489","685.89276","0.00531","13.64540"
"10.24400","0.08513","687.98755","0.00532","13.68708"
"10.27500","0.08538","690.18506","0.00534","13.73080"
"10.30700","0.08563","692.33893","0.00535","13.77365"
"10.33900","0.08587","694.43939","0.00537","13.81543"
"10.37100","0.08613","696.64978","0.00538","13.85941"
"10.39900","0.08636","698.72284","0.00540","13.90065"
"10.42700","0.08660","700.80493","0.00541","13.94207"
"10.45800","0.08684","703.00043","0.00543","13.98575"
"10.48700","0.08708","705.13788","0.00544","14.02827"
"10.51500","0.08731","707.34729","0.00546","14.07223"
"10.54300","0.08754","709.52960","0.00547","14.11564"
"10.57100","0.08777","711.77203","0.00549","14.16026"
"10.59700","0.08800","713.90491","0.00550","14.20269"
"10.62500","0.08824","716.04468","0.00551","14.24526"
"10.65300","0.08849","718.07617","0.00553","14.28567"
"10.68500","0.08875","720.27533","0.00555","14.32942"
"10.71700","0.08902","722.50983","0.00556","14.37388"
"10.74900","0.08927","724.59131","0.00558","14.41529"
"10.78100","0.08952","726.74670","0.00559","14.45817"
"10.81300","0.08976","728.91174","0.00561","14.50124"
"10.84100","0.09001","731.02539","0.00563","14.54329"
"10.86900","0.09024","733.12402","0.00564","14.58504"
"10.89700","0.09050","735.38837","0.00566","14.63009"
"10.92500","0.09075","737.58240","0.00567","14.67374"
"10.95300","0.09099","739.75104","0.00569","14.71688"
"10.98100","0.09121","741.87042","0.00570","14.75904"
"11.00900","0.09144","744.00146","0.00571","14.80144"
"11.03700","0.09166","746.10529","0.00573","14.84329"
"11.06500","0.09189","748.26569","0.00574","14.88627"
"11.09400","0.09214","750.44501","0.00576","14.92963"
"11.12600","0.09240","752.59167","0.00577","14.97234"
"11.15600","0.09264","754.72699","0.00579","15.01482"
"11.18400","0.09288","756.77917","0.00580","15.05564"
"11.21200","0.09313","758.91235","0.00582","15.09808"
"11.24000","0.09338","761.12445","0.00584","15.14209"
"11.26900","0.09364","763.27594","0.00585","15.18489"
"11.30100","0.09390","765.42603","0.00587","15.22767"
"11.33300","0.09416","767.58813","0.00588","15.27068"
"11.36200","0.09440","769.66986","0.00590","15.31210"
"11.39400","0.09467","771.91412","0.00592","15.35674"
"11.42600","0.09492","774.13879","0.00593","15.40100"
"11.45500","0.09515","776.26111","0.00595","15.44322"
"11.48300","0.09539","778.49969","0.00596","15.48776"
"11.50900","0.09562","780.67523","0.00598","15.53104"
"11.53500","0.09586","782.83148","0.00599","15.57394"
"11.56300","0.09612","785.06335","0.00601","15.61834"
"11.59100","0.09639","787.37280","0.00602","15.66428"
"11.61900","0.09665","789.52649","0.00604","15.70713"
"11.64700","0.09689","791.54736","0.00606","15.74734"
"11.67900","0.09716","793.79462","0.00607","15.79204"
"11.70900","0.09741","795.94043","0.00609","15.83473"
"11.74100","0.09767","798.18457","0.00610","15.87938"
"11.77100","0.09792","800.31049","0.00612","15.92167"
"11.80200","0.09816","802.48865","0.00614","15.96500"
"11.83400","0.09842","804.68927","0.00615","16.00879"
"11.86600","0.09865","806.79004","0.00617","16.05058"
"11.89700","0.09889","808.93011","0.00618","16.09315"
"11.92500","0.09911","810.97021","0.00619","16.13374"
"11.95300","0.09935","813.12433","0.00621","16.17660"
"11.98100","0.09958","815.26233","0.00622","16.21913"
"12.01000","0.09982","817.37317","0.00624","16.26112"
"12.04100","0.10006","819.49744","0.00625","16.30338"
"12.06900","0.10030","821.57129","0.00627","16.34464"
"12.10000","0.10055","823.69208","0.00628","16.38683"
"12.13200","0.10080","825.90131","0.00630","16.43079"
"12.16400","0.10106","828.08173","0.00632","16.47416"
"12.19600","0.10132","830.28906","0.00633","16.51808"
"12.22400","0.10155","832.30786","0.00635","16.55824"
"12.25600","0.10180","834.51923","0.00636","16.60223"
"12.28400","0.10204","836.54413","0.00638","16.64252"
"12.31300","0.10228","838.65564","0.00639","16.68452"
"12.34100","0.10252","840.84277","0.00641","16.72804"
"12.36900","0.10276","842.93292","0.00642","16.76962"
"12.39700","0.10299","845.01709","0.00644","16.81108"
"12.42500","0.10324","847.29346","0.00645","16.85637"
"12.45300","0.10348","849.43604","0.00647","16.89899"
"12.48100","0.10372","851.59326","0.00648","16.94191"
"12.51200","0.10397","853.77582","0.00650","16.98533"
"12.54000","0.10421","855.80847","0.00651","17.02577"
"12.57200","0.10446","857.94281","0.00653","17.06823"
"12.60600","0.10473","860.09766","0.00655","17.11110"
"12.63500","0.10498","862.19000","0.00656","17.15273"
"12.66300","0.10522","864.28418","0.00658","17.19439"
"12.69100","0.10546","866.31891","0.00659","17.23487"
"12.72300","0.10571","868.49207","0.00661","17.27810"
"12.75400","0.10595","870.61273","0.00662","17.32029"
"12.78200","0.10619","872.65448","0.00664","17.36091"
"12.81100","0.10643","874.74475","0.00665","17.40249"
"12.84300","0.10670","877.00751","0.00667","17.44751"
"12.87200","0.10695","879.08936","0.00668","17.48893"
"12.90100","0.10719","881.19287","0.00670","17.53078"
"12.92900","0.10742","883.31927","0.00671","17.57308"
"12.95700","0.10765","885.45105","0.00673","17.61549"
"12.98700","0.10790","887.60187","0.00674","17.65828"
"13.01600","0.10815","889.68488","0.00676","17.69972"
"13.04700","0.10841","891.84094","0.00678","17.74261"
"13.07900","0.10868","893.94257","0.00679","17.78442"
"13.11100","0.10895","896.13129","0.00681","17.82797"
"13.14100","0.10920","898.27814","0.00683","17.87068"
"13.16900","0.10945","900.41699","0.00684","17.91323"
"13.19700","0.10971","902.55615","0.00686","17.95579"
"13.22500","0.10996","904.65289","0.00687","17.99750"
"13.25600","0.11022","906.83820","0.00689","18.04097"
"13.28700","0.11049","909.04529","0.00691","18.08488"
"13.31700","0.11075","911.15887","0.00692","18.12693"
"13.34800","0.11101","913.33221","0.00694","18.17017"
"13.37600","0.11125","915.44916","0.00695","18.21228"
"13.40400","0.11149","917.53802","0.00697","18.25384"
"13.43400","0.11174","919.66724","0.00698","18.29620"
"13.46600","0.11201","921.86444","0.00700","18.33991"
"13.49800","0.11228","924.02271","0.00702","18.38285"
"13.53200","0.11255","926.14093","0.00703","18.42499"
"13.57100","0.11285","928.23694","0.00705","18.46669"
"13.61000","0.11314","930.36078","0.00707","18.50894"
"13.64500","0.11341","932.47070","0.00709","18.55092"
"13.67700","0.11367","934.55682","0.00710","18.59242"
"13.70900","0.11393","936.64813","0.00712","18.63402"
"13.74100","0.11419","938.73529","0.00714","18.67555"
"13.77400","0.11446","940.80682","0.00715","18.71676"
"13.80600","0.11473","942.89673","0.00717","18.75834"
"13.84100","0.11501","945.06610","0.00719","18.80149"
"13.87200","0.11527","947.18768","0.00720","18.84370"
"13.90100","0.11552","949.29315","0.00722","18.88559"
"13.93300","0.11580","951.50909","0.00724","18.92967"
"13.96800","0.11608","953.65051","0.00725","18.97227"
"14.00400","0.11638","955.81653","0.00727","19.01537"
"14.04400","0.11669","957.90558","0.00729","19.05693"
"14.08400","0.11700","959.93256","0.00731","19.09725"
"14.11800","0.11730","962.03485","0.00733","19.13908"
"14.15600","0.11760","964.16846","0.00735","19.18152"
"14.19000","0.11790","966.27515","0.00737","19.22343"
"14.22200","0.11817","968.34393","0.00739","19.26459"
"14.25800","0.11847","970.45917","0.00740","19.30667"
"14.29500","0.11878","972.57629","0.00742","19.34879"
"14.33000","0.11908","974.73273","0.00744","19.39169"
"14.36300","0.11936","976.84326","0.00746","19.43368"
"14.40100","0.11967","978.99390","0.00748","19.47647"
"14.43600","0.11999","981.13031","0.00750","19.51897"
"14.47400","0.12031","983.26416","0.00752","19.56142"
"14.51400","0.12065","985.37952","0.00754","19.60350"
"14.55400","0.12099","987.46863","0.00756","19.64507"
"14.59000","0.12130","989.56921","0.00758","19.68686"
"14.62900","0.12162","991.67639","0.00760","19.72878"
"14.66800","0.12194","993.74957","0.00762","19.77002"
"14.70400","0.12225","995.83655","0.00764","19.81154"
"14.74400","0.12257","997.88007","0.00766","19.85219"
"14.78400","0.12290","999.83704","0.00768","19.89113"
"14.82400","0.12321","1001.96924","0.00770","19.93355"
"14.86400","0.12356","1004.10437","0.00772","19.97602"
"14.90100","0.12390","1006.19006","0.00774","20.01752"
"14.93700","0.12423","1008.22614","0.00776","20.05802"
"14.97500","0.12460","1010.33972","0.00779","20.10007"
"15.01500","0.12496","1012.16528","0.00781","20.13639"
"15.05500","0.12527","1013.84796","0.00783","20.16986"
"15.09500","0.12560","1015.65863","0.00785","20.20589"
"15.13500","0.12591","1017.36737","0.00787","20.23988"
"15.17500","0.12624","1019.16418","0.00789","20.27563"
"15.21500","0.12658","1020.97632","0.00791","20.31168"
"15.25500","0.12691","1022.69244","0.00793","20.34582"
"15.29500","0.12722","1024.53760","0.00795","20.38253"
"15.33500","0.12752","1026.28870","0.00797","20.41737"
"15.37500","0.12784","1028.04846","0.00799","20.45238"
"15.41500","0.12817","1029.79785","0.00801","20.48718"
"15.45500","0.12851","1031.50476","0.00803","20.52114"
"15.49500","0.12884","1033.04810","0.00805","20.55184"
"15.53500","0.12916","1034.60474","0.00807","20.58281"
"15.57500","0.12950","1036.29639","0.00809","20.61646"
"15.61500","0.12984","1038.02441","0.00811","20.65084"
"15.65500","0.13017","1039.77051","0.00814","20.68558"
"15.69500","0.13050","1041.43311","0.00816","20.71865"
"15.73500","0.13083","1043.09631","0.00818","20.75174"
"15.77500","0.13116","1044.87927","0.00820","20.78721"
"15.81500","0.13150","1046.77588","0.00822","20.82495"
"15.85500","0.13187","1048.73865","0.00824","20.86399"
"15.89500","0.13221","1050.29187","0.00826","20.89489"
"15.93500","0.13255","1051.85400","0.00828","20.92597"
"15.97500","0.13288","1053.23938","0.00831","20.95353"
"16.01500","0.13323","1054.81689","0.00833","20.98492"
"16.05500","0.13356","1056.40112","0.00835","21.01643"
"16.09500","0.13391","1058.03528","0.00837","21.04894"
"16.13500","0.13425","1059.67810","0.00839","21.08163"
"16.17500","0.13457","1061.02710","0.00841","21.10847"
"16.21500","0.13490","1062.53870","0.00843","21.13854"
"16.25500","0.13522","1064.15137","0.00845","21.17062"
"16.29500","0.13554","1065.82031","0.00847","21.20382"
"16.33500","0.13588","1067.40125","0.00849","21.23527"
"16.37500","0.13621","1068.98022","0.00851","21.26669"
"16.41500","0.13656","1070.48279","0.00854","21.29658"
"16.45500","0.13691","1071.87622","0.00856","21.32430"
"16.49500","0.13724","1073.20410","0.00858","21.35072"
"16.53500","0.13758","1074.69312","0.00860","21.38034"
"16.57500","0.13793","1076.27075","0.00862","21.41173"
"16.61500","0.13826","1077.81177","0.00864","21.44238"
"16.65500","0.13860","1079.30200","0.00866","21.47203"
"16.69500","0.13894","1081.05261","0.00868","21.50686"
"16.73500","0.13929","1082.96826","0.00871","21.54497"
"16.77500","0.13965","1084.80151","0.00873","21.58144"
"16.81500","0.14004","1086.61584","0.00875","21.61754"
"16.85500","0.14038","1088.05737","0.00877","21.64622"
"16.89500","0.14071","1089.22131","0.00879","21.66937"
"16.93500","0.14103","1090.40747","0.00881","21.69297"
"16.97500","0.14134","1091.53662","0.00883","21.71543"
"17.01500","0.14164","1092.71960","0.00885","21.73897"
"17.05500","0.14196","1094.20935","0.00887","21.76860"
"17.09500","0.14227","1095.65222","0.00889","21.79731"
"17.13500","0.14258","1097.04846","0.00891","21.82509"
"17.17500","0.14291","1098.68604","0.00893","21.85767"
"17.21500","0.14321","1099.88245","0.00895","21.88147"
"17.25500","0.14353","1101.07654","0.00897","21.90522"
"17.29500","0.14385","1102.45068","0.00899","21.93256"
"17.33500","0.14418","1103.90479","0.00901","21.96149"
"17.37500","0.14452","1105.38684","0.00903","21.99097"
"17.41500","0.14486","1106.72754","0.00905","22.01765"
"17.45500","0.14518","1108.01855","0.00907","22.04333"
"17.49500","0.14551","1109.47705","0.00909","22.07235"
"17.53500","0.14585","1111.02161","0.00912","22.10307"
"17.57500","0.14618","1112.51953","0.00914","22.13287"
"17.61500","0.14650","1113.93896","0.00916","22.16111"
"17.65500","0.14684","1115.41785","0.00918","22.19053"
"17.69500","0.14717","1116.98767","0.00920","22.22177"
"17.73500","0.14750","1118.59717","0.00922","22.25378"
"17.77500","0.14784","1120.11230","0.00924","22.28393"
"17.81500","0.14819","1121.58081","0.00926","22.31314"
"17.85500","0.14854","1123.04065","0.00928","22.34218"
"17.89500","0.14887","1124.31641","0.00930","22.36757"
"17.93500","0.14921","1125.70215","0.00933","22.39513"
"17.97500","0.14954","1127.14319","0.00935","22.42380"
"18.01500","0.14989","1128.70496","0.00937","22.45487"
"18.05500","0.15022","1130.10742","0.00939","22.48277"
"18.09500","0.15055","1131.56189","0.00941","22.51171"
"18.13300","0.15086","1133.53235","0.00943","22.55091"
"18.17200","0.15119","1135.42407","0.00945","22.58854"
"18.21200","0.15152","1136.46179","0.00947","22.60919"
"18.25200","0.15185","1137.28345","0.00949","22.62554"
"18.29200","0.15219","1138.83191","0.00951","22.65634"
"18.33200","0.15254","1140.40649","0.00953","22.68767"
"18.37200","0.15288","1141.66113","0.00956","22.71263"
"18.41200","0.15320","1142.95483","0.00957","22.73837"
"18.45200","0.15354","1144.51111","0.00960","22.76933"
"18.49200","0.15389","1145.97070","0.00962","22.79836"
"18.53200","0.15426","1147.69861","0.00964","22.83274"
"18.57200","0.15461","1149.41138","0.00966","22.86681"
"18.61200","0.15495","1150.91382","0.00968","22.89670"
"18.65200","0.15528","1152.25635","0.00970","22.92341"
"18.69200","0.15563","1153.88110","0.00973","22.95574"
"18.73200","0.15597","1155.46472","0.00975","22.98724"
"18.77200","0.15632","1157.12537","0.00977","23.02028"
"18.81200","0.15667","1158.48401","0.00979","23.04731"
"18.85200","0.15698","1159.52502","0.00981","23.06802"
"18.89200","0.15728","1160.66528","0.00983","23.09070"
"18.93200","0.15758","1161.81287","0.00985","23.11353"
"18.97200","0.15788","1162.91235","0.00987","23.13541"
"19.01200","0.15819","1164.26221","0.00989","23.16226"
"19.05200","0.15853","1165.84851","0.00991","23.19382"
"19.09200","0.15886","1167.42310","0.00993","23.22515"
"19.13200","0.15918","1169.08118","0.00995","23.25813"
"19.17200","0.15950","1170.46912","0.00997","23.28574"
"19.21200","0.15982","1171.91394","0.00999","23.31449"
"19.25200","0.16014","1173.36707","0.01001","23.34340"
"19.29200","0.16047","1174.60120","0.01003","23.36795"
"19.33200","0.16080","1175.98218","0.01005","23.39542"
"19.37200","0.16116","1177.64661","0.01007","23.42854"
"19.41200","0.16152","1179.11865","0.01009","23.45782"
"19.45200","0.16188","1180.78735","0.01012","23.49102"
"19.49200","0.16223","1182.57068","0.01014","23.52650"
"19.53200","0.16255","1183.77295","0.01016","23.55042"
"19.57200","0.16287","1184.83386","0.01018","23.57152"
"19.61200","0.16319","1186.37524","0.01020","23.60219"
"19.65200","0.16353","1188.02124","0.01022","23.63493"
"19.69200","0.16390","1189.72961","0.01024","23.66892"
"19.73200","0.16422","1191.03894","0.01026","23.69497"
"19.77200","0.16455","1192.31970","0.01028","23.72045"
"19.81200","0.16489","1193.71375","0.01031","23.74818"
"19.85200","0.16523","1195.13977","0.01033","23.77655"
"19.89200","0.16558","1196.69299","0.01035","23.80745"
"19.93200","0.16590","1197.98914","0.01037","23.83324"
"19.97200","0.16621","1199.32446","0.01039","23.85980"
"20.01200","0.16656","1200.87439","0.01041","23.89064"
"20.05200","0.16689","1202.27808","0.01043","23.91856"
"20.09200","0.16722","1203.83496","0.01045","23.94954"
"20.13200","0.16756","1205.51550","0.01047","23.98297"
"20.17200","0.16790","1207.00708","0.01049","24.01264"
"20.21200","0.16823","1208.37134","0.01051","24.03979"
"20.25200","0.16857","1209.68213","0.01054","24.06586"
"20.29200","0.16891","1211.03442","0.01056","24.09277"
"20.33200","0.16925","1212.46008","0.01058","24.12113"
"20.37200","0.16958","1213.80481","0.01060","24.14788"
"20.41200","0.16991","1215.15918","0.01062","24.17483"
"20.45200","0.17022","1216.38879","0.01064","24.19929"
"20.49200","0.17056","1217.90430","0.01066","24.22944"
"20.53200","0.17094","1219.76038","0.01068","24.26636"
"20.57200","0.17130","1221.53955","0.01071","24.30176"
"20.61200","0.17165","1223.18958","0.01073","24.33459"
"20.65200","0.17200","1224.61169","0.01075","24.36288"
"20.69200","0.17232","1225.87146","0.01077","24.38794"
"20.73200","0.17262","1226.90063","0.01079","24.40841"
"20.77200","0.17293","1227.94263","0.01081","24.42914"
"20.81200","0.17324","1229.18140","0.01083","24.45379"
"20.85200","0.17356","1230.50598","0.01085","24.48014"
"20.89200","0.17386","1231.60681","0.01087","24.50204"
"20.93200","0.17418","1232.97852","0.01089","24.52933"
"20.97200","0.17450","1234.38879","0.01091","24.55739"
"21.01200","0.17483","1235.83850","0.01093","24.58623"
"21.05200","0.17516","1237.47009","0.01095","24.61869"
"21.09200","0.17549","1238.98047","0.01097","24.64874"
"21.13200","0.17582","1240.49976","0.01099","24.67896"
"21.17200","0.17615","1241.86462","0.01101","24.70611"
"21.21200","0.17648","1243.20691","0.01103","24.73282"
"21.25200","0.17684","1244.60400","0.01105","24.76061"
"21.29200","0.17717","1245.98560","0.01107","24.78810"
"21.33200","0.17750","1247.30347","0.01109","24.81432"
"21.37200","0.17783","1248.66199","0.01111","24.84134"
"21.41200","0.17817","1250.17139","0.01114","24.87137"
"21.45200","0.17850","1251.54639","0.01116","24.89873"
"21.49200","0.17885","1253.09412","0.01118","24.92952"
"21.53200","0.17920","1254.82483","0.01120","24.96395"
"21.57200","0.17956","1256.50098","0.01122","24.99729"
"21.61200","0.17988","1257.81104","0.01124","25.02336"
"21.65200","0.18021","1259.19250","0.01126","25.05084"
"21.69200","0.18057","1260.66016","0.01129","25.08004"
"21.73200","0.18092","1261.96179","0.01131","25.10593"
"21.77200","0.18123","1263.13647","0.01133","25.12930"
"21.81200","0.18155","1264.35229","0.01135","25.15349"
"21.85200","0.18187","1265.68542","0.01137","25.18001"
"21.89200","0.18221","1267.20679","0.01139","25.21028"
"21.93200","0.18255","1268.64111","0.01141","25.23881"
"21.97200","0.18290","1270.25891","0.01143","25.27100"
"22.01200","0.18324","1271.91858","0.01145","25.30402"
"22.05200","0.18356","1273.29077","0.01147","25.33132"
"22.09200","0.18391","1274.86646","0.01149","25.36266"
"22.13200","0.18426","1276.35010","0.01152","25.39218"
"22.17200","0.18461","1277.72900","0.01154","25.41961"
"22.21200","0.18498","1279.25696","0.01156","25.45001"
"22.25200","0.18530","1280.51038","0.01158","25.47495"
"22.29200","0.18562","1281.67419","0.01160","25.49810"
"22.33200","0.18595","1283.06885","0.01162","25.52584"
"22.37200","0.18630","1284.64746","0.01164","25.55725"
"22.41200","0.18665","1286.15686","0.01167","25.58728"
"22.45200","0.18696","1287.45093","0.01169","25.61302"
"22.49200","0.18729","1288.90076","0.01171","25.64187"
"22.53200","0.18763","1290.48755","0.01173","25.67344"
"22.57200","0.18796","1291.83508","0.01175","25.70024"
"22.61200","0.18828","1293.09265","0.01177","25.72526"
"22.65200","0.18860","1294.27539","0.01179","25.74879"
"22.69200","0.18890","1295.28040","0.01181","25.76879"
"22.73200","0.18922","1296.64001","0.01183","25.79584"
"22.77200","0.18956","1298.10413","0.01185","25.82496"
"22.81200","0.18988","1299.41614","0.01187","25.85106"
"22.85200","0.19019","1300.64050","0.01189","25.87542"
"22.89200","0.19051","1301.99182","0.01191","25.90231"
"22.93200","0.19085","1303.58032","0.01193","25.93391"
"22.97200","0.19118","1305.13513","0.01195","25.96484"
"23.01200","0.19152","1306.70032","0.01197","25.99598"
"23.05200","0.19184","1308.10803","0.01199","26.02398"
"23.09200","0.19217","1309.48523","0.01201","26.05138"
"23.13200","0.19251","1310.89270","0.01203","26.07938"
"23.17200","0.19286","1312.23804","0.01205","26.10615"
"23.21200","0.19320","1313.69934","0.01208","26.13522"
"23.25200","0.19353","1314.97144","0.01210","26.16053"
"23.29200","0.19386","1316.36230","0.01212","26.18820"
"23.33200","0.19418","1317.69971","0.01214","26.21480"
"23.37200","0.19451","1319.10071","0.01216","26.24268"
"23.41200","0.19483","1320.43494","0.01218","26.26922"
"23.45200","0.19516","1322.00952","0.01220","26.30054"
"23.49200","0.19550","1323.62219","0.01222","26.33263"
"23.53200","0.19585","1325.27454","0.01224","26.36550"
"23.57200","0.19621","1326.83057","0.01226","26.39646"
"23.61200","0.19655","1328.15771","0.01228","26.42286"
"23.65200","0.19689","1329.43127","0.01231","26.44820"
"23.69200","0.19722","1330.71338","0.01233","26.47370"
"23.73200","0.19756","1332.12561","0.01235","26.50180"
"23.77200","0.19790","1333.60938","0.01237","26.53132"
"23.81200","0.19823","1335.00623","0.01239","26.55911"
"23.85200","0.19857","1336.43848","0.01241","26.58760"
"23.89200","0.19890","1337.90442","0.01243","26.61676"
"23.93200","0.19924","1339.52417","0.01245","26.64899"
"23.97200","0.19958","1341.07458","0.01247","26.67983"
"24.01200","0.19991","1342.53528","0.01249","26.70889"
"24.05200","0.20025","1343.94031","0.01252","26.73685"
"24.09200","0.20059","1345.29297","0.01254","26.76375"
"24.13200","0.20094","1346.69373","0.01256","26.79162"
"24.17200","0.20127","1348.07104","0.01258","26.81902"
"24.21200","0.20162","1349.55847","0.01260","26.84861"
"24.25200","0.20196","1350.94983","0.01262","26.87630"
"24.29200","0.20230","1352.53882","0.01264","26.90791"
"24.33200","0.20263","1353.84412","0.01266","26.93387"
"24.37200","0.20295","1355.22900","0.01268","26.96143"
"24.41200","0.20329","1356.83752","0.01271","26.99343"
"24.45200","0.20361","1358.18152","0.01273","27.02016"
"24.49200","0.20391","1359.36853","0.01274","27.04378"
"24.53200","0.20423","1360.71924","0.01276","27.07065"
"24.57200","0.20457","1362.10962","0.01279","27.09831"
"24.61200","0.20491","1363.42981","0.01281","27.12457"
"24.65200","0.20523","1364.73523","0.01283","27.15055"
"24.69200","0.20556","1366.10461","0.01285","27.17779"
"24.73200","0.20589","1367.53528","0.01287","27.20625"
"24.77200","0.20621","1368.96790","0.01289","27.23475"
"24.81200","0.20655","1370.47485","0.01291","27.26473"
"24.85200","0.20688","1371.98047","0.01293","27.29469"
"24.89200","0.20721","1373.51074","0.01295","27.32513"
"24.93200","0.20755","1375.10742","0.01297","27.35689"
"24.97200","0.20788","1376.53174","0.01299","27.38523"
"25.01200","0.20821","1377.91248","0.01301","27.41270"
"25.05200","0.20852","1379.14331","0.01303","27.43719"
"25.09200","0.20887","1380.47217","0.01305","27.46362"
"25.13200","0.20919","1381.78625","0.01307","27.48977"
"25.17200","0.20952","1383.17151","0.01310","27.51732"
"25.21200","0.20987","1384.72192","0.01312","27.54817"
"25.25200","0.21021","1386.14258","0.01314","27.57643"
"25.29200","0.21053","1387.48523","0.01316","27.60314"
"25.33200","0.21086","1388.89697","0.01318","27.63123"
"25.37200","0.21118","1390.27124","0.01320","27.65857"
"25.41200","0.21152","1391.97546","0.01322","27.69247"
"25.45200","0.21187","1393.53674","0.01324","27.72353"
"25.49200","0.21220","1394.88562","0.01326","27.75037"
"25.53200","0.21253","1396.15723","0.01328","27.77567"
"25.57200","0.21285","1397.24451","0.01330","27.79730"
"25.61200","0.21318","1398.54517","0.01332","27.82317"
"25.65200","0.21352","1400.01160","0.01334","27.85235"
"25.69200","0.21387","1401.54431","0.01337","27.88284"
"25.73200","0.21423","1403.24585","0.01339","27.91669"
"25.77200","0.21459","1404.84729","0.01341","27.94855"
"25.81200","0.21495","1406.41272","0.01343","27.97969"
"25.85200","0.21528","1407.94568","0.01346","28.01019"
"25.89200","0.21562","1409.42065","0.01348","28.03953"
"25.93200","0.21597","1410.86121","0.01350","28.06819"
"25.97200","0.21630","1412.17676","0.01352","28.09437"
"26.01200","0.21663","1413.29187","0.01354","28.11655"
"26.05200","0.21695","1414.37109","0.01356","28.13802"
"26.09200","0.21728","1415.70142","0.01358","28.16449"
"26.13200","0.21760","1417.00183","0.01360","28.19036"
"26.17200","0.21791","1418.13074","0.01362","28.21282"
"26.21200","0.21823","1419.43677","0.01364","28.23880"
"26.25200","0.21853","1420.59253","0.01366","28.26179"
"26.29200","0.21885","1421.93127","0.01368","28.28843"
"26.33200","0.21916","1423.28149","0.01370","28.31529"
"26.37200","0.21947","1424.65881","0.01372","28.34269"
"26.41200","0.21981","1426.21631","0.01374","28.37367"
"26.45200","0.22015","1427.62793","0.01376","28.40176"
"26.49200","0.22048","1428.94153","0.01378","28.42789"
"26.53200","0.22081","1430.15808","0.01380","28.45209"
"26.57200","0.22112","1431.29407","0.01382","28.47469"
"26.61200","0.22146","1432.74451","0.01384","28.50355"
"26.65200","0.22181","1434.25574","0.01386","28.53361"
"26.69200","0.22215","1435.73804","0.01388","28.56310"
"26.73200","0.22249","1437.19580","0.01391","28.59210"
"26.77200","0.22282","1438.54016","0.01393","28.61885"
"26.81200","0.22315","1439.95190","0.01395","28.64693"
"26.85200","0.22349","1441.52808","0.01397","28.67829"
"26.89200","0.22384","1443.07056","0.01399","28.70898"
"26.93200","0.22418","1444.45239","0.01401","28.73647"
"26.97200","0.22452","1445.66016","0.01403","28.76050"
"27.01200","0.22485","1446.75671","0.01405","28.78231"
"27.05200","0.22518","1447.97119","0.01407","28.80647"
"27.09200","0.22550","1449.11792","0.01409","28.82929"
"27.13200","0.22583","1450.37659","0.01411","28.85433"
"27.17200","0.22618","1451.78528","0.01414","28.88235"
"27.21200","0.22652","1453.08765","0.01416","28.90826"
"27.25200","0.22685","1454.20752","0.01418","28.93054"
"27.29200","0.22719","1455.45190","0.01420","28.95530"
"27.33200","0.22752","1456.43945","0.01422","28.97494"
"27.37200","0.22788","1457.01978","0.01424","28.98649"
"27.41200","0.22822","1456.80652","0.01426","28.98225"
"27.45200","0.22857","1455.85632","0.01429","28.96334"
"27.49200","0.22892","1454.94250","0.01431","28.94516"
"27.53200","0.22926","1454.84656","0.01433","28.94325"
"27.57200","0.22960","1455.53455","0.01435","28.95694"
"27.61200","0.22996","1456.75879","0.01437","28.98130"
"27.65200","0.23029","1458.02197","0.01439","29.00643"
"27.69200","0.23061","1459.39380","0.01441","29.03372"
"27.73200","0.23096","1461.10645","0.01443","29.06779"
"27.77200","0.23128","1462.86731","0.01446","29.10282"
"27.81200","0.23161","1464.59070","0.01448","29.13711"
"27.85200","0.23192","1466.06702","0.01449","29.16648"
"27.89200","0.23225","1467.77893","0.01452","29.20053"
"27.93200","0.23260","1469.50964","0.01454","29.23497"
"27.97200","0.23294","1471.14331","0.01456","29.26747"
"28.01200","0.23326","1472.71582","0.01458","29.29875"
"28.05200","0.23358","1474.34253","0.01460","29.33111"
"28.09200","0.23390","1475.87122","0.01462","29.36153"
"28.13200","0.23420","1477.38147","0.01464","29.39157"
"28.17200","0.23451","1478.93335","0.01466","29.42245"
"28.21200","0.23483","1480.56042","0.01468","29.45481"
"28.25200","0.23514","1482.32397","0.01470","29.48990"
"28.29200","0.23546","1484.11169","0.01472","29.52547"
"28.33200","0.23578","1485.76868","0.01474","29.55843"
"28.37200","0.23611","1487.43799","0.01476","29.59164"
"28.41200","0.23645","1489.09534","0.01478","29.62461"
"28.45200","0.23680","1490.75342","0.01480","29.65760"
"28.49200","0.23714","1492.38440","0.01482","29.69005"
"28.53200","0.23749","1494.06274","0.01484","29.72343"
"28.57200","0.23783","1495.72546","0.01486","29.75651"
"28.61200","0.23816","1497.18640","0.01488","29.78558"
"28.65200","0.23847","1498.54980","0.01490","29.81270"
"28.69000","0.23878","1500.02222","0.01492","29.84200"