File: STRAIN_GAUGE/calibration test/2024-07-16/Steel_2.is_comp_RawData/Specimen_2_RawData_1.csv
Time,Extension,Load,Compressive strain (Extension),Compressive stress
(s),(mm),(N),(mm/mm),(MPa)
"0.00000","-0.00002","0.02029","0.00000","0.00040"
"0.03000","-0.00002","0.05037","0.00000","0.00100"
"0.06000","-0.00001","0.07000","0.00000","0.00139"
"0.09000","0.00000","0.09077","0.00000","0.00181"
"0.12000","0.00002","0.14056","0.00000","0.00280"
"0.15000","0.00007","0.22401","0.00000","0.00446"
"0.18000","0.00015","0.32298","0.00001","0.00643"
"0.21000","0.00031","0.56086","0.00002","0.01116"
"0.24000","0.00056","1.09206","0.00004","0.02173"
"0.27000","0.00089","1.98193","0.00006","0.03943"
"0.30000","0.00125","3.17710","0.00008","0.06321"
"0.33000","0.00163","4.63929","0.00010","0.09230"
"0.35800","0.00200","6.24967","0.00013","0.12433"
"0.38200","0.00232","7.82706","0.00015","0.15571"
"0.40600","0.00264","9.44024","0.00016","0.18781"
"0.43000","0.00294","10.98971","0.00018","0.21863"
"0.45700","0.00324","12.65145","0.00020","0.25169"
"0.48400","0.00353","14.28596","0.00022","0.28421"
"0.51100","0.00381","15.85877","0.00024","0.31550"
"0.54100","0.00410","17.49810","0.00026","0.34811"
"0.56800","0.00436","19.02322","0.00027","0.37846"
"0.59800","0.00463","20.60754","0.00029","0.40997"
"0.62800","0.00489","22.17598","0.00031","0.44118"
"0.65800","0.00515","23.70084","0.00032","0.47151"
"0.68800","0.00543","25.26830","0.00034","0.50270"
"0.71800","0.00569","26.80877","0.00036","0.53334"
"0.74600","0.00593","28.37165","0.00037","0.56444"
"0.77300","0.00616","29.95342","0.00038","0.59590"
"0.80300","0.00640","31.52008","0.00040","0.62707"
"0.83300","0.00664","33.12122","0.00042","0.65893"
"0.86300","0.00688","34.72367","0.00043","0.69081"
"0.89000","0.00711","36.31771","0.00044","0.72252"
"0.91700","0.00734","37.95982","0.00046","0.75519"
"0.94400","0.00758","39.53477","0.00047","0.78652"
"0.97400","0.00782","41.07519","0.00049","0.81716"
"1.00400","0.00806","42.57495","0.00050","0.84700"
"1.03300","0.00830","44.17789","0.00052","0.87889"
"1.06300","0.00855","45.79568","0.00053","0.91108"
"1.09100","0.00880","47.35453","0.00055","0.94209"
"1.12100","0.00904","48.94196","0.00057","0.97367"
"1.14800","0.00927","50.53951","0.00058","1.00545"
"1.17500","0.00949","52.18383","0.00059","1.03816"
"1.20200","0.00969","53.74392","0.00061","1.06920"
"1.22900","0.00991","55.36641","0.00062","1.10148"
"1.25600","0.01011","57.00999","0.00063","1.13418"
"1.28000","0.01030","58.66138","0.00064","1.16703"
"1.30100","0.01048","60.20638","0.00066","1.19777"
"1.32400","0.01069","61.76730","0.00067","1.22882"
"1.35100","0.01093","63.41389","0.00068","1.26158"
"1.37800","0.01117","65.02878","0.00070","1.29371"
"1.40500","0.01140","66.62752","0.00071","1.32551"
"1.42900","0.01160","68.19479","0.00072","1.35669"
"1.45300","0.01181","69.86250","0.00074","1.38987"
"1.47700","0.01202","71.50351","0.00075","1.42252"
"1.50100","0.01222","73.07951","0.00076","1.45387"
"1.52800","0.01244","74.74448","0.00078","1.48699"
"1.55500","0.01266","76.39817","0.00079","1.51989"
"1.58200","0.01288","78.00084","0.00080","1.55178"
"1.60900","0.01310","79.59951","0.00082","1.58358"
"1.63600","0.01332","81.13688","0.00083","1.61417"
"1.66500","0.01355","82.72753","0.00085","1.64581"
"1.69100","0.01376","84.30068","0.00086","1.67711"
"1.71500","0.01397","85.89951","0.00087","1.70892"
"1.73900","0.01419","87.56063","0.00089","1.74196"
"1.76300","0.01441","89.20834","0.00090","1.77474"
"1.78700","0.01463","90.90516","0.00091","1.80850"
"1.81100","0.01483","92.48908","0.00093","1.84001"
"1.83800","0.01505","94.16454","0.00094","1.87334"
"1.86200","0.01526","95.68774","0.00095","1.90365"
"1.88600","0.01548","97.19788","0.00097","1.93369"
"1.91300","0.01570","98.79307","0.00098","1.96543"
"1.93800","0.01592","100.37850","0.00099","1.99697"
"1.96300","0.01613","101.95306","0.00101","2.02829"
"1.99000","0.01635","103.53295","0.00102","2.05972"
"2.01700","0.01657","105.16389","0.00104","2.09217"
"2.04100","0.01679","106.72091","0.00105","2.12315"
"2.06500","0.01699","108.26668","0.00106","2.15390"
"2.08900","0.01720","109.87409","0.00107","2.18588"
"2.11300","0.01741","111.41902","0.00109","2.21661"
"2.13900","0.01762","112.98822","0.00110","2.24783"
"2.16300","0.01782","114.54984","0.00111","2.27890"
"2.18400","0.01800","116.11942","0.00113","2.31012"
"2.20600","0.01819","117.72070","0.00114","2.34198"
"2.23000","0.01839","119.31732","0.00115","2.37374"
"2.25600","0.01860","120.93639","0.00116","2.40595"
"2.28300","0.01881","122.55210","0.00118","2.43810"
"2.30700","0.01901","124.14535","0.00119","2.46979"
"2.33000","0.01923","125.78786","0.00120","2.50247"
"2.35500","0.01945","127.34206","0.00122","2.53339"
"2.38500","0.01968","128.89131","0.00123","2.56421"
"2.41300","0.01990","130.44073","0.00124","2.59504"
"2.43900","0.02011","132.02405","0.00126","2.62654"
"2.46300","0.02033","133.59856","0.00127","2.65786"
"2.48700","0.02054","135.18646","0.00128","2.68945"
"2.51300","0.02074","136.82059","0.00130","2.72196"
"2.53900","0.02094","138.43607","0.00131","2.75410"
"2.56600","0.02116","140.08195","0.00132","2.78684"
"2.59300","0.02137","141.65352","0.00134","2.81811"
"2.62000","0.02157","143.21246","0.00135","2.84912"
"2.64400","0.02177","144.76346","0.00136","2.87998"
"2.67000","0.02196","146.37111","0.00137","2.91196"
"2.69400","0.02215","147.99834","0.00138","2.94433"
"2.71800","0.02236","149.68550","0.00140","2.97790"
"2.74200","0.02255","151.33443","0.00141","3.01070"
"2.76600","0.02274","152.92262","0.00142","3.04230"
"2.79000","0.02293","154.47610","0.00143","3.07320"
"2.81400","0.02312","156.12875","0.00145","3.10608"
"2.83800","0.02334","157.76813","0.00146","3.13870"
"2.86200","0.02356","159.32413","0.00147","3.16965"
"2.88900","0.02377","160.98190","0.00149","3.20263"
"2.91300","0.02397","162.56107","0.00150","3.23405"
"2.93700","0.02419","164.13260","0.00151","3.26531"
"2.96400","0.02441","165.78232","0.00153","3.29813"
"2.98800","0.02462","167.36597","0.00154","3.32964"
"3.01200","0.02482","168.95956","0.00155","3.36134"
"3.03600","0.02501","170.53635","0.00156","3.39271"
"3.05700","0.02520","172.05687","0.00157","3.42296"
"3.08100","0.02541","173.70999","0.00159","3.45585"
"3.10700","0.02562","175.30219","0.00160","3.48753"
"3.13200","0.02582","176.88634","0.00161","3.51904"
"3.15500","0.02601","178.51308","0.00163","3.55140"
"3.17800","0.02621","180.15485","0.00164","3.58407"
"3.20200","0.02641","181.83740","0.00165","3.61754"
"3.22600","0.02661","183.44891","0.00166","3.64960"
"3.25000","0.02681","185.02768","0.00168","3.68101"
"3.27400","0.02701","186.58128","0.00169","3.71192"
"3.29800","0.02721","188.20119","0.00170","3.74414"
"3.32400","0.02742","189.81209","0.00171","3.77619"
"3.34900","0.02762","191.37537","0.00173","3.80729"
"3.37300","0.02783","192.99464","0.00174","3.83951"
"3.39500","0.02802","194.56958","0.00175","3.87084"
"3.41600","0.02821","196.08739","0.00176","3.90103"
"3.43900","0.02841","197.67149","0.00178","3.93255"
"3.46400","0.02862","199.25082","0.00179","3.96397"
"3.49100","0.02883","200.86775","0.00180","3.99614"
"3.51500","0.02903","202.45235","0.00181","4.02766"
"3.53900","0.02923","204.02597","0.00183","4.05897"
"3.56300","0.02943","205.53368","0.00184","4.08896"
"3.58700","0.02964","207.14198","0.00185","4.12096"
"3.61100","0.02983","208.72803","0.00186","4.15251"
"3.63500","0.03003","210.34596","0.00188","4.18470"
"3.65900","0.03024","212.03813","0.00189","4.21836"
"3.68000","0.03042","213.54977","0.00190","4.24844"
"3.70400","0.03062","215.19321","0.00191","4.28113"
"3.72800","0.03082","216.80164","0.00193","4.31313"
"3.75200","0.03103","218.43956","0.00194","4.34572"
"3.77600","0.03124","220.05397","0.00195","4.37783"
"3.80100","0.03145","221.64854","0.00197","4.40956"
"3.82500","0.03166","223.20276","0.00198","4.44048"
"3.84900","0.03186","224.79349","0.00199","4.47212"
"3.87300","0.03207","226.39566","0.00200","4.50400"
"3.89700","0.03228","228.03932","0.00202","4.53670"
"3.91900","0.03247","229.60568","0.00203","4.56786"
"3.94300","0.03268","231.20786","0.00204","4.59973"
"3.97000","0.03288","232.83023","0.00206","4.63201"
"3.99400","0.03308","234.42159","0.00207","4.66367"
"4.01800","0.03328","236.05188","0.00208","4.69610"
"4.04200","0.03348","237.64789","0.00209","4.72785"
"4.06600","0.03368","239.22256","0.00210","4.75918"
"4.08900","0.03387","240.84386","0.00212","4.79144"
"4.11000","0.03406","242.50658","0.00213","4.82452"
"4.13300","0.03424","244.09894","0.00214","4.85619"
"4.15700","0.03444","245.72681","0.00215","4.88858"
"4.18100","0.03463","247.33279","0.00216","4.92053"
"4.20500","0.03481","248.91083","0.00218","4.95192"
"4.23100","0.03501","250.52130","0.00219","4.98396"
"4.25500","0.03521","252.06497","0.00220","5.01467"
"4.28100","0.03542","253.68484","0.00221","5.04690"
"4.30800","0.03563","255.30634","0.00223","5.07916"
"4.33600","0.03583","256.88153","0.00224","5.11050"
"4.36100","0.03603","258.45947","0.00225","5.14189"
"4.38400","0.03622","260.07217","0.00226","5.17397"
"4.40500","0.03640","261.60339","0.00228","5.20443"
"4.42800","0.03660","263.22379","0.00229","5.23667"
"4.45200","0.03679","264.81824","0.00230","5.26839"
"4.47600","0.03699","266.47580","0.00231","5.30137"
"4.50000","0.03720","268.11423","0.00232","5.33396"
"4.52400","0.03739","269.70648","0.00234","5.36564"
"4.54800","0.03759","271.33746","0.00235","5.39809"
"4.57200","0.03778","272.96286","0.00236","5.43042"
"4.59600","0.03797","274.61972","0.00237","5.46339"
"4.61700","0.03815","276.16113","0.00238","5.49405"
"4.63800","0.03833","277.70468","0.00240","5.52476"
"4.65900","0.03850","279.22528","0.00241","5.55501"
"4.68200","0.03870","280.84302","0.00242","5.58719"
"4.70800","0.03890","282.46701","0.00243","5.61950"
"4.73100","0.03911","284.07452","0.00244","5.65148"
"4.75300","0.03931","285.66019","0.00246","5.68303"
"4.77700","0.03951","287.22531","0.00247","5.71417"
"4.80200","0.03971","288.81033","0.00248","5.74570"
"4.82600","0.03991","290.41214","0.00249","5.77757"
"4.85000","0.04012","292.10477","0.00251","5.81124"
"4.87400","0.04032","293.73010","0.00252","5.84358"
"4.90000","0.04052","295.35291","0.00253","5.87586"
"4.92300","0.04071","296.94174","0.00254","5.90747"
"4.94600","0.04090","298.58813","0.00256","5.94022"
"4.97000","0.04109","300.20673","0.00257","5.97242"
"4.99400","0.04130","301.83075","0.00258","6.00473"
"5.01800","0.04151","303.49670","0.00259","6.03788"
"5.04200","0.04172","305.18607","0.00261","6.07148"
"5.06400","0.04191","306.82394","0.00262","6.10407"
"5.08200","0.04208","308.35236","0.00263","6.13448"
"5.10200","0.04226","309.94452","0.00264","6.16615"
"5.12300","0.04245","311.51260","0.00265","6.19735"
"5.14500","0.04264","313.10010","0.00267","6.22893"
"5.16800","0.04284","314.72110","0.00268","6.26118"
"5.19100","0.04303","316.31171","0.00269","6.29282"
"5.21500","0.04322","317.85483","0.00270","6.32352"
"5.23900","0.04343","319.46024","0.00271","6.35546"
"5.26300","0.04364","321.12930","0.00273","6.38866"
"5.28400","0.04383","322.64578","0.00274","6.41883"
"5.30800","0.04403","324.29709","0.00275","6.45169"
"5.33200","0.04423","325.92358","0.00276","6.48404"
"5.35600","0.04443","327.54764","0.00278","6.51635"
"5.38100","0.04464","329.13998","0.00279","6.54803"
"5.40700","0.04485","330.75058","0.00280","6.58007"
"5.43000","0.04504","332.36191","0.00282","6.61213"
"5.45400","0.04524","334.00623","0.00283","6.64484"
"5.47900","0.04544","335.59467","0.00284","6.67644"
"5.50400","0.04564","337.23788","0.00285","6.70914"
"5.52500","0.04582","338.78757","0.00286","6.73996"
"5.54600","0.04601","340.38049","0.00288","6.77166"
"5.56700","0.04620","342.09561","0.00289","6.80578"
"5.58800","0.04639","343.73459","0.00290","6.83838"
"5.61100","0.04658","345.33841","0.00291","6.87029"
"5.63500","0.04677","346.91522","0.00292","6.90166"
"5.65900","0.04696","348.50229","0.00294","6.93323"
"5.68300","0.04716","350.18481","0.00295","6.96671"
"5.70700","0.04738","351.87772","0.00296","7.00039"
"5.73200","0.04759","353.44507","0.00297","7.03157"
"5.75900","0.04780","355.05179","0.00299","7.06353"
"5.78600","0.04801","356.65704","0.00300","7.09547"
"5.81300","0.04821","358.25757","0.00301","7.12731"
"5.83800","0.04841","359.82037","0.00303","7.15840"
"5.86200","0.04860","361.44440","0.00304","7.19071"
"5.88600","0.04880","363.09698","0.00305","7.22359"
"5.91000","0.04900","364.64368","0.00306","7.25436"
"5.93700","0.04921","366.28772","0.00308","7.28706"
"5.96200","0.04941","367.88815","0.00309","7.31890"
"5.98600","0.04961","369.49683","0.00310","7.35091"
"6.01000","0.04980","371.13123","0.00311","7.38342"
"6.03100","0.04997","372.69781","0.00312","7.41459"
"6.05200","0.05014","374.24002","0.00313","7.44527"
"6.07300","0.05032","375.76727","0.00314","7.47565"
"6.09700","0.05051","377.45541","0.00316","7.50924"
"6.12000","0.05070","379.08496","0.00317","7.54166"
"6.14100","0.05089","380.61469","0.00318","7.57209"
"6.16400","0.05108","382.22919","0.00319","7.60421"
"6.18800","0.05128","383.78220","0.00320","7.63510"
"6.21200","0.05148","385.32224","0.00322","7.66574"
"6.23600","0.05168","386.87894","0.00323","7.69671"
"6.26000","0.05188","388.48688","0.00324","7.72870"
"6.28400","0.05209","390.09409","0.00326","7.76068"
"6.31100","0.05229","391.72055","0.00327","7.79303"
"6.33600","0.05250","393.31467","0.00328","7.82475"
"6.36000","0.05271","394.97476","0.00329","7.85777"
"6.38300","0.05291","396.55988","0.00331","7.88931"
"6.40500","0.05310","398.13986","0.00332","7.92074"
"6.42900","0.05330","399.75854","0.00333","7.95294"
"6.45100","0.05349","401.34509","0.00334","7.98451"
"6.47200","0.05367","402.87384","0.00335","8.01492"
"6.49300","0.05385","404.40268","0.00337","8.04534"
"6.51600","0.05404","406.03802","0.00338","8.07787"
"6.54000","0.05424","407.69009","0.00339","8.11074"
"6.56300","0.05444","409.32181","0.00340","8.14320"
"6.58500","0.05464","410.89716","0.00341","8.17454"
"6.60900","0.05484","412.51358","0.00343","8.20670"
"6.63300","0.05504","414.05719","0.00344","8.23741"
"6.65700","0.05523","415.60327","0.00345","8.26816"
"6.68400","0.05545","417.20233","0.00347","8.29998"
"6.71100","0.05567","418.74677","0.00348","8.33070"
"6.73700","0.05589","420.35724","0.00349","8.36274"
"6.76100","0.05609","421.90927","0.00351","8.39362"
"6.78500","0.05630","423.47739","0.00352","8.42482"
"6.80900","0.05650","425.00333","0.00353","8.45517"
"6.83300","0.05670","426.53552","0.00354","8.48565"
"6.85900","0.05691","428.13998","0.00356","8.51757"
"6.88400","0.05711","429.74246","0.00357","8.54945"
"6.90800","0.05732","431.40570","0.00358","8.58254"
"6.93200","0.05752","433.04312","0.00360","8.61512"
"6.95600","0.05772","434.68494","0.00361","8.64778"
"6.98000","0.05792","436.31400","0.00362","8.68019"
"7.00200","0.05810","437.93430","0.00363","8.71243"
"7.02300","0.05829","439.50739","0.00364","8.74372"
"7.04400","0.05847","441.02518","0.00365","8.77392"
"7.06500","0.05867","442.52933","0.00367","8.80384"
"7.08900","0.05888","444.17679","0.00368","8.83662"
"7.11500","0.05910","445.72498","0.00369","8.86742"
"7.14200","0.05931","447.25467","0.00371","8.89785"
"7.16800","0.05952","448.82944","0.00372","8.92918"
"7.19200","0.05973","450.40549","0.00373","8.96053"
"7.21800","0.05996","452.02191","0.00375","8.99269"
"7.24200","0.06016","453.62943","0.00376","9.02467"
"7.26300","0.06036","455.17007","0.00377","9.05532"
"7.28700","0.06057","456.80844","0.00379","9.08792"
"7.31300","0.06079","458.42416","0.00380","9.12006"
"7.34000","0.06102","460.06213","0.00381","9.15265"
"7.36900","0.06125","461.67358","0.00383","9.18470"
"7.39700","0.06147","463.24756","0.00384","9.21602"
"7.42700","0.06169","464.67395","0.00386","9.24440"
"7.45600","0.06190","466.17645","0.00387","9.27429"
"7.48400","0.06211","467.74872","0.00388","9.30557"
"7.51300","0.06232","469.33801","0.00390","9.33718"
"7.54200","0.06254","470.89337","0.00391","9.36813"
"7.56900","0.06276","472.51398","0.00392","9.40037"
"7.59800","0.06299","474.07501","0.00394","9.43142"
"7.62800","0.06324","475.65378","0.00395","9.46283"
"7.65800","0.06349","477.29630","0.00397","9.49551"
"7.68800","0.06374","478.88696","0.00398","9.52715"
"7.71800","0.06399","480.46341","0.00400","9.55852"
"7.74600","0.06423","482.06061","0.00401","9.59029"
"7.77300","0.06447","483.63678","0.00403","9.62165"
"7.80200","0.06471","485.22958","0.00404","9.65334"
"7.82900","0.06494","486.83484","0.00406","9.68527"
"7.85500","0.06517","488.44882","0.00407","9.71738"
"7.88200","0.06541","490.02106","0.00409","9.74866"
"7.91200","0.06564","491.54205","0.00410","9.77892"
"7.94000","0.06588","493.13907","0.00412","9.81069"
"7.96800","0.06611","494.71091","0.00413","9.84196"
"7.99800","0.06635","496.22162","0.00415","9.87202"
"8.02800","0.06661","497.77548","0.00416","9.90293"
"8.05800","0.06687","499.41342","0.00418","9.93551"
"8.08800","0.06711","501.02533","0.00419","9.96758"
"8.11800","0.06736","502.53760","0.00421","9.99767"
"8.14800","0.06761","503.87198","0.00423","10.02421"
"8.17800","0.06786","505.15289","0.00424","10.04970"
"8.20800","0.06810","506.50101","0.00426","10.07652"
"8.23800","0.06836","508.02756","0.00427","10.10689"
"8.26800","0.06862","509.44501","0.00429","10.13509"
"8.29800","0.06887","510.87500","0.00430","10.16354"
"8.32800","0.06911","512.19250","0.00432","10.18975"
"8.35800","0.06937","513.43445","0.00434","10.21445"
"8.38800","0.06962","514.63556","0.00435","10.23835"
"8.41800","0.06988","516.14105","0.00437","10.26830"
"8.44800","0.07014","517.50720","0.00438","10.29548"
"8.47800","0.07039","518.74426","0.00440","10.32009"
"8.50800","0.07064","519.98041","0.00442","10.34468"
"8.53800","0.07090","521.13947","0.00443","10.36774"
"8.56800","0.07116","522.39337","0.00445","10.39269"
"8.59800","0.07142","523.47284","0.00446","10.41416"
"8.62800","0.07166","524.40234","0.00448","10.43265"
"8.65800","0.07191","525.40039","0.00449","10.45251"
"8.68800","0.07217","526.50238","0.00451","10.47443"
"8.71800","0.07243","527.63666","0.00453","10.49700"
"8.74800","0.07270","528.77747","0.00454","10.51969"
"8.77800","0.07293","529.61005","0.00456","10.53626"
"8.80800","0.07318","530.65082","0.00457","10.55696"
"8.83800","0.07344","531.82544","0.00459","10.58033"
"8.86800","0.07369","532.73712","0.00461","10.59847"
"8.89800","0.07394","533.85626","0.00462","10.62073"
"8.92800","0.07422","535.24933","0.00464","10.64845"
"8.95800","0.07448","536.42047","0.00466","10.67175"
"8.98800","0.07474","537.46503","0.00467","10.69253"
"9.01800","0.07500","538.40442","0.00469","10.71122"
"9.04800","0.07525","539.18146","0.00470","10.72668"
"9.07800","0.07551","540.01221","0.00472","10.74320"
"9.10800","0.07575","540.80573","0.00473","10.75899"
"9.13800","0.07598","541.60272","0.00475","10.77484"
"9.16800","0.07621","542.36615","0.00476","10.79003"
"9.19800","0.07643","543.13708","0.00478","10.80537"
"9.22800","0.07667","544.02588","0.00479","10.82305"
"9.25800","0.07690","544.87646","0.00481","10.83997"
"9.28800","0.07714","545.78418","0.00482","10.85803"
"9.31800","0.07736","546.47717","0.00484","10.87182"
"9.34800","0.07761","547.45135","0.00485","10.89120"
"9.37800","0.07785","548.62030","0.00487","10.91445"
"9.40800","0.07811","549.90796","0.00488","10.94007"
"9.43800","0.07836","551.04437","0.00490","10.96268"
"9.46800","0.07862","552.11041","0.00491","10.98389"
"9.49800","0.07888","553.07098","0.00493","11.00300"
"9.52800","0.07914","553.97174","0.00495","11.02092"
"9.55800","0.07940","554.87512","0.00496","11.03889"
"9.58800","0.07967","555.75922","0.00498","11.05648"
"9.61800","0.07992","556.49207","0.00500","11.07106"
"9.64800","0.08018","557.27527","0.00501","11.08664"
"9.67800","0.08042","558.01624","0.00503","11.10138"
"9.70800","0.08066","558.66528","0.00504","11.11429"
"9.73800","0.08090","559.45831","0.00506","11.13007"
"9.76800","0.08115","560.53741","0.00507","11.15154"
"9.79800","0.08141","561.55945","0.00509","11.17187"
"9.82800","0.08166","562.45526","0.00510","11.18969"
"9.85800","0.08190","563.32123","0.00512","11.20692"
"9.88800","0.08215","564.44928","0.00513","11.22936"
"9.91800","0.08241","565.57080","0.00515","11.25167"
"9.94800","0.08267","566.53577","0.00517","11.27087"
"9.97800","0.08292","567.43030","0.00518","11.28867"
"10.00800","0.08316","568.36389","0.00520","11.30724"
"10.03800","0.08343","569.33844","0.00521","11.32663"
"10.06800","0.08367","570.09662","0.00523","11.34171"
"10.09800","0.08391","570.79535","0.00524","11.35561"
"10.12800","0.08416","571.65228","0.00526","11.37266"
"10.15800","0.08441","572.65631","0.00528","11.39264"
"10.18800","0.08468","573.81207","0.00529","11.41563"
"10.21800","0.08494","574.88904","0.00531","11.43705"
"10.24800","0.08519","575.80402","0.00532","11.45526"
"10.27800","0.08543","576.56671","0.00534","11.47043"
"10.30800","0.08567","577.53699","0.00535","11.48973"
"10.33800","0.08593","578.58936","0.00537","11.51067"
"10.36800","0.08618","579.64093","0.00539","11.53159"
"10.39800","0.08642","580.65533","0.00540","11.55177"
"10.42800","0.08667","581.48737","0.00542","11.56832"
"10.45800","0.08693","582.19836","0.00543","11.58247"
"10.48800","0.08720","583.02948","0.00545","11.59900"
"10.51800","0.08744","583.61169","0.00546","11.61059"
"10.54800","0.08768","584.46210","0.00548","11.62750"
"10.57800","0.08795","585.68451","0.00550","11.65182"
"10.60800","0.08821","586.76959","0.00551","11.67341"
"10.63800","0.08845","587.62750","0.00553","11.69048"
"10.66800","0.08874","588.77679","0.00555","11.71334"
"10.69800","0.08900","589.81201","0.00556","11.73394"
"10.72800","0.08926","590.68787","0.00558","11.75136"
"10.75800","0.08950","591.42365","0.00559","11.76600"
"10.78800","0.08977","592.62634","0.00561","11.78993"
"10.81800","0.09004","593.96918","0.00563","11.81664"
"10.84800","0.09030","595.16138","0.00564","11.84036"
"10.87800","0.09055","596.23273","0.00566","11.86167"
"10.90800","0.09079","596.93201","0.00567","11.87559"
"10.93800","0.09102","597.63916","0.00569","11.88965"
"10.96800","0.09125","598.52307","0.00570","11.90724"
"10.99800","0.09148","599.32684","0.00572","11.92323"
"11.02800","0.09173","600.06421","0.00573","11.93790"
"11.05800","0.09196","600.79962","0.00575","11.95253"
"11.08800","0.09219","601.63196","0.00576","11.96909"
"11.11800","0.09244","602.51605","0.00578","11.98668"
"11.14800","0.09269","603.33362","0.00579","12.00294"
"11.17800","0.09293","604.21454","0.00581","12.02047"
"11.20800","0.09317","605.05829","0.00582","12.03725"
"11.23800","0.09343","606.02441","0.00584","12.05647"
"11.26800","0.09367","606.95544","0.00585","12.07500"
"11.29800","0.09390","607.76605","0.00587","12.09112"
"11.32800","0.09415","608.73511","0.00588","12.11040"
"11.35800","0.09440","609.76715","0.00590","12.13093"
"11.38800","0.09465","610.77814","0.00592","12.15105"
"11.41800","0.09491","611.79352","0.00593","12.17125"
"11.44800","0.09516","612.69019","0.00595","12.18909"
"11.47800","0.09541","613.49689","0.00596","12.20513"
"11.50800","0.09566","614.29858","0.00598","12.22108"
"11.53800","0.09591","615.05927","0.00599","12.23622"
"11.56800","0.09615","615.82568","0.00601","12.25146"
"11.59800","0.09640","616.80267","0.00603","12.27090"
"11.62800","0.09665","617.55084","0.00604","12.28578"
"11.65800","0.09689","618.47906","0.00606","12.30425"
"11.68800","0.09715","619.58063","0.00607","12.32617"
"11.71800","0.09740","620.50897","0.00609","12.34463"
"11.74800","0.09764","621.44806","0.00610","12.36332"
"11.77800","0.09789","622.60913","0.00612","12.38642"
"11.80800","0.09814","623.81342","0.00613","12.41037"
"11.83800","0.09842","625.19043","0.00615","12.43777"
"11.86800","0.09866","626.19617","0.00617","12.45778"
"11.89800","0.09891","627.22107","0.00618","12.47817"
"11.92800","0.09917","627.96466","0.00620","12.49296"
"11.95800","0.09942","628.42603","0.00621","12.50214"
"11.98800","0.09967","629.05157","0.00623","12.51458"
"12.01800","0.09993","630.08240","0.00625","12.53509"
"12.04800","0.10017","631.34857","0.00626","12.56028"
"12.07800","0.10042","632.53400","0.00628","12.58386"
"12.10800","0.10067","633.51282","0.00629","12.60334"
"12.13800","0.10090","634.20483","0.00631","12.61710"
"12.16800","0.10117","635.25983","0.00632","12.63809"
"12.19800","0.10143","636.19696","0.00634","12.65674"
"12.22800","0.10167","637.03400","0.00635","12.67339"
"12.25800","0.10192","638.13715","0.00637","12.69534"
"12.28800","0.10218","639.21246","0.00639","12.71673"
"12.31800","0.10241","640.08936","0.00640","12.73417"
"12.34800","0.10266","641.09644","0.00642","12.75421"
"12.37800","0.10293","642.08301","0.00643","12.77384"
"12.40800","0.10318","642.69177","0.00645","12.78595"
"12.43800","0.10345","643.51416","0.00647","12.80231"
"12.46800","0.10371","644.30249","0.00648","12.81799"
"12.49800","0.10398","645.15845","0.00650","12.83502"
"12.52800","0.10423","645.97894","0.00651","12.85134"
"12.55800","0.10449","647.05273","0.00653","12.87271"
"12.58800","0.10474","648.27753","0.00655","12.89707"
"12.61800","0.10501","649.45178","0.00656","12.92043"
"12.64800","0.10528","650.36743","0.00658","12.93865"
"12.67800","0.10552","651.11890","0.00660","12.95360"
"12.70800","0.10576","652.03461","0.00661","12.97182"
"12.73800","0.10600","652.94012","0.00662","12.98983"
"12.76800","0.10624","653.80023","0.00664","13.00694"
"12.79800","0.10646","654.50922","0.00665","13.02105"
"12.82800","0.10669","655.29279","0.00667","13.03664"
"12.85800","0.10693","656.30066","0.00668","13.05669"
"12.88800","0.10715","657.21570","0.00670","13.07489"
"12.91800","0.10742","658.20764","0.00671","13.09463"
"12.94800","0.10767","659.06213","0.00673","13.11162"
"12.97800","0.10791","659.90009","0.00674","13.12830"
"13.00800","0.10815","660.90698","0.00676","13.14833"
"13.03800","0.10840","661.79449","0.00678","13.16598"
"13.06800","0.10863","662.33051","0.00679","13.17665"
"13.09800","0.10889","663.22955","0.00681","13.19453"
"13.12800","0.10914","664.09460","0.00682","13.21174"
"13.15800","0.10939","664.94904","0.00684","13.22874"
"13.18800","0.10963","665.98553","0.00685","13.24936"
"13.21800","0.10987","667.05347","0.00687","13.27061"
"13.24800","0.11011","668.21698","0.00688","13.29376"
"13.27800","0.11036","669.47833","0.00690","13.31885"
"13.30800","0.11063","670.61292","0.00691","13.34142"
"13.33800","0.11090","671.53302","0.00693","13.35973"
"13.36800","0.11115","672.36829","0.00695","13.37634"
"13.39800","0.11141","673.24951","0.00696","13.39387"
"13.42800","0.11167","673.95966","0.00698","13.40800"
"13.45800","0.11192","674.70142","0.00700","13.42276"
"13.48800","0.11218","675.76447","0.00701","13.44391"
"13.51800","0.11245","677.04797","0.00703","13.46944"
"13.54800","0.11269","677.78992","0.00704","13.48420"
"13.57800","0.11293","678.62854","0.00706","13.50089"
"13.60800","0.11317","679.63281","0.00707","13.52087"
"13.63800","0.11341","680.60614","0.00709","13.54023"
"13.66800","0.11366","681.58179","0.00710","13.55964"
"13.69800","0.11391","682.42139","0.00712","13.57634"
"13.72800","0.11415","683.36115","0.00713","13.59504"
"13.75800","0.11440","684.49725","0.00715","13.61764"
"13.78800","0.11465","685.35242","0.00717","13.63465"
"13.81800","0.11490","686.00653","0.00718","13.64767"
"13.84800","0.11518","687.01562","0.00720","13.66774"
"13.87800","0.11545","688.03839","0.00722","13.68809"
"13.90800","0.11570","688.97089","0.00723","13.70664"
"13.93800","0.11595","689.97418","0.00725","13.72660"
"13.96800","0.11618","690.78461","0.00726","13.74272"
"13.99800","0.11641","691.60748","0.00728","13.75909"
"14.02800","0.11664","692.54010","0.00729","13.77765"
"14.05800","0.11690","693.71167","0.00731","13.80096"
"14.08800","0.11716","694.75085","0.00732","13.82163"
"14.11800","0.11742","695.79199","0.00734","13.84234"
"14.14800","0.11767","696.75488","0.00735","13.86150"
"14.17800","0.11792","697.75250","0.00737","13.88135"
"14.20800","0.11816","698.83606","0.00739","13.90290"
"14.23800","0.11843","700.02954","0.00740","13.92665"
"14.26800","0.11871","701.25214","0.00742","13.95097"
"14.29800","0.11898","702.26416","0.00744","13.97110"
"14.32800","0.11925","703.21576","0.00745","13.99003"
"14.35800","0.11949","703.98779","0.00747","14.00539"
"14.38800","0.11971","704.50476","0.00748","14.01568"
"14.41800","0.11994","705.26947","0.00750","14.03089"
"14.44800","0.12021","706.49823","0.00751","14.05534"
"14.47800","0.12047","707.67456","0.00753","14.07874"
"14.50800","0.12073","708.64429","0.00755","14.09803"
"14.53800","0.12099","709.65302","0.00756","14.11810"
"14.56800","0.12125","710.76184","0.00758","14.14016"
"14.59800","0.12150","711.72412","0.00759","14.15930"
"14.62800","0.12172","712.41754","0.00761","14.17310"
"14.65800","0.12194","713.22382","0.00762","14.18914"
"14.68800","0.12216","714.11267","0.00764","14.20682"
"14.71800","0.12240","715.15747","0.00765","14.22761"
"14.74800","0.12265","716.26483","0.00767","14.24964"
"14.77800","0.12292","717.44244","0.00768","14.27306"
"14.80800","0.12316","718.39026","0.00770","14.29192"
"14.83800","0.12341","719.27258","0.00771","14.30947"
"14.86800","0.12364","720.16852","0.00773","14.32730"
"14.89800","0.12387","721.07599","0.00774","14.34535"
"14.92800","0.12412","722.10431","0.00776","14.36581"
"14.95800","0.12438","723.26166","0.00777","14.38883"
"14.98800","0.12465","724.46600","0.00779","14.41279"
"15.01800","0.12490","725.48804","0.00781","14.43313"
"15.04800","0.12515","726.52289","0.00782","14.45371"
"15.07800","0.12542","727.67096","0.00784","14.47655"
"15.10800","0.12568","728.71832","0.00786","14.49739"
"15.13800","0.12592","729.68494","0.00787","14.51662"
"15.16800","0.12616","730.85028","0.00789","14.53981"
"15.19800","0.12641","732.00256","0.00790","14.56273"
"15.22800","0.12665","733.07343","0.00792","14.58403"
"15.25800","0.12692","734.33246","0.00793","14.60908"
"15.28800","0.12719","735.56268","0.00795","14.63356"
"15.31800","0.12744","736.47522","0.00797","14.65171"
"15.34800","0.12767","737.20880","0.00798","14.66630"
"15.37800","0.12793","738.34381","0.00800","14.68888"
"15.40800","0.12818","739.34875","0.00801","14.70888"
"15.43800","0.12843","740.21954","0.00803","14.72620"
"15.46800","0.12868","741.10297","0.00804","14.74378"
"15.49800","0.12893","742.03619","0.00806","14.76234"
"15.52800","0.12918","743.07697","0.00807","14.78305"
"15.55800","0.12943","744.07141","0.00809","14.80283"
"15.58800","0.12967","745.09656","0.00810","14.82323"
"15.61800","0.12991","746.32819","0.00812","14.84773"
"15.64800","0.13016","747.62805","0.00814","14.87359"
"15.67800","0.13043","748.94659","0.00815","14.89982"
"15.70800","0.13070","750.16357","0.00817","14.92403"
"15.73800","0.13097","751.32764","0.00819","14.94719"
"15.76800","0.13121","752.20270","0.00820","14.96460"
"15.79800","0.13146","752.95245","0.00822","14.97951"
"15.82800","0.13172","753.70502","0.00823","14.99449"
"15.85800","0.13198","754.48499","0.00825","15.01000"
"15.88800","0.13223","755.40527","0.00826","15.02831"
"15.91800","0.13247","756.25653","0.00828","15.04525"
"15.94800","0.13271","757.07123","0.00829","15.06145"
"15.97800","0.13295","757.99536","0.00831","15.07984"
"16.00800","0.13320","759.02991","0.00832","15.10042"
"16.03800","0.13346","760.16693","0.00834","15.12304"
"16.06800","0.13371","761.28748","0.00836","15.14533"
"16.09800","0.13396","762.61041","0.00837","15.17165"
"16.12800","0.13423","764.18665","0.00839","15.20301"
"16.15800","0.13450","765.51587","0.00841","15.22945"
"16.18800","0.13476","766.57904","0.00842","15.25061"
"16.21800","0.13502","767.54486","0.00844","15.26982"
"16.24800","0.13528","768.43066","0.00845","15.28744"
"16.27800","0.13552","769.16278","0.00847","15.30201"
"16.30800","0.13577","769.98102","0.00849","15.31829"
"16.33800","0.13602","771.03430","0.00850","15.33924"
"16.36800","0.13628","772.19641","0.00852","15.36236"
"16.39800","0.13655","773.36786","0.00853","15.38567"
"16.42800","0.13680","774.38275","0.00855","15.40586"
"16.45800","0.13701","775.05981","0.00856","15.41933"
"16.48800","0.13718","775.54620","0.00857","15.42900"
"16.51800","0.13740","776.43732","0.00859","15.44673"
"16.54800","0.13764","777.53320","0.00860","15.46853"
"16.57800","0.13788","778.62726","0.00862","15.49030"
"16.60800","0.13814","779.97894","0.00863","15.51719"
"16.63800","0.13841","781.36816","0.00865","15.54483"
"16.66800","0.13866","782.42670","0.00867","15.56589"
"16.69800","0.13890","783.44879","0.00868","15.58622"
"16.72800","0.13914","784.34967","0.00870","15.60414"
"16.75800","0.13938","785.23523","0.00871","15.62176"
"16.78800","0.13962","786.13916","0.00873","15.63974"
"16.81800","0.13988","787.23279","0.00874","15.66150"
"16.84800","0.14015","788.36707","0.00876","15.68406"
"16.87800","0.14039","789.39526","0.00877","15.70452"
"16.90800","0.14064","790.60327","0.00879","15.72855"
"16.93800","0.14088","791.72009","0.00881","15.75077"
"16.96800","0.14114","792.75012","0.00882","15.77126"
"16.99800","0.14139","793.87091","0.00884","15.79356"
"17.02800","0.14164","795.10010","0.00885","15.81801"
"17.05800","0.14189","795.62433","0.00887","15.82844"
"17.08800","0.14213","796.51642","0.00888","15.84619"
"17.11800","0.14239","797.72540","0.00890","15.87024"
"17.14800","0.14265","799.02960","0.00892","15.89619"
"17.17800","0.14291","800.21783","0.00893","15.91983"
"17.20800","0.14317","801.35522","0.00895","15.94246"
"17.23800","0.14342","802.35675","0.00896","15.96238"
"17.26800","0.14366","803.14832","0.00898","15.97813"
"17.29800","0.14390","804.09717","0.00899","15.99701"
"17.32800","0.14416","805.24481","0.00901","16.01984"
"17.35800","0.14441","806.18646","0.00903","16.03857"
"17.38800","0.14467","807.22882","0.00904","16.05931"
"17.41800","0.14493","808.32996","0.00906","16.08121"
"17.44800","0.14517","809.35803","0.00907","16.10167"
"17.47800","0.14543","810.50751","0.00909","16.12453"
"17.50800","0.14567","811.42871","0.00910","16.14286"
"17.53800","0.14590","812.52075","0.00912","16.16459"
"17.56800","0.14615","813.73645","0.00913","16.18877"
"17.59800","0.14639","814.72565","0.00915","16.20845"
"17.62800","0.14666","815.87408","0.00917","16.23130"
"17.65800","0.14692","817.03674","0.00918","16.25443"
"17.68800","0.14718","818.09955","0.00920","16.27557"
"17.71800","0.14743","819.00330","0.00921","16.29355"
"17.74800","0.14768","819.97040","0.00923","16.31279"
"17.77800","0.14793","820.94873","0.00925","16.33226"
"17.80800","0.14817","821.89014","0.00926","16.35099"
"17.83800","0.14840","822.77557","0.00928","16.36860"
"17.86800","0.14863","823.64191","0.00929","16.38584"
"17.89800","0.14888","824.69446","0.00930","16.40678"
"17.92800","0.14915","826.01355","0.00932","16.43302"
"17.95800","0.14943","827.35962","0.00934","16.45980"
"17.98800","0.14971","828.64978","0.00936","16.48546"
"18.01800","0.14995","829.77045","0.00937","16.50776"
"18.04800","0.15021","831.05066","0.00939","16.53323"
"18.07800","0.15046","832.14948","0.00940","16.55509"
"18.10800","0.15071","833.22223","0.00942","16.57643"
"18.13800","0.15098","834.35229","0.00944","16.59891"
"18.16800","0.15126","835.48743","0.00945","16.62149"
"18.19800","0.15151","836.40533","0.00947","16.63976"
"18.22800","0.15176","837.38324","0.00948","16.65921"
"18.25800","0.15199","838.27753","0.00950","16.67700"
"18.28800","0.15221","839.04602","0.00951","16.69229"
"18.31800","0.15245","840.00079","0.00953","16.71129"
"18.34800","0.15269","841.06122","0.00954","16.73238"
"18.37800","0.15292","842.04047","0.00956","16.75186"
"18.40800","0.15316","843.12518","0.00957","16.77344"
"18.43800","0.15341","844.18646","0.00959","16.79456"
"18.46800","0.15365","845.17035","0.00960","16.81413"
"18.49800","0.15389","846.23279","0.00962","16.83527"
"18.52800","0.15413","847.38525","0.00963","16.85819"
"18.55800","0.15437","848.61505","0.00965","16.88266"
"18.58800","0.15463","849.82898","0.00966","16.90681"
"18.61800","0.15489","850.86206","0.00968","16.92736"
"18.64800","0.15514","851.81775","0.00970","16.94638"
"18.67800","0.15540","852.89117","0.00971","16.96773"
"18.70800","0.15566","853.89532","0.00973","16.98771"
"18.73800","0.15592","854.97766","0.00974","17.00924"
"18.76800","0.15616","856.08942","0.00976","17.03136"
"18.79800","0.15641","857.09668","0.00978","17.05140"
"18.82800","0.15666","858.09216","0.00979","17.07120"
"18.85800","0.15691","859.15784","0.00981","17.09240"
"18.88800","0.15717","860.21527","0.00982","17.11344"
"18.91800","0.15741","861.14185","0.00984","17.13187"
"18.94800","0.15765","862.05920","0.00985","17.15012"
"18.97800","0.15789","863.14325","0.00987","17.17169"
"19.00800","0.15814","864.36731","0.00988","17.19604"
"19.03800","0.15840","865.69006","0.00990","17.22236"
"19.06800","0.15867","866.97296","0.00992","17.24788"
"19.09800","0.15893","868.10944","0.00993","17.27049"
"19.12800","0.15918","869.11810","0.00995","17.29056"
"19.15800","0.15942","869.89569","0.00996","17.30603"
"19.18800","0.15966","870.74152","0.00998","17.32285"
"19.21800","0.15990","871.65063","0.00999","17.34094"
"19.24800","0.16015","872.69037","0.01001","17.36162"
"19.27800","0.16041","873.73029","0.01003","17.38231"
"19.30800","0.16067","874.81714","0.01004","17.40393"
"19.33800","0.16093","875.98779","0.01006","17.42723"
"19.36800","0.16118","877.04181","0.01007","17.44819"
"19.39800","0.16143","878.05261","0.01009","17.46830"
"19.42800","0.16169","879.17792","0.01011","17.49069"
"19.45800","0.16193","880.26111","0.01012","17.51224"
"19.48800","0.16216","881.38538","0.01014","17.53461"
"19.51800","0.16243","882.70319","0.01015","17.56082"
"19.54800","0.16268","883.86755","0.01017","17.58399"
"19.57800","0.16293","884.99988","0.01018","17.60651"
"19.60800","0.16317","885.88568","0.01020","17.62414"
"19.63800","0.16342","886.87762","0.01021","17.64387"
"19.66800","0.16369","887.94061","0.01023","17.66502"
"19.69800","0.16396","888.95270","0.01025","17.68515"
"19.72800","0.16422","889.99066","0.01026","17.70580"
"19.75800","0.16447","891.06720","0.01028","17.72722"
"19.78800","0.16474","892.21844","0.01030","17.75012"
"19.81800","0.16500","893.26740","0.01031","17.77099"
"19.84800","0.16526","894.44025","0.01033","17.79432"
"19.87800","0.16552","895.59418","0.01035","17.81728"
"19.90800","0.16579","896.76978","0.01036","17.84067"
"19.93800","0.16605","897.98633","0.01038","17.86487"
"19.96800","0.16630","899.19385","0.01039","17.88889"
"19.99800","0.16654","900.21356","0.01041","17.90918"
"20.02800","0.16676","901.02490","0.01042","17.92532"
"20.05800","0.16700","901.92377","0.01044","17.94320"
"20.08800","0.16724","902.84149","0.01045","17.96146"
"20.11800","0.16749","903.75989","0.01047","17.97973"
"20.14800","0.16773","904.68658","0.01048","17.99817"
"20.17800","0.16797","905.62262","0.01050","18.01679"
"20.20800","0.16821","906.53662","0.01051","18.03497"
"20.23800","0.16842","907.32495","0.01053","18.05066"
"20.26800","0.16867","908.42834","0.01054","18.07261"
"20.29800","0.16891","909.44470","0.01056","18.09283"
"20.32800","0.16916","910.58496","0.01057","18.11551"
"20.35800","0.16940","911.63403","0.01059","18.13638"
"20.38800","0.16964","912.67853","0.01060","18.15716"
"20.41800","0.16989","913.88782","0.01062","18.18122"
"20.44800","0.17012","914.98651","0.01063","18.20308"
"20.47800","0.17037","916.24579","0.01065","18.22813"
"20.50800","0.17065","917.61084","0.01067","18.25529"
"20.53800","0.17090","918.61560","0.01068","18.27528"
"20.56800","0.17114","919.53558","0.01070","18.29358"
"20.59800","0.17140","920.57562","0.01071","18.31427"
"20.62800","0.17164","921.46173","0.01073","18.33190"
"20.65800","0.17189","922.35962","0.01074","18.34976"
"20.68800","0.17213","923.31445","0.01076","18.36876"
"20.71800","0.17239","924.41003","0.01077","18.39055"
"20.74800","0.17265","925.55737","0.01079","18.41338"
"20.77800","0.17290","926.60394","0.01081","18.43420"
"20.80800","0.17315","927.65161","0.01082","18.45504"
"20.83800","0.17340","928.67163","0.01084","18.47534"
"20.86800","0.17365","929.73615","0.01085","18.49651"
"20.89800","0.17390","930.90936","0.01087","18.51985"
"20.92800","0.17413","931.99158","0.01088","18.54138"
"20.95800","0.17438","933.10577","0.01090","18.56355"
"20.98800","0.17463","934.20374","0.01091","18.58539"
"21.01800","0.17489","935.41589","0.01093","18.60951"
"21.04800","0.17514","936.43329","0.01095","18.62975"
"21.07800","0.17540","937.41943","0.01096","18.64937"
"21.10800","0.17565","938.36810","0.01098","18.66824"
"21.13800","0.17590","939.29559","0.01099","18.68669"
"21.16800","0.17614","940.18292","0.01101","18.70435"
"21.19800","0.17638","941.21222","0.01102","18.72482"
"21.22800","0.17663","942.25842","0.01104","18.74564"
"21.25800","0.17689","943.38263","0.01106","18.76800"
"21.28800","0.17714","944.45734","0.01107","18.78938"
"21.31800","0.17740","945.58447","0.01109","18.81181"
"21.34800","0.17764","946.62207","0.01110","18.83245"
"21.37800","0.17788","947.69714","0.01112","18.85384"
"21.40800","0.17812","948.76208","0.01113","18.87502"
"21.43800","0.17838","950.04431","0.01115","18.90053"
"21.46800","0.17864","951.25366","0.01117","18.92459"
"21.49800","0.17890","952.38879","0.01118","18.94717"
"21.52800","0.17917","953.53979","0.01120","18.97007"
"21.55800","0.17944","954.64331","0.01122","18.99203"
"21.58800","0.17971","955.64001","0.01123","19.01185"
"21.61800","0.17997","956.61719","0.01125","19.03130"
"21.64800","0.18022","957.63684","0.01126","19.05158"
"21.67800","0.18047","958.67828","0.01128","19.07230"
"21.70800","0.18073","959.73328","0.01130","19.09329"
"21.73800","0.18097","960.73022","0.01131","19.11312"
"21.76800","0.18122","961.75647","0.01133","19.13354"
"21.79800","0.18148","962.80200","0.01134","19.15434"
"21.82800","0.18174","963.93195","0.01136","19.17682"
"21.85800","0.18199","965.14691","0.01137","19.20099"
"21.88800","0.18223","966.25171","0.01139","19.22297"
"21.91800","0.18247","967.25055","0.01140","19.24284"
"21.94800","0.18270","968.11633","0.01142","19.26006"
"21.97800","0.18293","969.09015","0.01143","19.27944"
"22.00800","0.18317","970.09406","0.01145","19.29941"
"22.03800","0.18340","970.96344","0.01146","19.31671"
"22.06800","0.18363","971.80518","0.01148","19.33345"
"22.09800","0.18386","972.62335","0.01149","19.34973"
"22.12800","0.18409","973.61090","0.01151","19.36938"
"22.15800","0.18434","974.71185","0.01152","19.39128"
"22.18800","0.18459","975.81616","0.01154","19.41325"
"22.21800","0.18483","976.85205","0.01155","19.43386"
"22.24800","0.18508","977.99512","0.01157","19.45660"
"22.27800","0.18533","979.16998","0.01158","19.47997"
"22.30800","0.18559","980.34424","0.01160","19.50333"
"22.33800","0.18585","981.60901","0.01162","19.52849"
"22.36800","0.18611","982.93585","0.01163","19.55489"
"22.39800","0.18635","984.13086","0.01165","19.57866"
"22.42800","0.18660","985.24329","0.01166","19.60079"
"22.45800","0.18685","986.33551","0.01168","19.62252"
"22.48800","0.18709","987.36517","0.01169","19.64301"
"22.51800","0.18737","988.55054","0.01171","19.66659"
"22.54800","0.18761","989.41638","0.01173","19.68382"
"22.57800","0.18786","990.37048","0.01174","19.70280"
"22.60800","0.18811","991.41241","0.01176","19.72352"
"22.63800","0.18836","992.44122","0.01177","19.74399"
"22.66800","0.18862","993.50317","0.01179","19.76512"
"22.69800","0.18889","994.79272","0.01181","19.79077"
"22.72800","0.18917","996.03461","0.01182","19.81548"
"22.75800","0.18941","997.03168","0.01184","19.83532"
"22.78800","0.18966","998.08881","0.01185","19.85635"
"22.81800","0.18990","999.19885","0.01187","19.87843"
"22.83700","0.19006","1000.00635","0.01188","19.89450"